Workbook
Name EMB_600: CONFIG_LISTAS!$D$2
Name EMB_600: CONFIG_LISTAS!$D$2
Name EMB_600: CONFIG_LISTAS!$D$2
Name EMB_600: CONFIG_LISTAS!$D$2
Name EMB_600: CONFIG_LISTAS!$D$2:$D$2
Name EMB_COCO: CONFIG_LISTAS!$C$2:$C$3
Name EMB_COCO: CONFIG_LISTAS!$C$2:$C$3
Name EMB_COCO: CONFIG_LISTAS!$C$2:$C$3
Name EMB_COCO: CONFIG_LISTAS!$C$2:$C$3
Name EMB_COCO: CONFIG_LISTAS!$C$2:$C$3
Name EMB_CORANTE: CONFIG_LISTAS!$B$2
Name EMB_CORANTE: CONFIG_LISTAS!$B$2
Name EMB_CORANTE: CONFIG_LISTAS!$B$2
Name EMB_CORANTE: CONFIG_LISTAS!$B$2
Name EMB_CORANTE: CONFIG_LISTAS!$B$2:$B$2
Name EMB_TODAS: CONFIG_LISTAS!$A$2:$A$9
Name EMB_TODAS: CONFIG_LISTAS!$A$2:$A$9
Name EMB_TODAS: CONFIG_LISTAS!$A$2:$A$9
Name EMB_TODAS: CONFIG_LISTAS!$A$2:$A$9
Name EMB_TODAS: CONFIG_LISTAS!$A$2:$A$9

Sheet INSTRUÇÕES 
B1: INSTRUÇÕES DE USO
B2: Leia antes de usar • Manual operacional da planilha • AIDU
B3: ⚡ INÍCIO RÁPIDO | C3: 1. Lance na SEMANA → 2. Confira o GRAFICO → 3. Consulte o PAINEL
B5: — SEÇÃO 01 • MAPA DA PLANILHA —
B7: INSTRUÇÕES | C7: Esta aba. Leia primeiro.
B8: CAPA | C8: Resumo do ano: realizado, meta, atingimento e melhor mês.
B9: CLASSIFICAÇÃO | C9: Top 10 automático, gráfico e divisão por tamanho de lata.
B10: JANEIRO … DEZEMBRO | C10: OP, lotes, produto, cliente, quantidade e fabricação.
B11: SEMANA [MÊS] | C11: ★ Lance produto, embalagem, caixas e Real (CX).
B12: GRAFICO [MÊS] | C12: Produção diária x meta, com observações.
B13: PAINEL / PAINEL_EXEC | C13: Resumo anual de produção, desempenho e gás.
B14: BASE_DADOS (OCULTA) | C14: Base automática consolidada das abas SEMANA. Não editar nem excluir.
B15: RESUMO_MENSAL (OCULTO) | C15: Base automática de cálculo do PAINEL. Não editar nem excluir.
B16: GÁS | C16: Cargas de gás: data, NF-e, lote, produto e KG.
B17: CADASTRO PRODUTOS | C17: Produtos, embalagens, unidades por caixa e pallets.
B18: — SEÇÃO 02 • PREENCHIMENTO DIÁRIO (aba SEMANA) —
B20: ✅ Preencha apenas | C20: PRODUTO • EMBALAGEM • CAIXAS • REAL (CX)
B21: 🔒 Automático | C21: CX/Pallet • Pallets (PBR) • Total de Latas • Totais do dia
B22: Dia sem produção | C22: Informe 0 em REAL (CX). Não apague o bloco do dia.
B23: Sábado trabalhado | C23: Preencha normalmente e informe o Real (CX).
B24: Sábado não trabalhado | C24: Informe 0 em REAL (CX); não entra na meta.
B26: — SEÇÃO 03 • CONTROLE DE GÁS (aba GÁS) —
B28: O que preencher | C28: Data, NF-e, lote, produto e quantidade recebida (KG).
B29: O que é automático | C29: Totais, maior/menor consumo e indicadores.
B30: Indicadores gerados | C30: Consumo mensal, total anual e destaques.
B31: Integração | C31: Atualiza automaticamente a base oculta e os indicadores do PAINEL.
B32: 🎨 LEGENDA DE CORES | C32: Verde = meta atingida • Vermelho = abaixo • Cinza = sem produção
B33: — SEÇÃO 04 • CAIXAS POR PALLET (PBR) —
B35: 70 ml / 100 ml / 125 ml / 180 ml | C35: 240 cx/pallet • 12 un/cx
B36: 200 ml (Espuma e Óleo de Coco) | C36: 330 cx/pallet • 6 un/cx
B37: 210 ml (ICEBERG ICE) | C37: 120 cx/pallet • 120 un/cx
B38: 400 ml / 500 ml / 600 ml | C38: 400 ml: 125 • 500/600 ml: 95 cx/pallet • 12 un/cx
B39: Exceções cadastradas | C39: ICEBERG 400 ml: 110 • DESTAK 600 ml: 190 cx/pallet, 6 un/cx
B40: DESTAK 5 L (histórico) | C40: 60 cx/pallet • 2 bombonas de 5 kg/cx • multiplicação: 10 kg por caixa
B41: — SEÇÃO 05 • RANKING DE PRODUTOS —
B43: Aba CLASSIFICAÇÃO | C43: Top 10 automático, participação, gráfico e tamanhos.
B44: Agrupamentos | C44: ADIMIX consolida variações; PURATOS agrupa DESTAK/NORCAU; ICEBERG é detalhado.
B45: Atualização | C45: Atualiza pelas abas SEMANA. Não editar manualmente.
B46: 🛠 MANUTENÇÃO | C46: Produtos: CADASTRO PRODUTOS • Pallets e unidades: CONFIG_PALETES
B47: ⚠ REGRAS IMPORTANTES — NÃO IGNORE
...

Sheet CAPA 
B1: CONTROLE DE PRODUÇÃO | G1: 2026
B2: Visão executiva • Acompanhamento anual • AIDU Indústria
B5: TOTAL REALIZADO | D5: META ACUMULADA | F5: ATINGIMENTO | G5: MELHOR MÊS
B6: =PAINEL!B6 -> 1674871 | D6: =PAINEL!D6 -> 1650000 | F6: =PAINEL!F6 -> 1.0150733 | G6: =PAINEL!H6 -> MARÇO
B7: latas no ano | D7: latas previstas | F7: meta x realizado | G7: pico do ano
B9: — SEÇÃO 01 • MAPA DA PLANILHA —
B11: SEMANA ▸ Preenchimento diário | E11: PAINEL ▸ Visão executiva
B12: Lance PRODUTO, EMBALAGEM, CAIXAS e REAL (CX). As demais colunas calculam automaticamente. | E12: Resumo do ano: produção, meta, atingimento, melhor mês e controle de gás.
B14: GRAFICO ▸ Realizado x Meta | E14: INSTRUÇÕES ▸ Manual de uso
B15: Produção diária x meta, com cores de desempenho e campo de observações. | E15: Regras de preenchimento, legenda, embalagens por pallet e avisos importantes.
B17: — SEÇÃO 02 • RECOMENDAÇÕES DE USO —
B19: 1 | C19: Lance os itens do dia apenas na área amarela de preenchimento.
B20: 2 | C20: As linhas TOTAL são automáticas — não inserir, apagar ou alterar.
B21: 3 | C21: Evite inserir fórmulas nas abas SEMANA fora dos campos estruturados.
B22: 4 | C22: Para impressão ou apresentação, priorize CAPA, PAINEL ou o GRAFICO do mês.
B24: AIDU INDÚSTRIA • Controle de Produção 2026 • Documento de uso interno
B26: — SEÇÃO 03 • NOSSAS LATAS —
B27: Linha de embalagens — desmoldantes, óleo de coco e douradores

Sheet CLASSIFICAÇÃO
A1: CLASSIFICAÇÃO DE PRODUÇÃO
A2: Acumulado do ano • Latas produzidas • Variações de válvula consolidadas por produto
A4: — TOP 10 PRODUTOS • LATAS PRODUZIDAS NO ANO —
A5: # | B5: Produto | C5: Latas Produzidas | D5: % do Total | E5: Posição
A6: 1 | B6: {=_xlfn.SORTBY($M$6:$N$15,$N$6:$N$15,-1)} -> UNTA FACIL | C6: 384444 | D6: =IF($C$17=0,0,C6/$C$17) -> 0.22953648 | E6: 🥇 1º lugar | M6: UNTA FACIL | N6: =SUMIF('SEMANA JANEIRO'!$B:$B,"*UNTA FACIL*",'SEMANA JANEIRO'!$I:$I)+SUMIF('SEMANA FEVEREIRO'!$B:$B,"*UNTA FACIL*",'SEMANA FEVEREIRO'!$I:$I)+SUMIF('SEMANA MARÇO'!$B:$B,"*UNTA FACIL*",'SEMANA MARÇO'!$I:$I)+SUMIF('SEMANA ABRIL'!$B:$B,"*UNTA FACIL*",'SEMANA ABRIL'!$I:$I)+SUMIF('SEMANA MAIO'!$B:$B,"*UNTA FACIL*",'SEMANA MAIO'!$I:$I)+SUMIF('SEMANA JUNHO'!$B:$B,"*UNTA FACIL*",'SEMANA JUNHO'!$I:$I)+SUMIF('SEMANA JULHO'!$B:$B,"*UNTA FACIL*",'SEMANA JULHO'!$I:$I)+SUMIF('SEMANA AGOSTO'!$B:$B,"*UNTA FACIL*",'SEMANA AGOSTO'!$I:$I)+SUMIF('SEMANA SETEMBRO'!$B:$B,"*UNTA FACIL*",'SEMANA SETEMBRO'!$I:$I)+SUMIF('SEMANA OUTUBRO'!$B:$B,"*UNTA FACIL*",'SEMANA OUTUBRO'!$I:$I)+SUMIF('SEMANA NOVEMBRO'!$B:$B,"*UNTA FACIL*",'SEMANA NOVEMBRO'!$I:$I)+SUMIF('SEMANA DEZEMBRO'!$B:$B,"*UNTA FACIL*",'SEMANA DEZEMBRO'!$I:$I) -> 384444
A7: 2 | B7: PURATOS | C7: 252246 | D7: =IF($C$17=0,0,C7/$C$17) -> 0.15060623 | E7: 🥈 2º lugar | M7: PURATOS | N7: =SUMIF('SEMANA JANEIRO'!$B:$B,"*DESTAK*",'SEMANA JANEIRO'!$I:$I)+SUMIF('SEMANA FEVEREIRO'!$B:$B,"*DESTAK*",'SEMANA FEVEREIRO'!$I:$I)+SUMIF('SEMANA MARÇO'!$B:$B,"*DESTAK*",'SEMANA MARÇO'!$I:$I)+SUMIF('SEMANA ABRIL'!$B:$B,"*DESTAK*",'SEMANA ABRIL'!$I:$I)+SUMIF('SEMANA MAIO'!$B:$B,"*DESTAK*",'SEMANA MAIO'!$I:$I)+SUMIF('SEMANA JUNHO'!$B:$B,"*DESTAK*",'SEMANA JUNHO'!$I:$I)+SUMIF('SEMANA JULHO'!$B:$B,"*DESTAK*",'SEMANA JULHO'!$I:$I)+SUMIF('SEMANA AGOSTO'!$B:$B,"*DESTAK*",'SEMANA AGOSTO'!$I:$I)+SUMIF('SEMANA SETEMBRO'!$B:$B,"*DESTAK*",'SEMANA SETEMBRO'!$I:$I)+SUMIF('SEMANA OUTUBRO'!$B:$B,"*DESTAK*",'SEMANA OUTUBRO'!$I:$I)+SUMIF('SEMANA NOVEMBRO'!$B:$B,"*DESTAK*",'SEMANA NOVEMBRO'!$I:$I)+SUMIF('SEMANA DEZEMBRO'!$B:$B,"*DESTAK*",'SEMANA DEZEMBRO'!$I:$I)+SUMIF('SEMANA JANEIRO'!$B:$B,"*NORCAU*",'SEMANA JANEIRO'!$I:$I)+SUMIF('SEMANA FEVEREIRO'!$B:$B,"*NORCAU*",'SEMANA FEVEREIRO'!$I:$I)+SUMIF('SEMANA MARÇO'!$B:$B,"*NORCAU*",'SEMANA MARÇO'!$I:$I)+SUMIF('SEMANA ABRIL'!$B:$B,"*NORCAU*",'SEMANA ABRIL'!$I:$I)+SUMIF('SEMANA MAIO'!$B:$B,"*NORCAU*",'SEMANA MAIO'!$I:$I)+SUMIF('SEMANA JUNHO'!$B:$B,"*NORCAU*",'SEMANA JUNHO'!$I:$I)+SUMIF('SEMANA JULHO'!$B:$B,"*NORCAU*",'SEMANA JULHO'!$I:$I)+SUMIF('SEMANA AGOSTO'!$B:$B,"*NORCAU*",'SEMANA AGOSTO'!$I:$I)+SUMIF('SEMANA SETEMBRO'!$B:$B,"*NORCAU*",'SEMANA SETEMBRO'!$I:$I)+SUMIF('SEMANA OUTUBRO'!$B:$B,"*NORCAU*",'SEMANA OUTUBRO'!$I:$I)+SUMIF('SEMANA NOVEMBRO'!$B:$B,"*NORCAU*",'SEMANA NOVEMBRO'!$I:$I)+SUMIF('SEMANA DEZEMBRO'!$B:$B,"*NORCAU*",'SEMANA DEZEMBRO'!$I:$I) -> 252246
A8: 3 | B8: ICEBERG CHEF | C8: 168427 | D8: =IF($C$17=0,0,C8/$C$17) -> 0.10056118 | E8: 🥉 3º lugar | M8: ICEBERG CHEF | N8: =SUMIF('SEMANA JANEIRO'!$B:$B,"*ICEBERG*",'SEMANA JANEIRO'!$I:$I)+SUMIF('SEMANA FEVEREIRO'!$B:$B,"*ICEBERG*",'SEMANA FEVEREIRO'!$I:$I)+SUMIF('SEMANA MARÇO'!$B:$B,"*ICEBERG*",'SEMANA MARÇO'!$I:$I)+SUMIF('SEMANA ABRIL'!$B:$B,"*ICEBERG*",'SEMANA ABRIL'!$I:$I)+SUMIF('SEMANA MAIO'!$B:$B,"*ICEBERG*",'SEMANA MAIO'!$I:$I)+SUMIF('SEMANA JUNHO'!$B:$B,"*ICEBERG*",'SEMANA JUNHO'!$I:$I)+SUMIF('SEMANA JULHO'!$B:$B,"*ICEBERG*",'SEMANA JULHO'!$I:$I)+SUMIF('SEMANA AGOSTO'!$B:$B,"*ICEBERG*",'SEMANA AGOSTO'!$I:$I)+SUMIF('SEMANA SETEMBRO'!$B:$B,"*ICEBERG*",'SEMANA SETEMBRO'!$I:$I)+SUMIF('SEMANA OUTUBRO'!$B:$B,"*ICEBERG*",'SEMANA OUTUBRO'!$I:$I)+SUMIF('SEMANA NOVEMBRO'!$B:$B,"*ICEBERG*",'SEMANA NOVEMBRO'!$I:$I)+SUMIF('SEMANA DEZEMBRO'!$B:$B,"*ICEBERG*",'SEMANA DEZEMBRO'!$I:$I) -> 168427
A9: 4 | B9: ADIMIX | C9: 120624 | D9: =IF($C$17=0,0,C9/$C$17) -> 0.072019875 | E9: Top 4 | M9: ADIMIX | N9: =SUMIF('SEMANA JANEIRO'!$B:$B,"*ADIMIX*",'SEMANA JANEIRO'!$I:$I)+SUMIF('SEMANA FEVEREIRO'!$B:$B,"*ADIMIX*",'SEMANA FEVEREIRO'!$I:$I)+SUMIF('SEMANA MARÇO'!$B:$B,"*ADIMIX*",'SEMANA MARÇO'!$I:$I)+SUMIF('SEMANA ABRIL'!$B:$B,"*ADIMIX*",'SEMANA ABRIL'!$I:$I)+SUMIF('SEMANA MAIO'!$B:$B,"*ADIMIX*",'SEMANA MAIO'!$I:$I)+SUMIF('SEMANA JUNHO'!$B:$B,"*ADIMIX*",'SEMANA JUNHO'!$I:$I)+SUMIF('SEMANA JULHO'!$B:$B,"*ADIMIX*",'SEMANA JULHO'!$I:$I)+SUMIF('SEMANA AGOSTO'!$B:$B,"*ADIMIX*",'SEMANA AGOSTO'!$I:$I)+SUMIF('SEMANA SETEMBRO'!$B:$B,"*ADIMIX*",'SEMANA SETEMBRO'!$I:$I)+SUMIF('SEMANA OUTUBRO'!$B:$B,"*ADIMIX*",'SEMANA OUTUBRO'!$I:$I)+SUMIF('SEMANA NOVEMBRO'!$B:$B,"*ADIMIX*",'SEMANA NOVEMBRO'!$I:$I)+SUMIF('SEMANA DEZEMBRO'!$B:$B,"*ADIMIX*",'SEMANA DEZEMBRO'!$I:$I) -> 120624
A10: 5 | B10: ALLBREAD | C10: 44124 | D10: =IF($C$17=0,0,C10/$C$17) -> 0.026344716 | E10: Top 5 | M10: FESTPAN | N10: =SUMIF('SEMANA JANEIRO'!$B:$B,"*FESTPAN*",'SEMANA JANEIRO'!$I:$I)+SUMIF('SEMANA FEVEREIRO'!$B:$B,"*FESTPAN*",'SEMANA FEVEREIRO'!$I:$I)+SUMIF('SEMANA MARÇO'!$B:$B,"*FESTPAN*",'SEMANA MARÇO'!$I:$I)+SUMIF('SEMANA ABRIL'!$B:$B,"*FESTPAN*",'SEMANA ABRIL'!$I:$I)+SUMIF('SEMANA MAIO'!$B:$B,"*FESTPAN*",'SEMANA MAIO'!$I:$I)+SUMIF('SEMANA JUNHO'!$B:$B,"*FESTPAN*",'SEMANA JUNHO'!$I:$I)+SUMIF('SEMANA JULHO'!$B:$B,"*FESTPAN*",'SEMANA JULHO'!$I:$I)+SUMIF('SEMANA AGOSTO'!$B:$B,"*FESTPAN*",'SEMANA AGOSTO'!$I:$I)+SUMIF('SEMANA SETEMBRO'!$B:$B,"*FESTPAN*",'SEMANA SETEMBRO'!$I:$I)+SUMIF('SEMANA OUTUBRO'!$B:$B,"*FESTPAN*",'SEMANA OUTUBRO'!$I:$I)+SUMIF('SEMANA NOVEMBRO'!$B:$B,"*FESTPAN*",'SEMANA NOVEMBRO'!$I:$I)+SUMIF('SEMANA DEZEMBRO'!$B:$B,"*FESTPAN*",'SEMANA DEZEMBRO'!$I:$I) -> 43632
A11: 6 | B11: FESTPAN | C11: 43632 | D11: =IF($C$17=0,0,C11/$C$17) -> 0.026050962 | E11: Top 6 | M11: QUALICOCO | N11: =SUMIF('SEMANA JANEIRO'!$B:$B,"*QUALICOCO*",'SEMANA JANEIRO'!$I:$I)+SUMIF('SEMANA FEVEREIRO'!$B:$B,"*QUALICOCO*",'SEMANA FEVEREIRO'!$I:$I)+SUMIF('SEMANA MARÇO'!$B:$B,"*QUALICOCO*",'SEMANA MARÇO'!$I:$I)+SUMIF('SEMANA ABRIL'!$B:$B,"*QUALICOCO*",'SEMANA ABRIL'!$I:$I)+SUMIF('SEMANA MAIO'!$B:$B,"*QUALICOCO*",'SEMANA MAIO'!$I:$I)+SUMIF('SEMANA JUNHO'!$B:$B,"*QUALICOCO*",'SEMANA JUNHO'!$I:$I)+SUMIF('SEMANA JULHO'!$B:$B,"*QUALICOCO*",'SEMANA JULHO'!$I:$I)+SUMIF('SEMANA AGOSTO'!$B:$B,"*QUALICOCO*",'SEMANA AGOSTO'!$I:$I)+SUMIF('SEMANA SETEMBRO'!$B:$B,"*QUALICOCO*",'SEMANA SETEMBRO'!$I:$I)+SUMIF('SEMANA OUTUBRO'!$B:$B,"*QUALICOCO*",'SEMANA OUTUBRO'!$I:$I)+SUMIF('SEMANA NOVEMBRO'!$B:$B,"*QUALICOCO*",'SEMANA NOVEMBRO'!$I:$I)+SUMIF('SEMANA DEZEMBRO'!$B:$B,"*QUALICOCO*",'SEMANA DEZEMBRO'!$I:$I) -> 34008
A12: 7 | B12: QUALICOCO | C12: 34008 | D12: =IF($C$17=0,0,C12/$C$17) -> 0.020304847 | E12: Top 7 | M12: DONA JURA | N12: =SUMIF('SEMANA JANEIRO'!$B:$B,"*DONA JURA*",'SEMANA JANEIRO'!$I:$I)+SUMIF('SEMANA FEVEREIRO'!$B:$B,"*DONA JURA*",'SEMANA FEVEREIRO'!$I:$I)+SUMIF('SEMANA MARÇO'!$B:$B,"*DONA JURA*",'SEMANA MARÇO'!$I:$I)+SUMIF('SEMANA ABRIL'!$B:$B,"*DONA JURA*",'SEMANA ABRIL'!$I:$I)+SUMIF('SEMANA MAIO'!$B:$B,"*DONA JURA*",'SEMANA MAIO'!$I:$I)+SUMIF('SEMANA JUNHO'!$B:$B,"*DONA JURA*",'SEMANA JUNHO'!$I:$I)+SUMIF('SEMANA JULHO'!$B:$B,"*DONA JURA*",'SEMANA JULHO'!$I:$I)+SUMIF('SEMANA AGOSTO'!$B:$B,"*DONA JURA*",'SEMANA AGOSTO'!$I:$I)+SUMIF('SEMANA SETEMBRO'!$B:$B,"*DONA JURA*",'SEMANA SETEMBRO'!$I:$I)+SUMIF('SEMANA OUTUBRO'!$B:$B,"*DONA JURA*",'SEMANA OUTUBRO'!$I:$I)+SUMIF('SEMANA NOVEMBRO'!$B:$B,"*DONA JURA*",'SEMANA NOVEMBRO'!$I:$I)+SUMIF('SEMANA DEZEMBRO'!$B:$B,"*DONA JURA*",'SEMANA DEZEMBRO'!$I:$I) -> 24888
A13: 8 | B13: ITAIQUARA | C13: 25176 | D13: =IF($C$17=0,0,C13/$C$17) -> 0.015031605 | E13: Top 8 | M13: ALLBREAD | N13: =SUMIF('SEMANA JANEIRO'!$B:$B,"*ALLBREAD*",'SEMANA JANEIRO'!$I:$I)+SUMIF('SEMANA FEVEREIRO'!$B:$B,"*ALLBREAD*",'SEMANA FEVEREIRO'!$I:$I)+SUMIF('SEMANA MARÇO'!$B:$B,"*ALLBREAD*",'SEMANA MARÇO'!$I:$I)+SUMIF('SEMANA ABRIL'!$B:$B,"*ALLBREAD*",'SEMANA ABRIL'!$I:$I)+SUMIF('SEMANA MAIO'!$B:$B,"*ALLBREAD*",'SEMANA MAIO'!$I:$I)+SUMIF('SEMANA JUNHO'!$B:$B,"*ALLBREAD*",'SEMANA JUNHO'!$I:$I)+SUMIF('SEMANA JULHO'!$B:$B,"*ALLBREAD*",'SEMANA JULHO'!$I:$I)+SUMIF('SEMANA AGOSTO'!$B:$B,"*ALLBREAD*",'SEMANA AGOSTO'!$I:$I)+SUMIF('SEMANA SETEMBRO'!$B:$B,"*ALLBREAD*",'SEMANA SETEMBRO'!$I:$I)+SUMIF('SEMANA OUTUBRO'!$B:$B,"*ALLBREAD*",'SEMANA OUTUBRO'!$I:$I)+SUMIF('SEMANA NOVEMBRO'!$B:$B,"*ALLBREAD*",'SEMANA NOVEMBRO'!$I:$I)+SUMIF('SEMANA DEZEMBRO'!$B:$B,"*ALLBREAD*",'SEMANA DEZEMBRO'!$I:$I) -> 44124
A14: 9 | B14: DONA JURA | C14: 24888 | D14: =IF($C$17=0,0,C14/$C$17) -> 0.014859652 | E14: Top 9 | M14: DONA LELLA | N14: =SUMIF('SEMANA JANEIRO'!$B:$B,"*DONA LELLA*",'SEMANA JANEIRO'!$I:$I)+SUMIF('SEMANA FEVEREIRO'!$B:$B,"*DONA LELLA*",'SEMANA FEVEREIRO'!$I:$I)+SUMIF('SEMANA MARÇO'!$B:$B,"*DONA LELLA*",'SEMANA MARÇO'!$I:$I)+SUMIF('SEMANA ABRIL'!$B:$B,"*DONA LELLA*",'SEMANA ABRIL'!$I:$I)+SUMIF('SEMANA MAIO'!$B:$B,"*DONA LELLA*",'SEMANA MAIO'!$I:$I)+SUMIF('SEMANA JUNHO'!$B:$B,"*DONA LELLA*",'SEMANA JUNHO'!$I:$I)+SUMIF('SEMANA JULHO'!$B:$B,"*DONA LELLA*",'SEMANA JULHO'!$I:$I)+SUMIF('SEMANA AGOSTO'!$B:$B,"*DONA LELLA*",'SEMANA AGOSTO'!$I:$I)+SUMIF('SEMANA SETEMBRO'!$B:$B,"*DONA LELLA*",'SEMANA SETEMBRO'!$I:$I)+SUMIF('SEMANA OUTUBRO'!$B:$B,"*DONA LELLA*",'SEMANA OUTUBRO'!$I:$I)+SUMIF('SEMANA NOVEMBRO'!$B:$B,"*DONA LELLA*",'SEMANA NOVEMBRO'!$I:$I)+SUMIF('SEMANA DEZEMBRO'!$B:$B,"*DONA LELLA*",'SEMANA DEZEMBRO'!$I:$I) -> 19800
A15: 10 | B15: DONA LELLA | C15: 19800 | D15: =IF($C$17=0,0,C15/$C$17) -> 0.011821806 | E15: Top 10 | M15: ITAIQUARA | N15: =SUMIF('SEMANA JANEIRO'!$B:$B,"*ITAIQUARA*",'SEMANA JANEIRO'!$I:$I)+SUMIF('SEMANA FEVEREIRO'!$B:$B,"*ITAIQUARA*",'SEMANA FEVEREIRO'!$I:$I)+SUMIF('SEMANA MARÇO'!$B:$B,"*ITAIQUARA*",'SEMANA MARÇO'!$I:$I)+SUMIF('SEMANA ABRIL'!$B:$B,"*ITAIQUARA*",'SEMANA ABRIL'!$I:$I)+SUMIF('SEMANA MAIO'!$B:$B,"*ITAIQUARA*",'SEMANA MAIO'!$I:$I)+SUMIF('SEMANA JUNHO'!$B:$B,"*ITAIQUARA*",'SEMANA JUNHO'!$I:$I)+SUMIF('SEMANA JULHO'!$B:$B,"*ITAIQUARA*",'SEMANA JULHO'!$I:$I)+SUMIF('SEMANA AGOSTO'!$B:$B,"*ITAIQUARA*",'SEMANA AGOSTO'!$I:$I)+SUMIF('SEMANA SETEMBRO'!$B:$B,"*ITAIQUARA*",'SEMANA SETEMBRO'!$I:$I)+SUMIF('SEMANA OUTUBRO'!$B:$B,"*ITAIQUARA*",'SEMANA OUTUBRO'!$I:$I)+SUMIF('SEMANA NOVEMBRO'!$B:$B,"*ITAIQUARA*",'SEMANA NOVEMBRO'!$I:$I)+SUMIF('SEMANA DEZEMBRO'!$B:$B,"*ITAIQUARA*",'SEMANA DEZEMBRO'!$I:$I) -> 25176
A17: TOTAL GERAL (todos os produtos) | C17: =SUMIFS('SEMANA JANEIRO'!$I:$I,'SEMANA JANEIRO'!$B:$B,"<>",'SEMANA JANEIRO'!$B:$B,"<>TOTAL",'SEMANA JANEIRO'!$B:$B,"<>PRODUTO")+SUMIFS('SEMANA FEVEREIRO'!$I:$I,'SEMANA FEVEREIRO'!$B:$B,"<>",'SEMANA FEVEREIRO'!$B:$B,"<>TOTAL",'SEMANA FEVEREIRO'!$B:$B,"<>PRODUTO")+SUMIFS('SEMANA MARÇO'!$I:$I,'SEMANA MARÇO'!$B:$B,"<>",'SEMANA MARÇO'!$B:$B,"<>TOTAL",'SEMANA MARÇO'!$B:$B,"<>PRODUTO")+SUMIFS('SEMANA ABRIL'!$I:$I,'SEMANA ABRIL'!$B:$B,"<>",'SEMANA ABRIL'!$B:$B,"<>TOTAL",'SEMANA ABRIL'!$B:$B,"<>PRODUTO")+SUMIFS('SEMANA MAIO'!$I:$I,'SEMANA MAIO'!$B:$B,"<>",'SEMANA MAIO'!$B:$B,"<>TOTAL",'SEMANA MAIO'!$B:$B,"<>PRODUTO")+SUMIFS('SEMANA JUNHO'!$I:$I,'SEMANA JUNHO'!$B:$B,"<>",'SEMANA JUNHO'!$B:$B,"<>TOTAL",'SEMANA JUNHO'!$B:$B,"<>PRODUTO")+SUMIFS('SEMANA JULHO'!$I:$I,'SEMANA JULHO'!$B:$B,"<>",'SEMANA JULHO'!$B:$B,"<>TOTAL",'SEMANA JULHO'!$B:$B,"<>PRODUTO")+SUMIFS('SEMANA AGOSTO'!$I:$I,'SEMANA AGOSTO'!$B:$B,"<>",'SEMANA AGOSTO'!$B:$B,"<>TOTAL",'SEMANA AGOSTO'!$B:$B,"<>PRODUTO")+SUMIFS('SEMANA SETEMBRO'!$I:$I,'SEMANA SETEMBRO'!$B:$B,"<>",'SEMANA SETEMBRO'!$B:$B,"<>TOTAL",'SEMANA SETEMBRO'!$B:$B,"<>PRODUTO")+SUMIFS('SEMANA OUTUBRO'!$I:$I,'SEMANA OUTUBRO'!$B:$B,"<>",'SEMANA OUTUBRO'!$B:$B,"<>TOTAL",'SEMANA OUTUBRO'!$B:$B,"<>PRODUTO")+SUMIFS('SEMANA NOVEMBRO'!$I:$I,'SEMANA NOVEMBRO'!$B:$B,"<>",'SEMANA NOVEMBRO'!$B:$B,"<>TOTAL",'SEMANA NOVEMBRO'!$B:$B,"<>PRODUTO")+SUMIFS('SEMANA DEZEMBRO'!$I:$I,'SEMANA DEZEMBRO'!$B:$B,"<>",'SEMANA DEZEMBRO'!$B:$B,"<>TOTAL",'SEMANA DEZEMBRO'!$B:$B,"<>PRODUTO") -> 1674871 | D17: 1
A19: * ADIMIX consolida todas as variações de válvula (Fadeva, Precision, etc.). Demais produtos seguem o nome exato registrado na BASE_DADOS.
A21: AIDU. • Controle de Produção 2026
A23: DETALHAMENTO DO TOP 10 POR TAMANHO DE LATA
A24: Produção separada por 180 ml, 400 ml, 600 ml e outros tamanhos.
A26: # | B26: Produto | C26: 180 ml | D26: 400 ml | E26: 600 ml | F26: Outros | G26: Total
A27: 🥇 1º | B27: {=INDEX($B$6:$B$15,ROW()-26)} -> UNTA FACIL | C27: {=_xlfn.LET(_xlpm.p,$B27,_xlpm.crit,IF(_xlpm.p="PURATOS",{"*DESTAK*","*NORCAU*"},IF(ISNUMBER(SEARCH("ICEBERG",_xlpm.p)),"*ICEBERG*","*"&_xlpm.p&"*")),SUM(SUMIFS(_AUTO_BASE!$E:$E,_AUTO_BASE!$C:$C,_xlpm.crit,_AUTO_BASE!$I:$I,180)))} -> 66096 | D27: {=_xlfn.LET(_xlpm.p,$B27,_xlpm.crit,IF(_xlpm.p="PURATOS",{"*DESTAK*","*NORCAU*"},IF(ISNUMBER(SEARCH("ICEBERG",_xlpm.p)),"*ICEBERG*","*"&_xlpm.p&"*")),SUM(SUMIFS(_AUTO_BASE!$E:$E,_AUTO_BASE!$C:$C,_xlpm.crit,_AUTO_BASE!$I:$I,400)))} -> 209820 | E27: {=_xlfn.LET(_xlpm.p,$B27,_xlpm.crit,IF(_xlpm.p="PURATOS",{"*DESTAK*","*NORCAU*"},IF(ISNUMBER(SEARCH("ICEBERG",_xlpm.p)),"*ICEBERG*","*"&_xlpm.p&"*")),SUM(SUMIFS(_AUTO_BASE!$E:$E,_AUTO_BASE!$C:$C,_xlpm.crit,_AUTO_BASE!$I:$I,600)))} -> 108528 | F27: =G27-SUM(C27:E27) -> 0 | G27: {=INDEX($C$6:$C$15,ROW()-26)} -> 384444
A28: 🥈 2º | B28: {=INDEX($B$6:$B$15,ROW()-26)} -> PURATOS | C28: {=_xlfn.LET(_xlpm.p,$B28,_xlpm.crit,IF(_xlpm.p="PURATOS",{"*DESTAK*","*NORCAU*"},IF(ISNUMBER(SEARCH("ICEBERG",_xlpm.p)),"*ICEBERG*","*"&_xlpm.p&"*")),SUM(SUMIFS(_AUTO_BASE!$E:$E,_AUTO_BASE!$C:$C,_xlpm.crit,_AUTO_BASE!$I:$I,180)))} -> 0 | D28: {=_xlfn.LET(_xlpm.p,$B28,_xlpm.crit,IF(_xlpm.p="PURATOS",{"*DESTAK*","*NORCAU*"},IF(ISNUMBER(SEARCH("ICEBERG",_xlpm.p)),"*ICEBERG*","*"&_xlpm.p&"*")),SUM(SUMIFS(_AUTO_BASE!$E:$E,_AUTO_BASE!$C:$C,_xlpm.crit,_AUTO_BASE!$I:$I,400)))} -> 0 | E28: {=_xlfn.LET(_xlpm.p,$B28,_xlpm.crit,IF(_xlpm.p="PURATOS",{"*DESTAK*","*NORCAU*"},IF(ISNUMBER(SEARCH("ICEBERG",_xlpm.p)),"*ICEBERG*","*"&_xlpm.p&"*")),SUM(SUMIFS(_AUTO_BASE!$E:$E,_AUTO_BASE!$C:$C,_xlpm.crit,_AUTO_BASE!$I:$I,600)))} -> 240846 | F28: =G28-SUM(C28:E28) -> 11400 | G28: {=INDEX($C$6:$C$15,ROW()-26)} -> 252246
A29: 🥉 3º | B29: {=INDEX($B$6:$B$15,ROW()-26)} -> ICEBERG CHEF | C29: {=_xlfn.LET(_xlpm.p,$B29,_xlpm.crit,IF(_xlpm.p="PURATOS",{"*DESTAK*","*NORCAU*"},IF(ISNUMBER(SEARCH("ICEBERG",_xlpm.p)),"*ICEBERG*","*"&_xlpm.p&"*")),SUM(SUMIFS(_AUTO_BASE!$E:$E,_AUTO_BASE!$C:$C,_xlpm.crit,_AUTO_BASE!$I:$I,180)))} -> 0 | D29: {=_xlfn.LET(_xlpm.p,$B29,_xlpm.crit,IF(_xlpm.p="PURATOS",{"*DESTAK*","*NORCAU*"},IF(ISNUMBER(SEARCH("ICEBERG",_xlpm.p)),"*ICEBERG*","*"&_xlpm.p&"*")),SUM(SUMIFS(_AUTO_BASE!$E:$E,_AUTO_BASE!$C:$C,_xlpm.crit,_AUTO_BASE!$I:$I,400)))} -> 163896 | E29: {=_xlfn.LET(_xlpm.p,$B29,_xlpm.crit,IF(_xlpm.p="PURATOS",{"*DESTAK*","*NORCAU*"},IF(ISNUMBER(SEARCH("ICEBERG",_xlpm.p)),"*ICEBERG*","*"&_xlpm.p&"*")),SUM(SUMIFS(_AUTO_BASE!$E:$E,_AUTO_BASE!$C:$C,_xlpm.crit,_AUTO_BASE!$I:$I,600)))} -> 0 | F29: =G29-SUM(C29:E29) -> 4531 | G29: {=INDEX($C$6:$C$15,ROW()-26)} -> 168427
A30: 4º | B30: {=INDEX($B$6:$B$15,ROW()-26)} -> ADIMIX | C30: {=_xlfn.LET(_xlpm.p,$B30,_xlpm.crit,IF(_xlpm.p="PURATOS",{"*DESTAK*","*NORCAU*"},IF(ISNUMBER(SEARCH("ICEBERG",_xlpm.p)),"*ICEBERG*","*"&_xlpm.p&"*")),SUM(SUMIFS(_AUTO_BASE!$E:$E,_AUTO_BASE!$C:$C,_xlpm.crit,_AUTO_BASE!$I:$I,180)))} -> 0 | D30: {=_xlfn.LET(_xlpm.p,$B30,_xlpm.crit,IF(_xlpm.p="PURATOS",{"*DESTAK*","*NORCAU*"},IF(ISNUMBER(SEARCH("ICEBERG",_xlpm.p)),"*ICEBERG*","*"&_xlpm.p&"*")),SUM(SUMIFS(_AUTO_BASE!$E:$E,_AUTO_BASE!$C:$C,_xlpm.crit,_AUTO_BASE!$I:$I,400)))} -> 0 | E30: {=_xlfn.LET(_xlpm.p,$B30,_xlpm.crit,IF(_xlpm.p="PURATOS",{"*DESTAK*","*NORCAU*"},IF(ISNUMBER(SEARCH("ICEBERG",_xlpm.p)),"*ICEBERG*","*"&_xlpm.p&"*")),SUM(SUMIFS(_AUTO_BASE!$E:$E,_AUTO_BASE!$C:$C,_xlpm.crit,_AUTO_BASE!$I:$I,600)))} -> 120624 | F30: =G30-SUM(C30:E30) -> 0 | G30: {=INDEX($C$6:$C$15,ROW()-26)} -> 120624
A31: 5º | B31: {=INDEX($B$6:$B$15,ROW()-26)} -> ALLBREAD | C31: {=_xlfn.LET(_xlpm.p,$B31,_xlpm.crit,IF(_xlpm.p="PURATOS",{"*DESTAK*","*NORCAU*"},IF(ISNUMBER(SEARCH("ICEBERG",_xlpm.p)),"*ICEBERG*","*"&_xlpm.p&"*")),SUM(SUMIFS(_AUTO_BASE!$E:$E,_AUTO_BASE!$C:$C,_xlpm.crit,_AUTO_BASE!$I:$I,180)))} -> 0 | D31: {=_xlfn.LET(_xlpm.p,$B31,_xlpm.crit,IF(_xlpm.p="PURATOS",{"*DESTAK*","*NORCAU*"},IF(ISNUMBER(SEARCH("ICEBERG",_xlpm.p)),"*ICEBERG*","*"&_xlpm.p&"*")),SUM(SUMIFS(_AUTO_BASE!$E:$E,_AUTO_BASE!$C:$C,_xlpm.crit,_AUTO_BASE!$I:$I,400)))} -> 0 | E31: {=_xlfn.LET(_xlpm.p,$B31,_xlpm.crit,IF(_xlpm.p="PURATOS",{"*DESTAK*","*NORCAU*"},IF(ISNUMBER(SEARCH("ICEBERG",_xlpm.p)),"*ICEBERG*","*"&_xlpm.p&"*")),SUM(SUMIFS(_AUTO_BASE!$E:$E,_AUTO_BASE!$C:$C,_xlpm.crit,_AUTO_BASE!$I:$I,600)))} -> 44124 | F31: =G31-SUM(C31:E31) -> 0 | G31: {=INDEX($C$6:$C$15,ROW()-26)} -> 44124
A32: 6º | B32: {=INDEX($B$6:$B$15,ROW()-26)} -> FESTPAN | C32: {=_xlfn.LET(_xlpm.p,$B32,_xlpm.crit,IF(_xlpm.p="PURATOS",{"*DESTAK*","*NORCAU*"},IF(ISNUMBER(SEARCH("ICEBERG",_xlpm.p)),"*ICEBERG*","*"&_xlpm.p&"*")),SUM(SUMIFS(_AUTO_BASE!$E:$E,_AUTO_BASE!$C:$C,_xlpm.crit,_AUTO_BASE!$I:$I,180)))} -> 0 | D32: {=_xlfn.LET(_xlpm.p,$B32,_xlpm.crit,IF(_xlpm.p="PURATOS",{"*DESTAK*","*NORCAU*"},IF(ISNUMBER(SEARCH("ICEBERG",_xlpm.p)),"*ICEBERG*","*"&_xlpm.p&"*")),SUM(SUMIFS(_AUTO_BASE!$E:$E,_AUTO_BASE!$C:$C,_xlpm.crit,_AUTO_BASE!$I:$I,400)))} -> 43632 | E32: {=_xlfn.LET(_xlpm.p,$B32,_xlpm.crit,IF(_xlpm.p="PURATOS",{"*DESTAK*","*NORCAU*"},IF(ISNUMBER(SEARCH("ICEBERG",_xlpm.p)),"*ICEBERG*","*"&_xlpm.p&"*")),SUM(SUMIFS(_AUTO_BASE!$E:$E,_AUTO_BASE!$C:$C,_xlpm.crit,_AUTO_BASE!$I:$I,600)))} -> 0 | F32: =G32-SUM(C32:E32) -> 0 | G32: {=INDEX($C$6:$C$15,ROW()-26)} -> 43632
A33: 7º | B33: {=INDEX($B$6:$B$15,ROW()-26)} -> QUALICOCO | C33: {=_xlfn.LET(_xlpm.p,$B33,_xlpm.crit,IF(_xlpm.p="PURATOS",{"*DESTAK*","*NORCAU*"},IF(ISNUMBER(SEARCH("ICEBERG",_xlpm.p)),"*ICEBERG*","*"&_xlpm.p&"*")),SUM(SUMIFS(_AUTO_BASE!$E:$E,_AUTO_BASE!$C:$C,_xlpm.crit,_AUTO_BASE!$I:$I,180)))} -> 0 | D33: {=_xlfn.LET(_xlpm.p,$B33,_xlpm.crit,IF(_xlpm.p="PURATOS",{"*DESTAK*","*NORCAU*"},IF(ISNUMBER(SEARCH("ICEBERG",_xlpm.p)),"*ICEBERG*","*"&_xlpm.p&"*")),SUM(SUMIFS(_AUTO_BASE!$E:$E,_AUTO_BASE!$C:$C,_xlpm.crit,_AUTO_BASE!$I:$I,400)))} -> 0 | E33: {=_xlfn.LET(_xlpm.p,$B33,_xlpm.crit,IF(_xlpm.p="PURATOS",{"*DESTAK*","*NORCAU*"},IF(ISNUMBER(SEARCH("ICEBERG",_xlpm.p)),"*ICEBERG*","*"&_xlpm.p&"*")),SUM(SUMIFS(_AUTO_BASE!$E:$E,_AUTO_BASE!$C:$C,_xlpm.crit,_AUTO_BASE!$I:$I,600)))} -> 0 | F33: =G33-SUM(C33:E33) -> 34008 | G33: {=INDEX($C$6:$C$15,ROW()-26)} -> 34008
A34: 8º | B34: {=INDEX($B$6:$B$15,ROW()-26)} -> ITAIQUARA | C34: {=_xlfn.LET(_xlpm.p,$B34,_xlpm.crit,IF(_xlpm.p="PURATOS",{"*DESTAK*","*NORCAU*"},IF(ISNUMBER(SEARCH("ICEBERG",_xlpm.p)),"*ICEBERG*","*"&_xlpm.p&"*")),SUM(SUMIFS(_AUTO_BASE!$E:$E,_AUTO_BASE!$C:$C,_xlpm.crit,_AUTO_BASE!$I:$I,180)))} -> 0 | D34: {=_xlfn.LET(_xlpm.p,$B34,_xlpm.crit,IF(_xlpm.p="PURATOS",{"*DESTAK*","*NORCAU*"},IF(ISNUMBER(SEARCH("ICEBERG",_xlpm.p)),"*ICEBERG*","*"&_xlpm.p&"*")),SUM(SUMIFS(_AUTO_BASE!$E:$E,_AUTO_BASE!$C:$C,_xlpm.crit,_AUTO_BASE!$I:$I,400)))} -> 0 | E34: {=_xlfn.LET(_xlpm.p,$B34,_xlpm.crit,IF(_xlpm.p="PURATOS",{"*DESTAK*","*NORCAU*"},IF(ISNUMBER(SEARCH("ICEBERG",_xlpm.p)),"*ICEBERG*","*"&_xlpm.p&"*")),SUM(SUMIFS(_AUTO_BASE!$E:$E,_AUTO_BASE!$C:$C,_xlpm.crit,_AUTO_BASE!$I:$I,600)))} -> 25176 | F34: =G34-SUM(C34:E34) -> 0 | G34: {=INDEX($C$6:$C$15,ROW()-26)} -> 25176
A35: 9º | B35: {=INDEX($B$6:$B$15,ROW()-26)} -> DONA JURA | C35: {=_xlfn.LET(_xlpm.p,$B35,_xlpm.crit,IF(_xlpm.p="PURATOS",{"*DESTAK*","*NORCAU*"},IF(ISNUMBER(SEARCH("ICEBERG",_xlpm.p)),"*ICEBERG*","*"&_xlpm.p&"*")),SUM(SUMIFS(_AUTO_BASE!$E:$E,_AUTO_BASE!$C:$C,_xlpm.crit,_AUTO_BASE!$I:$I,180)))} -> 0 | D35: {=_xlfn.LET(_xlpm.p,$B35,_xlpm.crit,IF(_xlpm.p="PURATOS",{"*DESTAK*","*NORCAU*"},IF(ISNUMBER(SEARCH("ICEBERG",_xlpm.p)),"*ICEBERG*","*"&_xlpm.p&"*")),SUM(SUMIFS(_AUTO_BASE!$E:$E,_AUTO_BASE!$C:$C,_xlpm.crit,_AUTO_BASE!$I:$I,400)))} -> 24888 | E35: {=_xlfn.LET(_xlpm.p,$B35,_xlpm.crit,IF(_xlpm.p="PURATOS",{"*DESTAK*","*NORCAU*"},IF(ISNUMBER(SEARCH("ICEBERG",_xlpm.p)),"*ICEBERG*","*"&_xlpm.p&"*")),SUM(SUMIFS(_AUTO_BASE!$E:$E,_AUTO_BASE!$C:$C,_xlpm.crit,_AUTO_BASE!$I:$I,600)))} -> 0 | F35: =G35-SUM(C35:E35) -> 0 | G35: {=INDEX($C$6:$C$15,ROW()-26)} -> 24888
A36: 10º | B36: {=INDEX($B$6:$B$15,ROW()-26)} -> DONA LELLA | C36: {=_xlfn.LET(_xlpm.p,$B36,_xlpm.crit,IF(_xlpm.p="PURATOS",{"*DESTAK*","*NORCAU*"},IF(ISNUMBER(SEARCH("ICEBERG",_xlpm.p)),"*ICEBERG*","*"&_xlpm.p&"*")),SUM(SUMIFS(_AUTO_BASE!$E:$E,_AUTO_BASE!$C:$C,_xlpm.crit,_AUTO_BASE!$I:$I,180)))} -> 0 | D36: {=_xlfn.LET(_xlpm.p,$B36,_xlpm.crit,IF(_xlpm.p="PURATOS",{"*DESTAK*","*NORCAU*"},IF(ISNUMBER(SEARCH("ICEBERG",_xlpm.p)),"*ICEBERG*","*"&_xlpm.p&"*")),SUM(SUMIFS(_AUTO_BASE!$E:$E,_AUTO_BASE!$C:$C,_xlpm.crit,_AUTO_BASE!$I:$I,400)))} -> 19800 | E36: {=_xlfn.LET(_xlpm.p,$B36,_xlpm.crit,IF(_xlpm.p="PURATOS",{"*DESTAK*","*NORCAU*"},IF(ISNUMBER(SEARCH("ICEBERG",_xlpm.p)),"*ICEBERG*","*"&_xlpm.p&"*")),SUM(SUMIFS(_AUTO_BASE!$E:$E,_AUTO_BASE!$C:$C,_xlpm.crit,_AUTO_BASE!$I:$I,600)))} -> 0 | F36: =G36-SUM(C36:E36) -> 0 | G36: {=INDEX($C$6:$C$15,ROW()-26)} -> 19800
B37: DETALHAMENTO DOS PRODUTOS AGRUPADOS
B38: » PURATOS DESTAK | C38: =SUMIFS(_AUTO_BASE!$E:$E,_AUTO_BASE!$C:$C,"*DESTAK*",_AUTO_BASE!$I:$I,180) -> 0 | D38: =SUMIFS(_AUTO_BASE!$E:$E,_AUTO_BASE!$C:$C,"*DESTAK*",_AUTO_BASE!$I:$I,400) -> 0 | E38: =SUMIFS(_AUTO_BASE!$E:$E,_AUTO_BASE!$C:$C,"*DESTAK*",_AUTO_BASE!$I:$I,600) -> 164466 | F38: =G38-SUM(C38:E38) -> 11400 | G38: =SUMIFS(_AUTO_BASE!$E:$E,_AUTO_BASE!$C:$C,"*DESTAK*") -> 175866
B39: » PURATOS NORCAU | C39: =SUMIFS(_AUTO_BASE!$E:$E,_AUTO_BASE!$C:$C,"*NORCAU*",_AUTO_BASE!$I:$I,180) -> 0 | D39: =SUMIFS(_AUTO_BASE!$E:$E,_AUTO_BASE!$C:$C,"*NORCAU*",_AUTO_BASE!$I:$I,400) -> 0 | E39: =SUMIFS(_AUTO_BASE!$E:$E,_AUTO_BASE!$C:$C,"*NORCAU*",_AUTO_BASE!$I:$I,600) -> 76380 | F39: =G39-SUM(C39:E39) -> 0 | G39: =SUMIFS(_AUTO_BASE!$E:$E,_AUTO_BASE!$C:$C,"*NORCAU*") -> 76380
B40: » ICEBERG CHEF | C40: {=SUMIFS(_AUTO_BASE!$E:$E,_AUTO_BASE!$C:$C,"*ICEBERG*",_AUTO_BASE!$I:$I,180)-SUM(SUMIFS(_AUTO_BASE!$E:$E,_AUTO_BASE!$C:$C,{"*ICE ICEBERG*","*ICEBERG ICE*"},_AUTO_BASE!$I:$I,180))} -> 0 | D40: {=SUMIFS(_AUTO_BASE!$E:$E,_AUTO_BASE!$C:$C,"*ICEBERG*",_AUTO_BASE!$I:$I,400)-SUM(SUMIFS(_AUTO_BASE!$E:$E,_AUTO_BASE!$C:$C,{"*ICE ICEBERG*","*ICEBERG ICE*"},_AUTO_BASE!$I:$I,400))} -> 163896 | E40: {=SUMIFS(_AUTO_BASE!$E:$E,_AUTO_BASE!$C:$C,"*ICEBERG*",_AUTO_BASE!$I:$I,600)-SUM(SUMIFS(_AUTO_BASE!$E:$E,_AUTO_BASE!$C:$C,{"*ICE ICEBERG*","*ICEBERG ICE*"},_AUTO_BASE!$I:$I,600))} -> 0 | F40: =G40-SUM(C40:E40) -> 2115 | G40: {=SUMIFS(_AUTO_BASE!$E:$E,_AUTO_BASE!$C:$C,"*ICEBERG*")-SUM(SUMIFS(_AUTO_BASE!$E:$E,_AUTO_BASE!$C:$C,{"*ICE ICEBERG*","*ICEBERG ICE*"}))} -> 166011
B41: » ICEBERG ICE | C41: {=SUM(SUMIFS(_AUTO_BASE!$E:$E,_AUTO_BASE!$C:$C,{"*ICE ICEBERG*","*ICEBERG ICE*"},_AUTO_BASE!$I:$I,180))} -> 0 | D41: {=SUM(SUMIFS(_AUTO_BASE!$E:$E,_AUTO_BASE!$C:$C,{"*ICE ICEBERG*","*ICEBERG ICE*"},_AUTO_BASE!$I:$I,400))} -> 0 | E41: {=SUM(SUMIFS(_AUTO_BASE!$E:$E,_AUTO_BASE!$C:$C,{"*ICE ICEBERG*","*ICEBERG ICE*"},_AUTO_BASE!$I:$I,600))} -> 0 | F41: =G41-SUM(C41:E41) -> 2416 | G41: {=SUM(SUMIFS(_AUTO_BASE!$E:$E,_AUTO_BASE!$C:$C,{"*ICE ICEBERG*","*ICEBERG ICE*"}))} -> 2416
B43: 📖 Como ler esta tabela
B44: • Exibe os mesmos produtos do Top 10 automático, com a produção anual separada por 180 ml, 400 ml, 600 ml e Outros.
B45: • PURATOS agrupa DESTAK e NORCAU; ICEBERG CHEF é consolidado no ranking e detalhado abaixo para conferência.
B46: • A ordem acompanha automaticamente o ranking: 🥇 1º, 🥈 2º, 🥉 3º e demais posições em ordem decrescente.

Sheet JANEIRO
B1: ORDEM DE PRODUÇÃO - JANEIRO
B3: OP | C3: LOTE | E3: LOTE CLIENTE | G3: PRODUTO | K3: CLIENTE | M3: QTDE(Kg) | N3: FABRICAÇÃO
B4: 2026/001 | C4: 26010001 | G4: LISSE 600ML | K4: ADIMIX | M4: 7.980 LATAS | N4: 46027
C5: 26010002 | G5: LISSE 600ML | M5: 7.980 LATAS | N5: 46028
B6: 2026/002 | C6: 26010003 | G6: ALL BREAD 600ML | K6: ALL BREAD | M6: 9.168 LATAS | N6: 46037
B7: 2026/003 | C7: 26010004 | G7: UNTA FACIL 600ML | K7: IN LOCO | M7: 15.960 LATAS | N7: 46029
C8: 26010005 | G8: UNTA FACIL ECO 600ML | M8: 8.976 LATAS | N8: 46041 | O8: 308cxs
B9: 2026/004 | C9: 26010006 | G9: DESTAK 600ML | K9: PURATOS | M9: 22.800 LATAS | N9: 46031
B10: 2026/005 | C10: 26010007 | G10: TTF MEL 600ML | K10: TTF | M10: 3.420 LATAS | N10: 46041
B11: 2026/006 | C11: 26010008 | G11: OL 40 | K11: SMART | M11: 420 KG | N11: 46027
C12: 26010009 | G12: OL 40 | M12: 420 KG | N12: 46027
C13: 26010010 | G13: OL 40 | M13: 420 KG | N13: 46027
C14: 26010011 | G14: OL 40 | M14: 420 KG | N14: 46027
C15: 26010012 | G15: OL 40 | M15: 420 KG | N15: 46027
C16: 26010013 | G16: OL 40 | M16: 420 KG | N16: 46027
C17: 26010014 | G17: OL 40 | M17: 420 KG | N17: 46028
C18: 26010015 | G18: OL 40 | M18: 420 KG | N18: 46028
C19: 26010016 | G19: OL 40 | M19: 420 KG | N19: 46029
C20: 26010017 | G20: OL 40 | M20: 420 KG | N20: 46029
C21: 26010018 | G21: OL 40 | M21: 420 KG | N21: 46029
C22: 26010019 | G22: OL 40 | M22: 420 KG | N22: 46029
C23: 26010020 | G23: OL 40 | M23: 420 KG | N23: 46029
... C46: 26060043 | G46: AL 10 | M46: 1.444 KG | N46: 46028
B47: 2026/007 | C47: 26060044 | E47: AL 43 | G47: AL 10 - 25LTRS | K47: MATEUS | M47: 67 BBs | N47: 46028
B48: 2026/008 | C48: 26010045 | G48: DESTAK 5L | K48: PURATOS | M48: 2.500 LTRS | N48: 46035
C49: 26010046 | G49: DESTAK 5L | M49: 5.000 LTRS | N49: 46036
C50: 26010047 | G50: DESTAK 5L | M50: 1.000 LTRS | N50: 46037
C51: 26010048 | G51: DESTAK 5L | M51: 3.000 LTRS | O51: FALTARÃO 12 PALLETS PARA ENTREGAR
B52: 2026/009 | C52: 26030050 | G52: CORANTE AMARELO | K52: SMART | M52: 30 KG | N52: 46045
C53: 26030051 | G53: CORANTE AZUL | M53: 28 KG | N53: 46073
C54: 26030052 | G54: CORANTE VIOLETA | M54: 25 KG | N54: 46045
C55: 26030053 | G55: CORANTE ROSA | M55: 24 KG | N55: 46073
C56: 26030054 | G56: CORANTE VERMELHO | M56: 30 KG | N56: 46045
B57: 2026/010 | E57: 26030050 | G57: CORANTE AMARELO | K57: REPETECO | M57: 1.440 LATAS | N57: 46045
E58: 26030051 | G58: CORANTE AZUL | M58: 1.440 LATAS | N58: 46045
E59: 26030052 | G59: CORANTE VIOLETA | M59: 1.440 LATAS | N59: 46045
E60: 26030053 | G60: CORANTE ROSA | M60: 1.440 LATAS | N60: 46078
E61: 26030054 | G61: CORANTE VERMELHO | M61: 1.440 LATAS | N61: 46045
B62: 2026/011 | E62: 26030051 | G62: CORANTE AZUL | K62: IN LOCO | M62: 2.880 LATAS | N62: 46078
B63: 2026/012 | C63: 26020055 | G63: ESPUMA GENGIBRE | K63: SMART | M63: 2.340 KG | N63: 46042
...

Sheet SEMANA JANEIRO
A1: LANÇAMENTO DE PRODUÇÃO • PREENCHIMENTO RÁPIDO | J1: _TOTAL_CX_NUM | K1: _TOTAL_PALLETS_NUM | L1: _TOTAL_REALCX_NUM | M1: _TOTAL_LATAS_NUM | AA1: PRODUTO_MAPA | AB1: FAIXA_EMBALAGEM | AC1: EMB_100 | AD1: EMB_100_180 | AE1: EMB_120 | AF1: EMB_125 | AG1: EMB_180 | AH1: EMB_180_400_600 | AI1: EMB_200 | AJ1: EMB_210 | AK1: EMB_400 | AL1: EMB_400_600 | AM1: EMB_600 | AN1: EMB_70 | AO1: EMB_TODAS | AP1: EMB_DESTAK
A2: Preencha produto, embalagem e caixas. As demais colunas ajudam a leitura diária. | G2: Legenda: verde = acima da meta • vermelho = abaixo da meta | P2: Pallet PBR: 600ml=95 | 400ml=125 | 200ml=330 | 180ml=240 cx | AA2: 3 LIMÕES DILUTE | AB2: $AI$2:$AI$2 | AC2: 100 | AD2: 100 | AE2: 120 | AF2: 125 | AG2: 180 | AH2: 180 | AI2: 200 | AJ2: 210 | AK2: 400 | AL2: 400 | AM2: 600 | AN2: 70 | AO2: 70 | AP2: 5
A3: 46027 | B3: PRODUTO | C3: EMBALAGEM | D3: CAIXAS | E3: UN | F3: CX/PALLET | G3: PALLETS (PBR) | H3: REAL (CX) | I3: TOTAL LATAS | AA3: ADIMIX | AB3: $AM$2:$AM$2 | AD3: 180 | AH3: 400 | AL3: 600 | AO3: 100 | AP3: 600
L4: =IF(H4="","",H4) | N4: =IF(I4="","",I4) | AA4: ADIMIX (FADEVA) | AB4: $AM$2:$AM$2 | AH4: 600 | AO4: 125
B5: ADIMIX (PRECISION) | C5: 600 | D5: 665 | E5: CX | F5: =IF($B5="","",IF(SUMIFS(CONFIG_PALETES!$C:$C,CONFIG_PALETES!$A:$A,TRIM($B5),CONFIG_PALETES!$B:$B,$C5&" ml")>0,SUMIFS(CONFIG_PALETES!$C:$C,CONFIG_PALETES!$A:$A,TRIM($B5),CONFIG_PALETES!$B:$B,$C5&" ml"),IF(SUMIFS(CONFIG_PALETES!$C:$C,CONFIG_PALETES!$A:$A,"GERAL",CONFIG_PALETES!$B:$B,$C5&" ml")>0,SUMIFS(CONFIG_PALETES!$C:$C,CONFIG_PALETES!$A:$A,"GERAL",CONFIG_PALETES!$B:$B,$C5&" ml"),""))) -> 95 | G5: =IFERROR(ROUNDUP(D5/F5,0),"") -> 7 | H5: 667 | I5: =IF(H5="","",H5*IF(SUMIFS(CONFIG_PALETES!$D:$D,CONFIG_PALETES!$A:$A,IF(ISNUMBER(SEARCH("ESPUMA",$B5)),"ESPUMA",IF(OR(ISNUMBER(SEARCH("OLEO DE COCO",$B5)),ISNUMBER(SEARCH("ÓLEO DE COCO",$B5)),ISNUMBER(SEARCH("COPRA",$B5))),"ÓLEO DE COCO",IF(ISNUMBER(SEARCH("CORANTE",$B5)),"CORANTE",TRIM($B5)))),CONFIG_PALETES!$B:$B,$C5&" ml")>0,SUMIFS(CONFIG_PALETES!$D:$D,CONFIG_PALETES!$A:$A,IF(ISNUMBER(SEARCH("ESPUMA",$B5)),"ESPUMA",IF(OR(ISNUMBER(SEARCH("OLEO DE COCO",$B5)),ISNUMBER(SEARCH("ÓLEO DE COCO",$B5)),ISNUMBER(SEARCH("COPRA",$B5))),"ÓLEO DE COCO",IF(ISNUMBER(SEARCH("CORANTE",$B5)),"CORANTE",TRIM($B5)))),CONFIG_PALETES!$B:$B,$C5&" ml"),IF(SUMIFS(CONFIG_PALETES!$D:$D,CONFIG_PALETES!$A:$A,"GERAL",CONFIG_PALETES!$B:$B,$C5&" ml")>0,SUMIFS(CONFIG_PALETES!$D:$D,CONFIG_PALETES!$A:$A,"GERAL",CONFIG_PALETES!$B:$B,$C5&" ml"),12))) -> 8004 | J5: =IF(D5="","",ROUNDUP(D5/IF(AND(C5="600 ml",ISNUMBER(SEARCH("NORCAU",B5))),95,IF(AND(C5="600 ml",ISNUMBER(SEARCH("APURATOS",B5))),190,IF(C5="600 ml",95,IF(C5="400 ml",125,IF(C5="200 ml",330,IF(C5="180 ml",240,1)))))),0)) -> 665 | L5: =IF(H5="","",H5) -> 667 | N5: =IF(I5="","",I5) -> 8004 | AA5: ADIMIX (PRECISION) | AB5: $AM$2:$AM$2 | AO5: 180
B6: ADIMIX (FADEVA) | C6: 600 | D6: 665 | E6: CX | F6: =IF($B6="","",IF(SUMIFS(CONFIG_PALETES!$C:$C,CONFIG_PALETES!$A:$A,TRIM($B6),CONFIG_PALETES!$B:$B,$C6&" ml")>0,SUMIFS(CONFIG_PALETES!$C:$C,CONFIG_PALETES!$A:$A,TRIM($B6),CONFIG_PALETES!$B:$B,$C6&" ml"),IF(SUMIFS(CONFIG_PALETES!$C:$C,CONFIG_PALETES!$A:$A,"GERAL",CONFIG_PALETES!$B:$B,$C6&" ml")>0,SUMIFS(CONFIG_PALETES!$C:$C,CONFIG_PALETES!$A:$A,"GERAL",CONFIG_PALETES!$B:$B,$C6&" ml"),""))) -> 95 | G6: =IFERROR(ROUNDUP(D6/F6,0),"") -> 7 | H6: 29 | I6: =IF(H6="","",H6*IF(SUMIFS(CONFIG_PALETES!$D:$D,CONFIG_PALETES!$A:$A,IF(ISNUMBER(SEARCH("ESPUMA",$B6)),"ESPUMA",IF(OR(ISNUMBER(SEARCH("OLEO DE COCO",$B6)),ISNUMBER(SEARCH("ÓLEO DE COCO",$B6)),ISNUMBER(SEARCH("COPRA",$B6))),"ÓLEO DE COCO",IF(ISNUMBER(SEARCH("CORANTE",$B6)),"CORANTE",TRIM($B6)))),CONFIG_PALETES!$B:$B,$C6&" ml")>0,SUMIFS(CONFIG_PALETES!$D:$D,CONFIG_PALETES!$A:$A,IF(ISNUMBER(SEARCH("ESPUMA",$B6)),"ESPUMA",IF(OR(ISNUMBER(SEARCH("OLEO DE COCO",$B6)),ISNUMBER(SEARCH("ÓLEO DE COCO",$B6)),ISNUMBER(SEARCH("COPRA",$B6))),"ÓLEO DE COCO",IF(ISNUMBER(SEARCH("CORANTE",$B6)),"CORANTE",TRIM($B6)))),CONFIG_PALETES!$B:$B,$C6&" ml"),IF(SUMIFS(CONFIG_PALETES!$D:$D,CONFIG_PALETES!$A:$A,"GERAL",CONFIG_PALETES!$B:$B,$C6&" ml")>0,SUMIFS(CONFIG_PALETES!$D:$D,CONFIG_PALETES!$A:$A,"GERAL",CONFIG_PALETES!$B:$B,$C6&" ml"),12))) -> 348 | J6: =IF(D6="","",ROUNDUP(D6/IF(AND(C6="600 ml",ISNUMBER(SEARCH("NORCAU",B6))),95,IF(AND(C6="600 ml",ISNUMBER(SEARCH("APURATOS",B6))),190,IF(C6="600 ml",95,IF(C6="400 ml",125,IF(C6="200 ml",330,IF(C6="180 ml",240,1)))))),0)) -> 665 | L6: =IF(H6="","",H6) -> 29 | N6: =IF(I6="","",I6) -> 348 | AA6: ADIMIX LISSE | AB6: $AM$2:$AM$2 | AO6: 200
E7: CX | F7: =IF($B7="","",IF(SUMIFS(CONFIG_PALETES!$C:$C,CONFIG_PALETES!$A:$A,TRIM($B7),CONFIG_PALETES!$B:$B,$C7&" ml")>0,SUMIFS(CONFIG_PALETES!$C:$C,CONFIG_PALETES!$A:$A,TRIM($B7),CONFIG_PALETES!$B:$B,$C7&" ml"),IF(SUMIFS(CONFIG_PALETES!$C:$C,CONFIG_PALETES!$A:$A,"GERAL",CONFIG_PALETES!$B:$B,$C7&" ml")>0,SUMIFS(CONFIG_PALETES!$C:$C,CONFIG_PALETES!$A:$A,"GERAL",CONFIG_PALETES!$B:$B,$C7&" ml"),""))) | G7: =IFERROR(ROUNDUP(D7/F7,0),"") | I7: =IF(H7="","",H7*IF(SUMIFS(CONFIG_PALETES!$D:$D,CONFIG_PALETES!$A:$A,IF(ISNUMBER(SEARCH("ESPUMA",$B7)),"ESPUMA",IF(OR(ISNUMBER(SEARCH("OLEO DE COCO",$B7)),ISNUMBER(SEARCH("ÓLEO DE COCO",$B7)),ISNUMBER(SEARCH("COPRA",$B7))),"ÓLEO DE COCO",IF(ISNUMBER(SEARCH("CORANTE",$B7)),"CORANTE",TRIM($B7)))),CONFIG_PALETES!$B:$B,$C7&" ml")>0,SUMIFS(CONFIG_PALETES!$D:$D,CONFIG_PALETES!$A:$A,IF(ISNUMBER(SEARCH("ESPUMA",$B7)),"ESPUMA",IF(OR(ISNUMBER(SEARCH("OLEO DE COCO",$B7)),ISNUMBER(SEARCH("ÓLEO DE COCO",$B7)),ISNUMBER(SEARCH("COPRA",$B7))),"ÓLEO DE COCO",IF(ISNUMBER(SEARCH("CORANTE",$B7)),"CORANTE",TRIM($B7)))),CONFIG_PALETES!$B:$B,$C7&" ml"),IF(SUMIFS(CONFIG_PALETES!$D:$D,CONFIG_PALETES!$A:$A,"GERAL",CONFIG_PALETES!$B:$B,$C7&" ml")>0,SUMIFS(CONFIG_PALETES!$D:$D,CONFIG_PALETES!$A:$A,"GERAL",CONFIG_PALETES!$B:$B,$C7&" ml"),12))) | J7: =IF(D7="","",ROUNDUP(D7/IF(AND(C7="600 ml",ISNUMBER(SEARCH("NORCAU",B7))),95,IF(AND(C7="600 ml",ISNUMBER(SEARCH("APURATOS",B7))),190,IF(C7="600 ml",95,IF(C7="400 ml",125,IF(C7="200 ml",330,IF(C7="180 ml",240,1)))))),0)) | L7: =IF(H7="","",H7) | N7: =IF(I7="","",I7) | AA7: ADKO | AB7: $AG$2:$AG$2 | AO7: 400
J8: =IF(D8="","",ROUNDUP(D8/IF(AND(C8="600 ml",ISNUMBER(SEARCH("NORCAU",B8))),95,IF(AND(C8="600 ml",ISNUMBER(SEARCH("APURATOS",B8))),190,IF(C8="600 ml",95,IF(C8="400 ml",125,IF(C8="200 ml",330,IF(C8="180 ml",240,1)))))),0)) | L8: =IF(H8="","",H8) | N8: =IF(I8="","",I8) | AA8: ADKO UNTA FORMA | AB8: $AG$2:$AG$2 | AO8: 500
B9: TOTAL | D9: =SUM(D2:D8) -> 1330 | F9: — | G9: =SUM(G2:G8) -> 14 | H9: =SUM(H2:H8) -> 696 | I9: =SUM(I2:I8) -> 8352 | J9: =SUM(D4:D8) -> 1330 | K9: =SUM(G4:G8) -> 14 | L9: =SUM(H4:H8) -> 696 | M9: =SUM(I4:I8) -> 8352 | N9: =IF(I9="","",I9) -> 8352 | O9: =SUM(N5:N8) -> 8352 | Q9: {=IF(H9=0,"",SUMPRODUCT(IFERROR(INT(H4:H8/F4:F8),0)))} -> 7 | R9: =IF(Q9="","",MAX(0,G9-Q9)) -> 7 | AA9: ALL BREAD | AB9: $AM$2:$AM$2 | AO9: 600
J10: =IF(D10="","",ROUNDUP(D10/IF(AND(C10="600 ml",ISNUMBER(SEARCH("NORCAU",B10))),95,IF(AND(C10="600 ml",ISNUMBER(SEARCH("APURATOS",B10))),190,IF(C10="600 ml",95,IF(C10="400 ml",125,IF(C10="200 ml",330,IF(C10="180 ml",240,1)))))),0)) | L10: =IF(H10="","",H10) | N10: =IF(I10="","",I10) | AA10: ALL BREAD MANTEIGA | AB10: $AM$2:$AM$2
A11: 46028 | B11: PRODUTO | C11: EMBALAGEM | D11: CAIXAS | E11: UN | F11: CX/PALLET | G11: PALLETS (PBR) | H11: REAL (CX) | I11: TOTAL LATAS | AA11: ALLBREAD | AB11: $AM$2:$AM$2
J12: =IF(D12="","",ROUNDUP(D12/IF(AND(C12="600 ml",ISNUMBER(SEARCH("NORCAU",B12))),95,IF(AND(C12="600 ml",ISNUMBER(SEARCH("APURATOS",B12))),190,IF(C12="600 ml",95,IF(C12="400 ml",125,IF(C12="200 ml",330,IF(C12="180 ml",240,1)))))),0)) | L12: =IF(H12="","",H12) | N12: =IF(I12="","",I12) | AA12: ALLBREAD MANTEIGA | AB12: $AM$2:$AM$2
B13: ADIMIX (FADEVA) | C13: 600 | D13: =D6-L6 -> 636 | E13: CX | F13: =IF($B13="","",IF(SUMIFS(CONFIG_PALETES!$C:$C,CONFIG_PALETES!$A:$A,TRIM($B13),CONFIG_PALETES!$B:$B,$C13&" ml")>0,SUMIFS(CONFIG_PALETES!$C:$C,CONFIG_PALETES!$A:$A,TRIM($B13),CONFIG_PALETES!$B:$B,$C13&" ml"),IF(SUMIFS(CONFIG_PALETES!$C:$C,CONFIG_PALETES!$A:$A,"GERAL",CONFIG_PALETES!$B:$B,$C13&" ml")>0,SUMIFS(CONFIG_PALETES!$C:$C,CONFIG_PALETES!$A:$A,"GERAL",CONFIG_PALETES!$B:$B,$C13&" ml"),""))) -> 95 | G13: =IFERROR(ROUNDUP(D13/F13,0),"") -> 7 | H13: 156 | I13: =IF(H13="","",H13*IF(SUMIFS(CONFIG_PALETES!$D:$D,CONFIG_PALETES!$A:$A,IF(ISNUMBER(SEARCH("ESPUMA",$B13)),"ESPUMA",IF(OR(ISNUMBER(SEARCH("OLEO DE COCO",$B13)),ISNUMBER(SEARCH("ÓLEO DE COCO",$B13)),ISNUMBER(SEARCH("COPRA",$B13))),"ÓLEO DE COCO",IF(ISNUMBER(SEARCH("CORANTE",$B13)),"CORANTE",TRIM($B13)))),CONFIG_PALETES!$B:$B,$C13&" ml")>0,SUMIFS(CONFIG_PALETES!$D:$D,CONFIG_PALETES!$A:$A,IF(ISNUMBER(SEARCH("ESPUMA",$B13)),"ESPUMA",IF(OR(ISNUMBER(SEARCH("OLEO DE COCO",$B13)),ISNUMBER(SEARCH("ÓLEO DE COCO",$B13)),ISNUMBER(SEARCH("COPRA",$B13))),"ÓLEO DE COCO",IF(ISNUMBER(SEARCH("CORANTE",$B13)),"CORANTE",TRIM($B13)))),CONFIG_PALETES!$B:$B,$C13&" ml"),IF(SUMIFS(CONFIG_PALETES!$D:$D,CONFIG_PALETES!$A:$A,"GERAL",CONFIG_PALETES!$B:$B,$C13&" ml")>0,SUMIFS(CONFIG_PALETES!$D:$D,CONFIG_PALETES!$A:$A,"GERAL",CONFIG_PALETES!$B:$B,$C13&" ml"),12))) -> 1872 | J13: =IF(D13="","",ROUNDUP(D13/IF(AND(C13="600 ml",ISNUMBER(SEARCH("NORCAU",B13))),95,IF(AND(C13="600 ml",ISNUMBER(SEARCH("APURATOS",B13))),190,IF(C13="600 ml",95,IF(C13="400 ml",125,IF(C13="200 ml",330,IF(C13="180 ml",240,1)))))),0)) -> 636 | L13: =IF(H13="","",H13) -> 156 | N13: =IF(I13="","",I13) -> 1872 | AA13: ANTIMOFO IN LOCO | AB13: $AM$2:$AM$2
E14: CX | F14: =IF($B14="","",IF(SUMIFS(CONFIG_PALETES!$C:$C,CONFIG_PALETES!$A:$A,TRIM($B14),CONFIG_PALETES!$B:$B,$C14&" ml")>0,SUMIFS(CONFIG_PALETES!$C:$C,CONFIG_PALETES!$A:$A,TRIM($B14),CONFIG_PALETES!$B:$B,$C14&" ml"),IF(SUMIFS(CONFIG_PALETES!$C:$C,CONFIG_PALETES!$A:$A,"GERAL",CONFIG_PALETES!$B:$B,$C14&" ml")>0,SUMIFS(CONFIG_PALETES!$C:$C,CONFIG_PALETES!$A:$A,"GERAL",CONFIG_PALETES!$B:$B,$C14&" ml"),""))) | G14: =IFERROR(ROUNDUP(D14/F14,0),"") | I14: =IF(H14="","",H14*IF(SUMIFS(CONFIG_PALETES!$D:$D,CONFIG_PALETES!$A:$A,IF(ISNUMBER(SEARCH("ESPUMA",$B14)),"ESPUMA",IF(OR(ISNUMBER(SEARCH("OLEO DE COCO",$B14)),ISNUMBER(SEARCH("ÓLEO DE COCO",$B14)),ISNUMBER(SEARCH("COPRA",$B14))),"ÓLEO DE COCO",IF(ISNUMBER(SEARCH("CORANTE",$B14)),"CORANTE",TRIM($B14)))),CONFIG_PALETES!$B:$B,$C14&" ml")>0,SUMIFS(CONFIG_PALETES!$D:$D,CONFIG_PALETES!$A:$A,IF(ISNUMBER(SEARCH("ESPUMA",$B14)),"ESPUMA",IF(OR(ISNUMBER(SEARCH("OLEO DE COCO",$B14)),ISNUMBER(SEARCH("ÓLEO DE COCO",$B14)),ISNUMBER(SEARCH("COPRA",$B14))),"ÓLEO DE COCO",IF(ISNUMBER(SEARCH("CORANTE",$B14)),"CORANTE",TRIM($B14)))),CONFIG_PALETES!$B:$B,$C14&" ml"),IF(SUMIFS(CONFIG_PALETES!$D:$D,CONFIG_PALETES!$A:$A,"GERAL",CONFIG_PALETES!$B:$B,$C14&" ml")>0,SUMIFS(CONFIG_PALETES!$D:$D,CONFIG_PALETES!$A:$A,"GERAL",CONFIG_PALETES!$B:$B,$C14&" ml"),12))) | J14: =IF(D14="","",ROUNDUP(D14/IF(AND(C14="600 ml",ISNUMBER(SEARCH("NORCAU",B14))),95,IF(AND(C14="600 ml",ISNUMBER(SEARCH("APURATOS",B14))),190,IF(C14="600 ml",95,IF(C14="400 ml",125,IF(C14="200 ml",330,IF(C14="180 ml",240,1)))))),0)) | L14: =IF(H14="","",H14) | N14: =IF(I14="","",I14) | AA14: AP VIOLA | AB14: $AK$2:$AK$2
J15: =IF(D15="","",ROUNDUP(D15/IF(AND(C15="600 ml",ISNUMBER(SEARCH("NORCAU",B15))),95,IF(AND(C15="600 ml",ISNUMBER(SEARCH("APURATOS",B15))),190,IF(C15="600 ml",95,IF(C15="400 ml",125,IF(C15="200 ml",330,IF(C15="180 ml",240,1)))))),0)) | L15: =IF(H15="","",H15) | N15: =IF(I15="","",I15) | AA15: AZEITE TURMA DA MONICA | AB15: $AC$2:$AC$2
B16: TOTAL | D16: =SUM(D9:D15) -> 1966 | F16: — | G16: =SUM(G9:G15) -> 21 | H16: =SUM(H9:H15) -> 852 | I16: =SUM(I9:I15) -> 10224 | J16: =SUM(D12:D15) -> 636 | K16: =SUM(G12:G15) -> 7 | L16: =SUM(H12:H15) -> 156 | M16: =SUM(I12:I15) -> 1872 | N16: =IF(I16="","",I16) -> 10224 | O16: =SUM(N13:N15) -> 1872 | Q16: {=IF(H16=0,"",SUMPRODUCT(IFERROR(INT(H12:H15/F12:F15),0)))} -> 1 | R16: =IF(Q16="","",MAX(0,G16-Q16)) -> 20 | AA16: BONASSE | AB16: $AK$2:$AK$2
J17: =IF(D17="","",ROUNDUP(D17/IF(AND(C17="600 ml",ISNUMBER(SEARCH("NORCAU",B17))),95,IF(AND(C17="600 ml",ISNUMBER(SEARCH("APURATOS",B17))),190,IF(C17="600 ml",95,IF(C17="400 ml",125,IF(C17="200 ml",330,IF(C17="180 ml",240,1)))))),0)) | L17: =IF(H17="","",H17) | N17: =IF(I17="","",I17) | AA17: BRICOFLEX | AB17: $AK$2:$AK$2
A18: 46029 | B18: PRODUTO | C18: EMBALAGEM | D18: CAIXAS | E18: UN | F18: CX/PALLET | G18: PALLETS (PBR) | H18: REAL (CX) | I18: TOTAL LATAS | AA18: CARREFOUR COCO | AB18: $AC$2:$AC$2
J19: =IF(D19="","",ROUNDUP(D19/IF(AND(C19="600 ml",ISNUMBER(SEARCH("NORCAU",B19))),95,IF(AND(C19="600 ml",ISNUMBER(SEARCH("APURATOS",B19))),190,IF(C19="600 ml",95,IF(C19="400 ml",125,IF(C19="200 ml",330,IF(C19="180 ml",240,1)))))),0)) | L19: =IF(H19="","",H19) | N19: =IF(I19="","",I19) | AA19: CASA DO PANIFICADOR | AB19: $AK$2:$AK$2
B20: ADIMIX | C20: 600 | D20: =D13-L13 -> 480 | E20: CX | F20: =IF($B20="","",IF(SUMIFS(CONFIG_PALETES!$C:$C,CONFIG_PALETES!$A:$A,TRIM($B20),CONFIG_PALETES!$B:$B,$C20&" ml")>0,SUMIFS(CONFIG_PALETES!$C:$C,CONFIG_PALETES!$A:$A,TRIM($B20),CONFIG_PALETES!$B:$B,$C20&" ml"),IF(SUMIFS(CONFIG_PALETES!$C:$C,CONFIG_PALETES!$A:$A,"GERAL",CONFIG_PALETES!$B:$B,$C20&" ml")>0,SUMIFS(CONFIG_PALETES!$C:$C,CONFIG_PALETES!$A:$A,"GERAL",CONFIG_PALETES!$B:$B,$C20&" ml"),""))) -> 95 | G20: =IFERROR(ROUNDUP(D20/F20,0),"") -> 6 | H20: 494 | I20: =IF(H20="","",H20*IF(SUMIFS(CONFIG_PALETES!$D:$D,CONFIG_PALETES!$A:$A,IF(ISNUMBER(SEARCH("ESPUMA",$B20)),"ESPUMA",IF(OR(ISNUMBER(SEARCH("OLEO DE COCO",$B20)),ISNUMBER(SEARCH("ÓLEO DE COCO",$B20)),ISNUMBER(SEARCH("COPRA",$B20))),"ÓLEO DE COCO",IF(ISNUMBER(SEARCH("CORANTE",$B20)),"CORANTE",TRIM($B20)))),CONFIG_PALETES!$B:$B,$C20&" ml")>0,SUMIFS(CONFIG_PALETES!$D:$D,CONFIG_PALETES!$A:$A,IF(ISNUMBER(SEARCH("ESPUMA",$B20)),"ESPUMA",IF(OR(ISNUMBER(SEARCH("OLEO DE COCO",$B20)),ISNUMBER(SEARCH("ÓLEO DE COCO",$B20)),ISNUMBER(SEARCH("COPRA",$B20))),"ÓLEO DE COCO",IF(ISNUMBER(SEARCH("CORANTE",$B20)),"CORANTE",TRIM($B20)))),CONFIG_PALETES!$B:$B,$C20&" ml"),IF(SUMIFS(CONFIG_PALETES!$D:$D,CONFIG_PALETES!$A:$A,"GERAL",CONFIG_PALETES!$B:$B,$C20&" ml")>0,SUMIFS(CONFIG_PALETES!$D:$D,CONFIG_PALETES!$A:$A,"GERAL",CONFIG_PALETES!$B:$B,$C20&" ml"),12))) -> 5928 | J20: =IF(D20="","",ROUNDUP(D20/IF(AND(C20="600 ml",ISNUMBER(SEARCH("NORCAU",B20))),95,IF(AND(C20="600 ml",ISNUMBER(SEARCH("APURATOS",B20))),190,IF(C20="600 ml",95,IF(C20="400 ml",125,IF(C20="200 ml",330,IF(C20="180 ml",240,1)))))),0)) -> 480 | L20: =IF(H20="","",H20) -> 494 | N20: =IF(I20="","",I20) -> 5928 | AA20: CASA PANIFICADOR | AB20: $AK$2:$AK$2
B21: UNTA FACIL | C21: 600 | D21: 1348 | E21: CX | F21: =IF($B21="","",IF(SUMIFS(CONFIG_PALETES!$C:$C,CONFIG_PALETES!$A:$A,TRIM($B21),CONFIG_PALETES!$B:$B,$C21&" ml")>0,SUMIFS(CONFIG_PALETES!$C:$C,CONFIG_PALETES!$A:$A,TRIM($B21),CONFIG_PALETES!$B:$B,$C21&" ml"),IF(SUMIFS(CONFIG_PALETES!$C:$C,CONFIG_PALETES!$A:$A,"GERAL",CONFIG_PALETES!$B:$B,$C21&" ml")>0,SUMIFS(CONFIG_PALETES!$C:$C,CONFIG_PALETES!$A:$A,"GERAL",CONFIG_PALETES!$B:$B,$C21&" ml"),""))) -> 95 | G21: =IFERROR(ROUNDUP(D21/F21,0),"") -> 15 | H21: 509 | I21: =IF(H21="","",H21*IF(SUMIFS(CONFIG_PALETES!$D:$D,CONFIG_PALETES!$A:$A,IF(ISNUMBER(SEARCH("ESPUMA",$B21)),"ESPUMA",IF(OR(ISNUMBER(SEARCH("OLEO DE COCO",$B21)),ISNUMBER(SEARCH("ÓLEO DE COCO",$B21)),ISNUMBER(SEARCH("COPRA",$B21))),"ÓLEO DE COCO",IF(ISNUMBER(SEARCH("CORANTE",$B21)),"CORANTE",TRIM($B21)))),CONFIG_PALETES!$B:$B,$C21&" ml")>0,SUMIFS(CONFIG_PALETES!$D:$D,CONFIG_PALETES!$A:$A,IF(ISNUMBER(SEARCH("ESPUMA",$B21)),"ESPUMA",IF(OR(ISNUMBER(SEARCH("OLEO DE COCO",$B21)),ISNUMBER(SEARCH("ÓLEO DE COCO",$B21)),ISNUMBER(SEARCH("COPRA",$B21))),"ÓLEO DE COCO",IF(ISNUMBER(SEARCH("CORANTE",$B21)),"CORANTE",TRIM($B21)))),CONFIG_PALETES!$B:$B,$C21&" ml"),IF(SUMIFS(CONFIG_PALETES!$D:$D,CONFIG_PALETES!$A:$A,"GERAL",CONFIG_PALETES!$B:$B,$C21&" ml")>0,SUMIFS(CONFIG_PALETES!$D:$D,CONFIG_PALETES!$A:$A,"GERAL",CONFIG_PALETES!$B:$B,$C21&" ml"),12))) -> 6108 | J21: =IF(D21="","",ROUNDUP(D21/IF(AND(C21="600 ml",ISNUMBER(SEARCH("NORCAU",B21))),95,IF(AND(C21="600 ml",ISNUMBER(SEARCH("APURATOS",B21))),190,IF(C21="600 ml",95,IF(C21="400 ml",125,IF(C21="200 ml",330,IF(C21="180 ml",240,1)))))),0)) -> 1348 | L21: =IF(H21="","",H21) -> 509 | N21: =IF(I21="","",I21) -> 6108 | AA21: CELEBRATE | AB21: $AK$2:$AK$2
E22: CX | F22: =IF($B22="","",IF(SUMIFS(CONFIG_PALETES!$C:$C,CONFIG_PALETES!$A:$A,TRIM($B22),CONFIG_PALETES!$B:$B,$C22&" ml")>0,SUMIFS(CONFIG_PALETES!$C:$C,CONFIG_PALETES!$A:$A,TRIM($B22),CONFIG_PALETES!$B:$B,$C22&" ml"),IF(SUMIFS(CONFIG_PALETES!$C:$C,CONFIG_PALETES!$A:$A,"GERAL",CONFIG_PALETES!$B:$B,$C22&" ml")>0,SUMIFS(CONFIG_PALETES!$C:$C,CONFIG_PALETES!$A:$A,"GERAL",CONFIG_PALETES!$B:$B,$C22&" ml"),""))) | G22: =IFERROR(ROUNDUP(D22/F22,0),"") | I22: =IF(H22="","",H22*IF(SUMIFS(CONFIG_PALETES!$D:$D,CONFIG_PALETES!$A:$A,IF(ISNUMBER(SEARCH("ESPUMA",$B22)),"ESPUMA",IF(OR(ISNUMBER(SEARCH("OLEO DE COCO",$B22)),ISNUMBER(SEARCH("ÓLEO DE COCO",$B22)),ISNUMBER(SEARCH("COPRA",$B22))),"ÓLEO DE COCO",IF(ISNUMBER(SEARCH("CORANTE",$B22)),"CORANTE",TRIM($B22)))),CONFIG_PALETES!$B:$B,$C22&" ml")>0,SUMIFS(CONFIG_PALETES!$D:$D,CONFIG_PALETES!$A:$A,IF(ISNUMBER(SEARCH("ESPUMA",$B22)),"ESPUMA",IF(OR(ISNUMBER(SEARCH("OLEO DE COCO",$B22)),ISNUMBER(SEARCH("ÓLEO DE COCO",$B22)),ISNUMBER(SEARCH("COPRA",$B22))),"ÓLEO DE COCO",IF(ISNUMBER(SEARCH("CORANTE",$B22)),"CORANTE",TRIM($B22)))),CONFIG_PALETES!$B:$B,$C22&" ml"),IF(SUMIFS(CONFIG_PALETES!$D:$D,CONFIG_PALETES!$A:$A,"GERAL",CONFIG_PALETES!$B:$B,$C22&" ml")>0,SUMIFS(CONFIG_PALETES!$D:$D,CONFIG_PALETES!$A:$A,"GERAL",CONFIG_PALETES!$B:$B,$C22&" ml"),12))) | J22: =IF(D22="","",ROUNDUP(D22/IF(AND(C22="600 ml",ISNUMBER(SEARCH("NORCAU",B22))),95,IF(AND(C22="600 ml",ISNUMBER(SEARCH("APURATOS",B22))),190,IF(C22="600 ml",95,IF(C22="400 ml",125,IF(C22="200 ml",330,IF(C22="180 ml",240,1)))))),0)) | L22: =IF(H22="","",H22) | N22: =IF(I22="","",I22) | AA22: CLEIDE DOCES | AB22: $AM$2:$AM$2
J23: =IF(D23="","",ROUNDUP(D23/IF(AND(C23="600 ml",ISNUMBER(SEARCH("NORCAU",B23))),95,IF(AND(C23="600 ml",ISNUMBER(SEARCH("APURATOS",B23))),190,IF(C23="600 ml",95,IF(C23="400 ml",125,IF(C23="200 ml",330,IF(C23="180 ml",240,1)))))),0)) | L23: =IF(H23="","",H23) | N23: =IF(I23="","",I23) | AA23: COCO EXTRAVIRGEM COPRA | AB23: $AC$2:$AC$2
B24: TOTAL | D24: =SUM(D17:D23) -> 1828 | F24: — | G24: =SUM(G17:G23) -> 21 | H24: =SUM(H17:H23) -> 1003 | I24: =SUM(I17:I23) -> 12036 | J24: =SUM(D19:D23) -> 1828 | K24: =SUM(G19:G23) -> 21 | L24: =SUM(H19:H23) -> 1003 | M24: =SUM(I19:I23) -> 12036 | N24: =IF(I24="","",I24) -> 12036 | O24: =SUM(N20:N23) -> 12036 | Q24: {=IF(H24=0,"",SUMPRODUCT(IFERROR(INT(H19:H23/F19:F23),0)))} -> 10 | R24: =IF(Q24="","",MAX(0,G24-Q24)) -> 11 | AA24: COCO SEM SABOR COPRA | AB24: $AC$2:$AC$2
J25: =IF(D25="","",ROUNDUP(D25/IF(AND(C25="600 ml",ISNUMBER(SEARCH("NORCAU",B25))),95,IF(AND(C25="600 ml",ISNUMBER(SEARCH("APURATOS",B25))),190,IF(C25="600 ml",95,IF(C25="400 ml",125,IF(C25="200 ml",330,IF(C25="180 ml",240,1)))))),0)) | L25: =IF(H25="","",H25) | N25: =IF(I25="","",I25) | AA25: CONSERVANTE INLOCO | AB25: $AM$2:$AM$2
A26: 46030 | B26: PRODUTO | C26: EMBALAGEM | D26: CAIXAS | E26: UN | F26: CX/PALLET | G26: PALLETS (PBR) | H26: REAL (CX) | I26: TOTAL LATAS | AA26: COPRA EXTRAVIRGEM | AB26: $AD$2:$AD$3
J27: =IF(D27="","",ROUNDUP(D27/IF(AND(C27="600 ml",ISNUMBER(SEARCH("NORCAU",B27))),95,IF(AND(C27="600 ml",ISNUMBER(SEARCH("APURATOS",B27))),190,IF(C27="600 ml",95,IF(C27="400 ml",125,IF(C27="200 ml",330,IF(C27="180 ml",240,1)))))),0)) | L27: =IF(H27="","",H27) | N27: =IF(I27="","",I27) | AA27: COPRA MANTEIGA | AB27: $AC$2:$AC$2
B28: UNTA FACIL | C28: 600 | D28: =D21-L21 -> 839 | E28: CX | F28: =IF($B28="","",IF(SUMIFS(CONFIG_PALETES!$C:$C,CONFIG_PALETES!$A:$A,TRIM($B28),CONFIG_PALETES!$B:$B,$C28&" ml")>0,SUMIFS(CONFIG_PALETES!$C:$C,CONFIG_PALETES!$A:$A,TRIM($B28),CONFIG_PALETES!$B:$B,$C28&" ml"),IF(SUMIFS(CONFIG_PALETES!$C:$C,CONFIG_PALETES!$A:$A,"GERAL",CONFIG_PALETES!$B:$B,$C28&" ml")>0,SUMIFS(CONFIG_PALETES!$C:$C,CONFIG_PALETES!$A:$A,"GERAL",CONFIG_PALETES!$B:$B,$C28&" ml"),""))) -> 95 | G28: =IFERROR(ROUNDUP(D28/F28,0),"") -> 9 | H28: 821 | I28: =IF(H28="","",H28*IF(SUMIFS(CONFIG_PALETES!$D:$D,CONFIG_PALETES!$A:$A,IF(ISNUMBER(SEARCH("ESPUMA",$B28)),"ESPUMA",IF(OR(ISNUMBER(SEARCH("OLEO DE COCO",$B28)),ISNUMBER(SEARCH("ÓLEO DE COCO",$B28)),ISNUMBER(SEARCH("COPRA",$B28))),"ÓLEO DE COCO",IF(ISNUMBER(SEARCH("CORANTE",$B28)),"CORANTE",TRIM($B28)))),CONFIG_PALETES!$B:$B,$C28&" ml")>0,SUMIFS(CONFIG_PALETES!$D:$D,CONFIG_PALETES!$A:$A,IF(ISNUMBER(SEARCH("ESPUMA",$B28)),"ESPUMA",IF(OR(ISNUMBER(SEARCH("OLEO DE COCO",$B28)),ISNUMBER(SEARCH("ÓLEO DE COCO",$B28)),ISNUMBER(SEARCH("COPRA",$B28))),"ÓLEO DE COCO",IF(ISNUMBER(SEARCH("CORANTE",$B28)),"CORANTE",TRIM($B28)))),CONFIG_PALETES!$B:$B,$C28&" ml"),IF(SUMIFS(CONFIG_PALETES!$D:$D,CONFIG_PALETES!$A:$A,"GERAL",CONFIG_PALETES!$B:$B,$C28&" ml")>0,SUMIFS(CONFIG_PALETES!$D:$D,CONFIG_PALETES!$A:$A,"GERAL",CONFIG_PALETES!$B:$B,$C28&" ml"),12))) -> 9852 | J28: =IF(D28="","",ROUNDUP(D28/IF(AND(C28="600 ml",ISNUMBER(SEARCH("NORCAU",B28))),95,IF(AND(C28="600 ml",ISNUMBER(SEARCH("APURATOS",B28))),190,IF(C28="600 ml",95,IF(C28="400 ml",125,IF(C28="200 ml",330,IF(C28="180 ml",240,1)))))),0)) -> 839 | L28: =IF(H28="","",H28) -> 821 | N28: =IF(I28="","",I28) -> 9852 | AA28: COPRA SEM SABOR | AB28: $AC$2:$AC$2
E29: CX | F29: =IF($B29="","",IF(SUMIFS(CONFIG_PALETES!$C:$C,CONFIG_PALETES!$A:$A,TRIM($B29),CONFIG_PALETES!$B:$B,$C29&" ml")>0,SUMIFS(CONFIG_PALETES!$C:$C,CONFIG_PALETES!$A:$A,TRIM($B29),CONFIG_PALETES!$B:$B,$C29&" ml"),IF(SUMIFS(CONFIG_PALETES!$C:$C,CONFIG_PALETES!$A:$A,"GERAL",CONFIG_PALETES!$B:$B,$C29&" ml")>0,SUMIFS(CONFIG_PALETES!$C:$C,CONFIG_PALETES!$A:$A,"GERAL",CONFIG_PALETES!$B:$B,$C29&" ml"),""))) | G29: =IFERROR(ROUNDUP(D29/F29,0),"") | I29: =IF(H29="","",H29*IF(SUMIFS(CONFIG_PALETES!$D:$D,CONFIG_PALETES!$A:$A,IF(ISNUMBER(SEARCH("ESPUMA",$B29)),"ESPUMA",IF(OR(ISNUMBER(SEARCH("OLEO DE COCO",$B29)),ISNUMBER(SEARCH("ÓLEO DE COCO",$B29)),ISNUMBER(SEARCH("COPRA",$B29))),"ÓLEO DE COCO",IF(ISNUMBER(SEARCH("CORANTE",$B29)),"CORANTE",TRIM($B29)))),CONFIG_PALETES!$B:$B,$C29&" ml")>0,SUMIFS(CONFIG_PALETES!$D:$D,CONFIG_PALETES!$A:$A,IF(ISNUMBER(SEARCH("ESPUMA",$B29)),"ESPUMA",IF(OR(ISNUMBER(SEARCH("OLEO DE COCO",$B29)),ISNUMBER(SEARCH("ÓLEO DE COCO",$B29)),ISNUMBER(SEARCH("COPRA",$B29))),"ÓLEO DE COCO",IF(ISNUMBER(SEARCH("CORANTE",$B29)),"CORANTE",TRIM($B29)))),CONFIG_PALETES!$B:$B,$C29&" ml"),IF(SUMIFS(CONFIG_PALETES!$D:$D,CONFIG_PALETES!$A:$A,"GERAL",CONFIG_PALETES!$B:$B,$C29&" ml")>0,SUMIFS(CONFIG_PALETES!$D:$D,CONFIG_PALETES!$A:$A,"GERAL",CONFIG_PALETES!$B:$B,$C29&" ml"),12))) | J29: =IF(D29="","",ROUNDUP(D29/IF(AND(C29="600 ml",ISNUMBER(SEARCH("NORCAU",B29))),95,IF(AND(C29="600 ml",ISNUMBER(SEARCH("APURATOS",B29))),190,IF(C29="600 ml",95,IF(C29="400 ml",125,IF(C29="200 ml",330,IF(C29="180 ml",240,1)))))),0)) | L29: =IF(H29="","",H29) | N29: =IF(I29="","",I29) | AA29: CORANTE AMARELO | AB29: $AN$2:$AN$2
E30: CX | F30: =IF($B30="","",IF(SUMIFS(CONFIG_PALETES!$C:$C,CONFIG_PALETES!$A:$A,TRIM($B30),CONFIG_PALETES!$B:$B,$C30&" ml")>0,SUMIFS(CONFIG_PALETES!$C:$C,CONFIG_PALETES!$A:$A,TRIM($B30),CONFIG_PALETES!$B:$B,$C30&" ml"),IF(SUMIFS(CONFIG_PALETES!$C:$C,CONFIG_PALETES!$A:$A,"GERAL",CONFIG_PALETES!$B:$B,$C30&" ml")>0,SUMIFS(CONFIG_PALETES!$C:$C,CONFIG_PALETES!$A:$A,"GERAL",CONFIG_PALETES!$B:$B,$C30&" ml"),""))) | G30: =IFERROR(ROUNDUP(D30/F30,0),"") | I30: =IF(H30="","",H30*IF(SUMIFS(CONFIG_PALETES!$D:$D,CONFIG_PALETES!$A:$A,IF(ISNUMBER(SEARCH("ESPUMA",$B30)),"ESPUMA",IF(OR(ISNUMBER(SEARCH("OLEO DE COCO",$B30)),ISNUMBER(SEARCH("ÓLEO DE COCO",$B30)),ISNUMBER(SEARCH("COPRA",$B30))),"ÓLEO DE COCO",IF(ISNUMBER(SEARCH("CORANTE",$B30)),"CORANTE",TRIM($B30)))),CONFIG_PALETES!$B:$B,$C30&" ml")>0,SUMIFS(CONFIG_PALETES!$D:$D,CONFIG_PALETES!$A:$A,IF(ISNUMBER(SEARCH("ESPUMA",$B30)),"ESPUMA",IF(OR(ISNUMBER(SEARCH("OLEO DE COCO",$B30)),ISNUMBER(SEARCH("ÓLEO DE COCO",$B30)),ISNUMBER(SEARCH("COPRA",$B30))),"ÓLEO DE COCO",IF(ISNUMBER(SEARCH("CORANTE",$B30)),"CORANTE",TRIM($B30)))),CONFIG_PALETES!$B:$B,$C30&" ml"),IF(SUMIFS(CONFIG_PALETES!$D:$D,CONFIG_PALETES!$A:$A,"GERAL",CONFIG_PALETES!$B:$B,$C30&" ml")>0,SUMIFS(CONFIG_PALETES!$D:$D,CONFIG_PALETES!$A:$A,"GERAL",CONFIG_PALETES!$B:$B,$C30&" ml"),12))) | J30: =IF(D30="","",ROUNDUP(D30/IF(AND(C30="600 ml",ISNUMBER(SEARCH("NORCAU",B30))),95,IF(AND(C30="600 ml",ISNUMBER(SEARCH("APURATOS",B30))),190,IF(C30="600 ml",95,IF(C30="400 ml",125,IF(C30="200 ml",330,IF(C30="180 ml",240,1)))))),0)) | L30: =IF(H30="","",H30) | N30: =IF(I30="","",I30) | AA30: CORANTE AMARELO IN LOCO | AB30: $AN$2:$AN$2
J31: =IF(D31="","",ROUNDUP(D31/IF(AND(C31="600 ml",ISNUMBER(SEARCH("NORCAU",B31))),95,IF(AND(C31="600 ml",ISNUMBER(SEARCH("APURATOS",B31))),190,IF(C31="600 ml",95,IF(C31="400 ml",125,IF(C31="200 ml",330,IF(C31="180 ml",240,1)))))),0)) | L31: =IF(H31="","",H31) | N31: =IF(I31="","",I31) | AA31: CORANTE AMARELO REPETECO | AB31: $AN$2:$AN$2
B32: TOTAL | D32: =SUM(D25:D31) -> 839 | F32: — | G32: =SUM(G25:G31) -> 9 | H32: =SUM(H25:H31) -> 821 | I32: =SUM(I25:I31) -> 9852 | J32: =SUM(D27:D31) -> 839 | K32: =SUM(G27:G31) -> 9 | L32: =SUM(H27:H31) -> 821 | M32: =SUM(I27:I31) -> 9852 | N32: =IF(I32="","",I32) -> 9852 | O32: =SUM(N28:N31) -> 9852 | Q32: {=IF(H32=0,"",SUMPRODUCT(IFERROR(INT(H27:H31/F27:F31),0)))} -> 8 | R32: =IF(Q32="","",MAX(0,G32-Q32)) -> 1 | AA32: CORANTE AZUL | AB32: $AN$2:$AN$2
J33: =IF(D33="","",ROUNDUP(D33/IF(AND(C33="600 ml",ISNUMBER(SEARCH("NORCAU",B33))),95,IF(AND(C33="600 ml",ISNUMBER(SEARCH("APURATOS",B33))),190,IF(C33="600 ml",95,IF(C33="400 ml",125,IF(C33="200 ml",330,IF(C33="180 ml",240,1)))))),0)) | L33: =IF(H33="","",H33) | N33: =IF(I33="","",I33) | AA33: CORANTE AZUL CEU REPETECO | AB33: $AN$2:$AN$2
A34: 46031 | B34: PRODUTO | C34: EMBALAGEM | D34: CAIXAS | E34: UN | F34: CX/PALLET | G34: PALLETS (PBR) | H34: REAL (CX) | I34: TOTAL LATAS | AA34: CORANTE AZUL INLOCO | AB34: $AN$2:$AN$2
J35: =IF(D35="","",ROUNDUP(D35/IF(AND(C35="600 ml",ISNUMBER(SEARCH("NORCAU",B35))),95,IF(AND(C35="600 ml",ISNUMBER(SEARCH("APURATOS",B35))),190,IF(C35="600 ml",95,IF(C35="400 ml",125,IF(C35="200 ml",330,IF(C35="180 ml",240,1)))))),0)) | L35: =IF(H35="","",H35) | N35: =IF(I35="","",I35) | AA35: CORANTE AZUL TURQUESA REP | AB35: $AN$2:$AN$2
B36: UNTA FACIL | C36: 600 | D36: =D28-L28 -> 18 | E36: CX | F36: =IF($B36="","",IF(SUMIFS(CONFIG_PALETES!$C:$C,CONFIG_PALETES!$A:$A,TRIM($B36),CONFIG_PALETES!$B:$B,$C36&" ml")>0,SUMIFS(CONFIG_PALETES!$C:$C,CONFIG_PALETES!$A:$A,TRIM($B36),CONFIG_PALETES!$B:$B,$C36&" ml"),IF(SUMIFS(CONFIG_PALETES!$C:$C,CONFIG_PALETES!$A:$A,"GERAL",CONFIG_PALETES!$B:$B,$C36&" ml")>0,SUMIFS(CONFIG_PALETES!$C:$C,CONFIG_PALETES!$A:$A,"GERAL",CONFIG_PALETES!$B:$B,$C36&" ml"),""))) -> 95 | G36: =IFERROR(ROUNDUP(D36/F36,0),"") -> 1 | H36: 13 | I36: =IF(H36="","",H36*IF(SUMIFS(CONFIG_PALETES!$D:$D,CONFIG_PALETES!$A:$A,IF(ISNUMBER(SEARCH("ESPUMA",$B36)),"ESPUMA",IF(OR(ISNUMBER(SEARCH("OLEO DE COCO",$B36)),ISNUMBER(SEARCH("ÓLEO DE COCO",$B36)),ISNUMBER(SEARCH("COPRA",$B36))),"ÓLEO DE COCO",IF(ISNUMBER(SEARCH("CORANTE",$B36)),"CORANTE",TRIM($B36)))),CONFIG_PALETES!$B:$B,$C36&" ml")>0,SUMIFS(CONFIG_PALETES!$D:$D,CONFIG_PALETES!$A:$A,IF(ISNUMBER(SEARCH("ESPUMA",$B36)),"ESPUMA",IF(OR(ISNUMBER(SEARCH("OLEO DE COCO",$B36)),ISNUMBER(SEARCH("ÓLEO DE COCO",$B36)),ISNUMBER(SEARCH("COPRA",$B36))),"ÓLEO DE COCO",IF(ISNUMBER(SEARCH("CORANTE",$B36)),"CORANTE",TRIM($B36)))),CONFIG_PALETES!$B:$B,$C36&" ml"),IF(SUMIFS(CONFIG_PALETES!$D:$D,CONFIG_PALETES!$A:$A,"GERAL",CONFIG_PALETES!$B:$B,$C36&" ml")>0,SUMIFS(CONFIG_PALETES!$D:$D,CONFIG_PALETES!$A:$A,"GERAL",CONFIG_PALETES!$B:$B,$C36&" ml"),12))) -> 156 | J36: =IF(D36="","",ROUNDUP(D36/IF(AND(C36="600 ml",ISNUMBER(SEARCH("NORCAU",B36))),95,IF(AND(C36="600 ml",ISNUMBER(SEARCH("APURATOS",B36))),190,IF(C36="600 ml",95,IF(C36="400 ml",125,IF(C36="200 ml",330,IF(C36="180 ml",240,1)))))),0)) -> 18 | L36: =IF(H36="","",H36) -> 13 | N36: =IF(I36="","",I36) -> 156 | AA36: CORANTE LARANJA REPETECO | AB36: $AN$2:$AN$2
