Workbook
Name EMB_600: CONFIG_LISTAS!$D$2
Name EMB_600: CONFIG_LISTAS!$D$2
Name EMB_600: CONFIG_LISTAS!$D$2
Name EMB_600: CONFIG_LISTAS!$D$2
Name EMB_600: CONFIG_LISTAS!$D$2
Name EMB_COCO: CONFIG_LISTAS!$C$2:$C$3
Name EMB_COCO: CONFIG_LISTAS!$C$2:$C$3
Name EMB_COCO: CONFIG_LISTAS!$C$2:$C$3
Name EMB_COCO: CONFIG_LISTAS!$C$2:$C$3
Name EMB_COCO: CONFIG_LISTAS!$C$2:$C$3
Name EMB_CORANTE: CONFIG_LISTAS!$B$2
Name EMB_CORANTE: CONFIG_LISTAS!$B$2
Name EMB_CORANTE: CONFIG_LISTAS!$B$2
Name EMB_CORANTE: CONFIG_LISTAS!$B$2
Name EMB_CORANTE: CONFIG_LISTAS!$B$2
Name EMB_TODAS: CONFIG_LISTAS!$A$2:$A$9
Name EMB_TODAS: CONFIG_LISTAS!$A$2:$A$9
Name EMB_TODAS: CONFIG_LISTAS!$A$2:$A$9
Name EMB_TODAS: CONFIG_LISTAS!$A$2:$A$9
Name EMB_TODAS: CONFIG_LISTAS!$A$2:$A$9

Sheet INSTRUÇÕES 
B1: INSTRUÇÕES DE USO
B2: Leia antes de usar • Manual operacional da planilha • AIDU
B5: — SEÇÃO 01 • MAPA DA PLANILHA —
B7: INSTRUÇÕES | C7: Esta aba. Leia primeiro.
B8: CAPA | C8: Visão executiva do ano: total realizado, meta e melhor mês.
B9: RANKING | C9: Top 10 produtos por latas produzidas no acumulado do ano.
B10: JANEIRO … DEZEMBRO | C10: Ordem de produção do mês (OP, lote, produto, cliente).
B11: SEMANA [MÊS] | C11: ★ Aba de preenchimento diário. Só mexer aqui.
B12: GRAFICO [MÊS] | C12: Gráfico diário: realizado x meta, com campo de observações.
B13: DASHBOARD | C13: Resumo executivo anual. Atualiza automático.
B14: RESUMO_MENSAL | C14: Tabela mensal com produção, meta, gás e status.
B15: GÁS | C15: Lançamento das cargas de gás (data + quantidade em KG).
B17: — SEÇÃO 02 • PREENCHIMENTO DIÁRIO (aba SEMANA) —
B19: ✅ Preencha apenas | C19: PRODUTO • EMBALAGEM • CAIXAS
B20: 🔒 Automático | C20: CX/Pallet • Pallets (PBR) • Real (CX) • Total de Latas
B21: Dia sem produção | C21: Coloque 0. Nunca apague a linha.
B22: Sábado trabalhado | C22: Preencher normalmente.
B23: Sábado não trabalhado | C23: Colocar 0.
B25: — SEÇÃO 03 • CONTROLE DE GÁS (aba GÁS) —
B27: O que preencher | C27: Coluna A = data da carga • Coluna QUANTIDADE = KG recebido
B28: O que é automático | C28: Total mensal, maior consumo e total anual no DASHBOARD.
B29: Produtos com 6 un/cx | C29: Espuma 200ml • Puratos Destak 600ml • Óleo de Coco 200ml
B30: Demais produtos | C30: 12 un/cx
B32: — SEÇÃO 04 • CAIXAS POR PALLET (PBR) —
B34: 70 ml / 100 ml / 125 ml / 180 ml | C34: 240 cx/pallet
B35: 200 ml (Espuma e Óleo de Coco) | C35: 330 cx/pallet
B36: 400 ml | C36: 125 cx/pallet (Iceberg: 110 cx/pallet)
B37: 500 ml (somente Douratto) | C37: 95 cx/pallet
B38: 600 ml | C38: 95 cx/pallet (Puratos Destak: 190 cx/pallet)
B40: — SEÇÃO 05 • RANKING DE PRODUTOS —
B42: Aba RANKING | C42: Top 10 produtos por latas no acumulado do ano.
B43: ADIMIX | C43: Consolida todas as variações de válvula (Fadeva, Precision etc.).
B44: Atualização | C44: Dados vêm da BASE_DADOS, que reflete os lançamentos das abas SEMANA.
B46: ⚠ REGRAS IMPORTANTES — NÃO IGNORE
B48: 🚫 NÃO apagar linhas | C48: Quebra as fórmulas de soma e referência.
B49: 🚫 NÃO mexer nas fórmulas | C49: Preencha apenas os campos indicados.
B50: 🚫 NÃO inserir linhas extras | C50: Nas abas SEMANA fora dos campos estruturados.
B51: 📅 Formato de data | C51: dd/mm/aaaa (ex: 01/05/2026)
B52: 📊 Para apresentação | C52: Use DASHBOARD, RESUMO_MENSAL ou GRAFICO do mês.
B54: AIDU INDÚSTRIA • Controle de Produção 2026 • Manual operacional interno

Sheet CAPA 
B1: CONTROLE DE PRODUÇÃO | G1: 2026
B2: Visão executiva • Acompanhamento anual • AIDU Indústria
B5: TOTAL REALIZADO | D5: META ACUMULADA | F5: ATINGIMENTO | G5: MELHOR MÊS
B6: ='DASHBOARD '!A6 -> 0 | D6: ='DASHBOARD '!C6 -> 0 | F6: ='DASHBOARD '!E6 -> 0 | G6: ='DASHBOARD '!G6 -> 0
B7: latas no ano | D7: latas previstas | F7: meta x realizado | G7: pico do ano
B9: — SEÇÃO 01 • MAPA DA PLANILHA —
B11: SEMANA ▸ Preenchimento diário | E11: DASHBOARD ▸ Visão executiva
B12: Lance PRODUTO, EMBALAGEM e CAIXAS. As demais colunas calculam automaticamente. | E12: Resumo do ano: produção, meta, atingimento, melhor mês e controle de gás.
B14: GRAFICO ▸ Realizado x Meta | E14: INSTRUÇÕES ▸ Manual de uso
B15: Gráfico mensal com curva de produção, meta diária e campo de observações. | E15: Regras de preenchimento, legenda, embalagens por pallet e avisos importantes.
B17: — SEÇÃO 02 • RECOMENDAÇÕES DE USO —
B19: 1 | C19: Lance os itens do dia apenas na área amarela de preenchimento.
B20: 2 | C20: As linhas TOTAL são automáticas — não inserir, apagar ou alterar.
B21: 3 | C21: Evite inserir fórmulas nas abas SEMANA fora dos campos estruturados.
B22: 4 | C22: Para impressão ou apresentação, priorize DASHBOARD, RESUMO_MENSAL e GRAFICO do mês.
B24: AIDU INDÚSTRIA • Controle de Produção 2026 • Documento de uso interno
B26: — SEÇÃO 03 • NOSSAS LATAS —
B27: Linha de embalagens — desmoldantes, óleo de coco e douradores

Sheet RANKING 
A1: RANKING DE PRODUÇÃO | E1: AIDU.
A2: Acumulado do ano • Latas produzidas • Variações de válvula consolidadas por produto
A4: — TOP 10 PRODUTOS • LATAS PRODUZIDAS NO ANO —
A5: # | B5: Produto | C5: Latas Produzidas | D5: % do Total | E5: Posição
A6: 1 | B6: UNTA FACIL | C6: =SUMIF('SEMANA JANEIRO'!$B:$B,"*UNTA FACIL*",'SEMANA JANEIRO'!$I:$I)+SUMIF('SEMANA FEVEREIRO'!$B:$B,"*UNTA FACIL*",'SEMANA FEVEREIRO'!$I:$I)+SUMIF('SEMANA MARÇO'!$B:$B,"*UNTA FACIL*",'SEMANA MARÇO'!$I:$I)+SUMIF('SEMANA ABRIL'!$B:$B,"*UNTA FACIL*",'SEMANA ABRIL'!$I:$I)+SUMIF('SEMANA MAIO'!$B:$B,"*UNTA FACIL*",'SEMANA MAIO'!$I:$I)+SUMIF('SEMANA JUNHO'!$B:$B,"*UNTA FACIL*",'SEMANA JUNHO'!$I:$I)+SUMIF('SEMANA JULHO'!$B:$B,"*UNTA FACIL*",'SEMANA JULHO'!$I:$I)+SUMIF('SEMANA AGOSTO'!$B:$B,"*UNTA FACIL*",'SEMANA AGOSTO'!$I:$I)+SUMIF('SEMANA SETEMBRO'!$B:$B,"*UNTA FACIL*",'SEMANA SETEMBRO'!$I:$I)+SUMIF('SEMANA OUTUBRO'!$B:$B,"*UNTA FACIL*",'SEMANA OUTUBRO'!$I:$I)+SUMIF('SEMANA NOVEMBRO'!$B:$B,"*UNTA FACIL*",'SEMANA NOVEMBRO'!$I:$I)+SUMIF('SEMANA DEZEMBRO'!$B:$B,"*UNTA FACIL*",'SEMANA DEZEMBRO'!$I:$I) -> 260364 | D6: =IF($C$17=0,0,C6/$C$17) -> 0.21463318 | E6: 🥇 1º lugar
A7: 2 | B7: PURATOS | C7: =SUMIF('SEMANA JANEIRO'!$B:$B,"*DESTAK*",'SEMANA JANEIRO'!$I:$I)+SUMIF('SEMANA FEVEREIRO'!$B:$B,"*DESTAK*",'SEMANA FEVEREIRO'!$I:$I)+SUMIF('SEMANA MARÇO'!$B:$B,"*DESTAK*",'SEMANA MARÇO'!$I:$I)+SUMIF('SEMANA ABRIL'!$B:$B,"*DESTAK*",'SEMANA ABRIL'!$I:$I)+SUMIF('SEMANA MAIO'!$B:$B,"*DESTAK*",'SEMANA MAIO'!$I:$I)+SUMIF('SEMANA JUNHO'!$B:$B,"*DESTAK*",'SEMANA JUNHO'!$I:$I)+SUMIF('SEMANA JULHO'!$B:$B,"*DESTAK*",'SEMANA JULHO'!$I:$I)+SUMIF('SEMANA AGOSTO'!$B:$B,"*DESTAK*",'SEMANA AGOSTO'!$I:$I)+SUMIF('SEMANA SETEMBRO'!$B:$B,"*DESTAK*",'SEMANA SETEMBRO'!$I:$I)+SUMIF('SEMANA OUTUBRO'!$B:$B,"*DESTAK*",'SEMANA OUTUBRO'!$I:$I)+SUMIF('SEMANA NOVEMBRO'!$B:$B,"*DESTAK*",'SEMANA NOVEMBRO'!$I:$I)+SUMIF('SEMANA DEZEMBRO'!$B:$B,"*DESTAK*",'SEMANA DEZEMBRO'!$I:$I)+SUMIF('SEMANA JANEIRO'!$B:$B,"*NORCAU*",'SEMANA JANEIRO'!$I:$I)+SUMIF('SEMANA FEVEREIRO'!$B:$B,"*NORCAU*",'SEMANA FEVEREIRO'!$I:$I)+SUMIF('SEMANA MARÇO'!$B:$B,"*NORCAU*",'SEMANA MARÇO'!$I:$I)+SUMIF('SEMANA ABRIL'!$B:$B,"*NORCAU*",'SEMANA ABRIL'!$I:$I)+SUMIF('SEMANA MAIO'!$B:$B,"*NORCAU*",'SEMANA MAIO'!$I:$I)+SUMIF('SEMANA JUNHO'!$B:$B,"*NORCAU*",'SEMANA JUNHO'!$I:$I)+SUMIF('SEMANA JULHO'!$B:$B,"*NORCAU*",'SEMANA JULHO'!$I:$I)+SUMIF('SEMANA AGOSTO'!$B:$B,"*NORCAU*",'SEMANA AGOSTO'!$I:$I)+SUMIF('SEMANA SETEMBRO'!$B:$B,"*NORCAU*",'SEMANA SETEMBRO'!$I:$I)+SUMIF('SEMANA OUTUBRO'!$B:$B,"*NORCAU*",'SEMANA OUTUBRO'!$I:$I)+SUMIF('SEMANA NOVEMBRO'!$B:$B,"*NORCAU*",'SEMANA NOVEMBRO'!$I:$I)+SUMIF('SEMANA DEZEMBRO'!$B:$B,"*NORCAU*",'SEMANA DEZEMBRO'!$I:$I) -> 194394 | D7: =IF($C$17=0,0,C7/$C$17) -> 0.16025028 | E7: 🥈 2º lugar
A8: 3 | B8: ICEBERG CHEF | C8: =SUMIF('SEMANA JANEIRO'!$B:$B,"*ICEBERG*",'SEMANA JANEIRO'!$I:$I)+SUMIF('SEMANA FEVEREIRO'!$B:$B,"*ICEBERG*",'SEMANA FEVEREIRO'!$I:$I)+SUMIF('SEMANA MARÇO'!$B:$B,"*ICEBERG*",'SEMANA MARÇO'!$I:$I)+SUMIF('SEMANA ABRIL'!$B:$B,"*ICEBERG*",'SEMANA ABRIL'!$I:$I)+SUMIF('SEMANA MAIO'!$B:$B,"*ICEBERG*",'SEMANA MAIO'!$I:$I)+SUMIF('SEMANA JUNHO'!$B:$B,"*ICEBERG*",'SEMANA JUNHO'!$I:$I)+SUMIF('SEMANA JULHO'!$B:$B,"*ICEBERG*",'SEMANA JULHO'!$I:$I)+SUMIF('SEMANA AGOSTO'!$B:$B,"*ICEBERG*",'SEMANA AGOSTO'!$I:$I)+SUMIF('SEMANA SETEMBRO'!$B:$B,"*ICEBERG*",'SEMANA SETEMBRO'!$I:$I)+SUMIF('SEMANA OUTUBRO'!$B:$B,"*ICEBERG*",'SEMANA OUTUBRO'!$I:$I)+SUMIF('SEMANA NOVEMBRO'!$B:$B,"*ICEBERG*",'SEMANA NOVEMBRO'!$I:$I)+SUMIF('SEMANA DEZEMBRO'!$B:$B,"*ICEBERG*",'SEMANA DEZEMBRO'!$I:$I) -> 110523 | D8: =IF($C$17=0,0,C8/$C$17) -> 0.091110534 | E8: 🥉 3º lugar
A9: 4 | B9: ADIMIX | C9: =SUMIF('SEMANA JANEIRO'!$B:$B,"*ADIMIX*",'SEMANA JANEIRO'!$I:$I)+SUMIF('SEMANA FEVEREIRO'!$B:$B,"*ADIMIX*",'SEMANA FEVEREIRO'!$I:$I)+SUMIF('SEMANA MARÇO'!$B:$B,"*ADIMIX*",'SEMANA MARÇO'!$I:$I)+SUMIF('SEMANA ABRIL'!$B:$B,"*ADIMIX*",'SEMANA ABRIL'!$I:$I)+SUMIF('SEMANA MAIO'!$B:$B,"*ADIMIX*",'SEMANA MAIO'!$I:$I)+SUMIF('SEMANA JUNHO'!$B:$B,"*ADIMIX*",'SEMANA JUNHO'!$I:$I)+SUMIF('SEMANA JULHO'!$B:$B,"*ADIMIX*",'SEMANA JULHO'!$I:$I)+SUMIF('SEMANA AGOSTO'!$B:$B,"*ADIMIX*",'SEMANA AGOSTO'!$I:$I)+SUMIF('SEMANA SETEMBRO'!$B:$B,"*ADIMIX*",'SEMANA SETEMBRO'!$I:$I)+SUMIF('SEMANA OUTUBRO'!$B:$B,"*ADIMIX*",'SEMANA OUTUBRO'!$I:$I)+SUMIF('SEMANA NOVEMBRO'!$B:$B,"*ADIMIX*",'SEMANA NOVEMBRO'!$I:$I)+SUMIF('SEMANA DEZEMBRO'!$B:$B,"*ADIMIX*",'SEMANA DEZEMBRO'!$I:$I) -> 88332 | D9: =IF($C$17=0,0,C9/$C$17) -> 0.072817203 | E9: Top 4
A10: 5 | B10: FESTPAN | C10: =SUMIF('SEMANA JANEIRO'!$B:$B,"*FESTPAN*",'SEMANA JANEIRO'!$I:$I)+SUMIF('SEMANA FEVEREIRO'!$B:$B,"*FESTPAN*",'SEMANA FEVEREIRO'!$I:$I)+SUMIF('SEMANA MARÇO'!$B:$B,"*FESTPAN*",'SEMANA MARÇO'!$I:$I)+SUMIF('SEMANA ABRIL'!$B:$B,"*FESTPAN*",'SEMANA ABRIL'!$I:$I)+SUMIF('SEMANA MAIO'!$B:$B,"*FESTPAN*",'SEMANA MAIO'!$I:$I)+SUMIF('SEMANA JUNHO'!$B:$B,"*FESTPAN*",'SEMANA JUNHO'!$I:$I)+SUMIF('SEMANA JULHO'!$B:$B,"*FESTPAN*",'SEMANA JULHO'!$I:$I)+SUMIF('SEMANA AGOSTO'!$B:$B,"*FESTPAN*",'SEMANA AGOSTO'!$I:$I)+SUMIF('SEMANA SETEMBRO'!$B:$B,"*FESTPAN*",'SEMANA SETEMBRO'!$I:$I)+SUMIF('SEMANA OUTUBRO'!$B:$B,"*FESTPAN*",'SEMANA OUTUBRO'!$I:$I)+SUMIF('SEMANA NOVEMBRO'!$B:$B,"*FESTPAN*",'SEMANA NOVEMBRO'!$I:$I)+SUMIF('SEMANA DEZEMBRO'!$B:$B,"*FESTPAN*",'SEMANA DEZEMBRO'!$I:$I) -> 43632 | D10: =IF($C$17=0,0,C10/$C$17) -> 0.035968394 | E10: Top 5
A11: 6 | B11: QUALICOCO | C11: =SUMIF('SEMANA JANEIRO'!$B:$B,"*QUALICOCO*",'SEMANA JANEIRO'!$I:$I)+SUMIF('SEMANA FEVEREIRO'!$B:$B,"*QUALICOCO*",'SEMANA FEVEREIRO'!$I:$I)+SUMIF('SEMANA MARÇO'!$B:$B,"*QUALICOCO*",'SEMANA MARÇO'!$I:$I)+SUMIF('SEMANA ABRIL'!$B:$B,"*QUALICOCO*",'SEMANA ABRIL'!$I:$I)+SUMIF('SEMANA MAIO'!$B:$B,"*QUALICOCO*",'SEMANA MAIO'!$I:$I)+SUMIF('SEMANA JUNHO'!$B:$B,"*QUALICOCO*",'SEMANA JUNHO'!$I:$I)+SUMIF('SEMANA JULHO'!$B:$B,"*QUALICOCO*",'SEMANA JULHO'!$I:$I)+SUMIF('SEMANA AGOSTO'!$B:$B,"*QUALICOCO*",'SEMANA AGOSTO'!$I:$I)+SUMIF('SEMANA SETEMBRO'!$B:$B,"*QUALICOCO*",'SEMANA SETEMBRO'!$I:$I)+SUMIF('SEMANA OUTUBRO'!$B:$B,"*QUALICOCO*",'SEMANA OUTUBRO'!$I:$I)+SUMIF('SEMANA NOVEMBRO'!$B:$B,"*QUALICOCO*",'SEMANA NOVEMBRO'!$I:$I)+SUMIF('SEMANA DEZEMBRO'!$B:$B,"*QUALICOCO*",'SEMANA DEZEMBRO'!$I:$I) -> 34008 | D11: =IF($C$17=0,0,C11/$C$17) -> 0.028034771 | E11: Top 6
A12: 7 | B12: DONA JURA | C12: =SUMIF('SEMANA JANEIRO'!$B:$B,"*DONA JURA*",'SEMANA JANEIRO'!$I:$I)+SUMIF('SEMANA FEVEREIRO'!$B:$B,"*DONA JURA*",'SEMANA FEVEREIRO'!$I:$I)+SUMIF('SEMANA MARÇO'!$B:$B,"*DONA JURA*",'SEMANA MARÇO'!$I:$I)+SUMIF('SEMANA ABRIL'!$B:$B,"*DONA JURA*",'SEMANA ABRIL'!$I:$I)+SUMIF('SEMANA MAIO'!$B:$B,"*DONA JURA*",'SEMANA MAIO'!$I:$I)+SUMIF('SEMANA JUNHO'!$B:$B,"*DONA JURA*",'SEMANA JUNHO'!$I:$I)+SUMIF('SEMANA JULHO'!$B:$B,"*DONA JURA*",'SEMANA JULHO'!$I:$I)+SUMIF('SEMANA AGOSTO'!$B:$B,"*DONA JURA*",'SEMANA AGOSTO'!$I:$I)+SUMIF('SEMANA SETEMBRO'!$B:$B,"*DONA JURA*",'SEMANA SETEMBRO'!$I:$I)+SUMIF('SEMANA OUTUBRO'!$B:$B,"*DONA JURA*",'SEMANA OUTUBRO'!$I:$I)+SUMIF('SEMANA NOVEMBRO'!$B:$B,"*DONA JURA*",'SEMANA NOVEMBRO'!$I:$I)+SUMIF('SEMANA DEZEMBRO'!$B:$B,"*DONA JURA*",'SEMANA DEZEMBRO'!$I:$I) -> 24888 | D12: =IF($C$17=0,0,C12/$C$17) -> 0.020516625 | E12: Top 7
A13: 8 | B13: ALLBREAD | C13: =SUMIF('SEMANA JANEIRO'!$B:$B,"*ALLBREAD*",'SEMANA JANEIRO'!$I:$I)+SUMIF('SEMANA FEVEREIRO'!$B:$B,"*ALLBREAD*",'SEMANA FEVEREIRO'!$I:$I)+SUMIF('SEMANA MARÇO'!$B:$B,"*ALLBREAD*",'SEMANA MARÇO'!$I:$I)+SUMIF('SEMANA ABRIL'!$B:$B,"*ALLBREAD*",'SEMANA ABRIL'!$I:$I)+SUMIF('SEMANA MAIO'!$B:$B,"*ALLBREAD*",'SEMANA MAIO'!$I:$I)+SUMIF('SEMANA JUNHO'!$B:$B,"*ALLBREAD*",'SEMANA JUNHO'!$I:$I)+SUMIF('SEMANA JULHO'!$B:$B,"*ALLBREAD*",'SEMANA JULHO'!$I:$I)+SUMIF('SEMANA AGOSTO'!$B:$B,"*ALLBREAD*",'SEMANA AGOSTO'!$I:$I)+SUMIF('SEMANA SETEMBRO'!$B:$B,"*ALLBREAD*",'SEMANA SETEMBRO'!$I:$I)+SUMIF('SEMANA OUTUBRO'!$B:$B,"*ALLBREAD*",'SEMANA OUTUBRO'!$I:$I)+SUMIF('SEMANA NOVEMBRO'!$B:$B,"*ALLBREAD*",'SEMANA NOVEMBRO'!$I:$I)+SUMIF('SEMANA DEZEMBRO'!$B:$B,"*ALLBREAD*",'SEMANA DEZEMBRO'!$I:$I) -> 23040 | D13: =IF($C$17=0,0,C13/$C$17) -> 0.018993211 | E13: Top 8
A14: 9 | B14: DONA LELLA | C14: =SUMIF('SEMANA JANEIRO'!$B:$B,"*DONA LELLA*",'SEMANA JANEIRO'!$I:$I)+SUMIF('SEMANA FEVEREIRO'!$B:$B,"*DONA LELLA*",'SEMANA FEVEREIRO'!$I:$I)+SUMIF('SEMANA MARÇO'!$B:$B,"*DONA LELLA*",'SEMANA MARÇO'!$I:$I)+SUMIF('SEMANA ABRIL'!$B:$B,"*DONA LELLA*",'SEMANA ABRIL'!$I:$I)+SUMIF('SEMANA MAIO'!$B:$B,"*DONA LELLA*",'SEMANA MAIO'!$I:$I)+SUMIF('SEMANA JUNHO'!$B:$B,"*DONA LELLA*",'SEMANA JUNHO'!$I:$I)+SUMIF('SEMANA JULHO'!$B:$B,"*DONA LELLA*",'SEMANA JULHO'!$I:$I)+SUMIF('SEMANA AGOSTO'!$B:$B,"*DONA LELLA*",'SEMANA AGOSTO'!$I:$I)+SUMIF('SEMANA SETEMBRO'!$B:$B,"*DONA LELLA*",'SEMANA SETEMBRO'!$I:$I)+SUMIF('SEMANA OUTUBRO'!$B:$B,"*DONA LELLA*",'SEMANA OUTUBRO'!$I:$I)+SUMIF('SEMANA NOVEMBRO'!$B:$B,"*DONA LELLA*",'SEMANA NOVEMBRO'!$I:$I)+SUMIF('SEMANA DEZEMBRO'!$B:$B,"*DONA LELLA*",'SEMANA DEZEMBRO'!$I:$I) -> 19800 | D14: =IF($C$17=0,0,C14/$C$17) -> 0.016322291 | E14: Top 9
A15: 10 | B15: ITAIQUARA | C15: =SUMIF('SEMANA JANEIRO'!$B:$B,"*ITAIQUARA*",'SEMANA JANEIRO'!$I:$I)+SUMIF('SEMANA FEVEREIRO'!$B:$B,"*ITAIQUARA*",'SEMANA FEVEREIRO'!$I:$I)+SUMIF('SEMANA MARÇO'!$B:$B,"*ITAIQUARA*",'SEMANA MARÇO'!$I:$I)+SUMIF('SEMANA ABRIL'!$B:$B,"*ITAIQUARA*",'SEMANA ABRIL'!$I:$I)+SUMIF('SEMANA MAIO'!$B:$B,"*ITAIQUARA*",'SEMANA MAIO'!$I:$I)+SUMIF('SEMANA JUNHO'!$B:$B,"*ITAIQUARA*",'SEMANA JUNHO'!$I:$I)+SUMIF('SEMANA JULHO'!$B:$B,"*ITAIQUARA*",'SEMANA JULHO'!$I:$I)+SUMIF('SEMANA AGOSTO'!$B:$B,"*ITAIQUARA*",'SEMANA AGOSTO'!$I:$I)+SUMIF('SEMANA SETEMBRO'!$B:$B,"*ITAIQUARA*",'SEMANA SETEMBRO'!$I:$I)+SUMIF('SEMANA OUTUBRO'!$B:$B,"*ITAIQUARA*",'SEMANA OUTUBRO'!$I:$I)+SUMIF('SEMANA NOVEMBRO'!$B:$B,"*ITAIQUARA*",'SEMANA NOVEMBRO'!$I:$I)+SUMIF('SEMANA DEZEMBRO'!$B:$B,"*ITAIQUARA*",'SEMANA DEZEMBRO'!$I:$I) -> 17184 | D15: =IF($C$17=0,0,C15/$C$17) -> 0.01416577 | E15: Top 10
A17: TOTAL GERAL (todos os produtos) | C17: =SUMIFS('SEMANA JANEIRO'!$I:$I,'SEMANA JANEIRO'!$B:$B,"<>",'SEMANA JANEIRO'!$B:$B,"<>TOTAL",'SEMANA JANEIRO'!$B:$B,"<>PRODUTO")+SUMIFS('SEMANA FEVEREIRO'!$I:$I,'SEMANA FEVEREIRO'!$B:$B,"<>",'SEMANA FEVEREIRO'!$B:$B,"<>TOTAL",'SEMANA FEVEREIRO'!$B:$B,"<>PRODUTO")+SUMIFS('SEMANA MARÇO'!$I:$I,'SEMANA MARÇO'!$B:$B,"<>",'SEMANA MARÇO'!$B:$B,"<>TOTAL",'SEMANA MARÇO'!$B:$B,"<>PRODUTO")+SUMIFS('SEMANA ABRIL'!$I:$I,'SEMANA ABRIL'!$B:$B,"<>",'SEMANA ABRIL'!$B:$B,"<>TOTAL",'SEMANA ABRIL'!$B:$B,"<>PRODUTO")+SUMIFS('SEMANA MAIO'!$I:$I,'SEMANA MAIO'!$B:$B,"<>",'SEMANA MAIO'!$B:$B,"<>TOTAL",'SEMANA MAIO'!$B:$B,"<>PRODUTO")+SUMIFS('SEMANA JUNHO'!$I:$I,'SEMANA JUNHO'!$B:$B,"<>",'SEMANA JUNHO'!$B:$B,"<>TOTAL",'SEMANA JUNHO'!$B:$B,"<>PRODUTO")+SUMIFS('SEMANA JULHO'!$I:$I,'SEMANA JULHO'!$B:$B,"<>",'SEMANA JULHO'!$B:$B,"<>TOTAL",'SEMANA JULHO'!$B:$B,"<>PRODUTO")+SUMIFS('SEMANA AGOSTO'!$I:$I,'SEMANA AGOSTO'!$B:$B,"<>",'SEMANA AGOSTO'!$B:$B,"<>TOTAL",'SEMANA AGOSTO'!$B:$B,"<>PRODUTO")+SUMIFS('SEMANA SETEMBRO'!$I:$I,'SEMANA SETEMBRO'!$B:$B,"<>",'SEMANA SETEMBRO'!$B:$B,"<>TOTAL",'SEMANA SETEMBRO'!$B:$B,"<>PRODUTO")+SUMIFS('SEMANA OUTUBRO'!$I:$I,'SEMANA OUTUBRO'!$B:$B,"<>",'SEMANA OUTUBRO'!$B:$B,"<>TOTAL",'SEMANA OUTUBRO'!$B:$B,"<>PRODUTO")+SUMIFS('SEMANA NOVEMBRO'!$I:$I,'SEMANA NOVEMBRO'!$B:$B,"<>",'SEMANA NOVEMBRO'!$B:$B,"<>TOTAL",'SEMANA NOVEMBRO'!$B:$B,"<>PRODUTO")+SUMIFS('SEMANA DEZEMBRO'!$I:$I,'SEMANA DEZEMBRO'!$B:$B,"<>",'SEMANA DEZEMBRO'!$B:$B,"<>TOTAL",'SEMANA DEZEMBRO'!$B:$B,"<>PRODUTO") -> 1213065 | D17: 1
A19: * ADIMIX consolida todas as variações de válvula (Fadeva, Precision, etc.). Demais produtos seguem o nome exato registrado na BASE_DADOS.
A21: AIDU. • Controle de Produção 2026
A23: — RANKING POR TAMANHO DE LATA • QUEBRA POR VÁLVULA —
A24: Mesmos 10 produtos do ranking acima, separados pela válvula (tamanho da lata em ml). Coluna "Outros" agrupa demais tamanhos.
A26: # | B26: Produto | C26: 180 ml | D26: 400 ml | E26: 600 ml | F26: Outros | G26: Total
A27: 🥇 1º | B27: UNTA FACIL | C27: =SUMIFS('SEMANA JANEIRO'!$I:$I,'SEMANA JANEIRO'!$B:$B,"*UNTA FACIL*",'SEMANA JANEIRO'!$C:$C,180)+SUMIFS('SEMANA FEVEREIRO'!$I:$I,'SEMANA FEVEREIRO'!$B:$B,"*UNTA FACIL*",'SEMANA FEVEREIRO'!$C:$C,180)+SUMIFS('SEMANA MARÇO'!$I:$I,'SEMANA MARÇO'!$B:$B,"*UNTA FACIL*",'SEMANA MARÇO'!$C:$C,180)+SUMIFS('SEMANA ABRIL'!$I:$I,'SEMANA ABRIL'!$B:$B,"*UNTA FACIL*",'SEMANA ABRIL'!$C:$C,180)+SUMIFS('SEMANA MAIO'!$I:$I,'SEMANA MAIO'!$B:$B,"*UNTA FACIL*",'SEMANA MAIO'!$C:$C,180)+SUMIFS('SEMANA JUNHO'!$I:$I,'SEMANA JUNHO'!$B:$B,"*UNTA FACIL*",'SEMANA JUNHO'!$C:$C,180)+SUMIFS('SEMANA JULHO'!$I:$I,'SEMANA JULHO'!$B:$B,"*UNTA FACIL*",'SEMANA JULHO'!$C:$C,180)+SUMIFS('SEMANA AGOSTO'!$I:$I,'SEMANA AGOSTO'!$B:$B,"*UNTA FACIL*",'SEMANA AGOSTO'!$C:$C,180)+SUMIFS('SEMANA SETEMBRO'!$I:$I,'SEMANA SETEMBRO'!$B:$B,"*UNTA FACIL*",'SEMANA SETEMBRO'!$C:$C,180)+SUMIFS('SEMANA OUTUBRO'!$I:$I,'SEMANA OUTUBRO'!$B:$B,"*UNTA FACIL*",'SEMANA OUTUBRO'!$C:$C,180)+SUMIFS('SEMANA NOVEMBRO'!$I:$I,'SEMANA NOVEMBRO'!$B:$B,"*UNTA FACIL*",'SEMANA NOVEMBRO'!$C:$C,180)+SUMIFS('SEMANA DEZEMBRO'!$I:$I,'SEMANA DEZEMBRO'!$B:$B,"*UNTA FACIL*",'SEMANA DEZEMBRO'!$C:$C,180) -> 47472 | D27: =SUMIFS('SEMANA JANEIRO'!$I:$I,'SEMANA JANEIRO'!$B:$B,"*UNTA FACIL*",'SEMANA JANEIRO'!$C:$C,400)+SUMIFS('SEMANA FEVEREIRO'!$I:$I,'SEMANA FEVEREIRO'!$B:$B,"*UNTA FACIL*",'SEMANA FEVEREIRO'!$C:$C,400)+SUMIFS('SEMANA MARÇO'!$I:$I,'SEMANA MARÇO'!$B:$B,"*UNTA FACIL*",'SEMANA MARÇO'!$C:$C,400)+SUMIFS('SEMANA ABRIL'!$I:$I,'SEMANA ABRIL'!$B:$B,"*UNTA FACIL*",'SEMANA ABRIL'!$C:$C,400)+SUMIFS('SEMANA MAIO'!$I:$I,'SEMANA MAIO'!$B:$B,"*UNTA FACIL*",'SEMANA MAIO'!$C:$C,400)+SUMIFS('SEMANA JUNHO'!$I:$I,'SEMANA JUNHO'!$B:$B,"*UNTA FACIL*",'SEMANA JUNHO'!$C:$C,400)+SUMIFS('SEMANA JULHO'!$I:$I,'SEMANA JULHO'!$B:$B,"*UNTA FACIL*",'SEMANA JULHO'!$C:$C,400)+SUMIFS('SEMANA AGOSTO'!$I:$I,'SEMANA AGOSTO'!$B:$B,"*UNTA FACIL*",'SEMANA AGOSTO'!$C:$C,400)+SUMIFS('SEMANA SETEMBRO'!$I:$I,'SEMANA SETEMBRO'!$B:$B,"*UNTA FACIL*",'SEMANA SETEMBRO'!$C:$C,400)+SUMIFS('SEMANA OUTUBRO'!$I:$I,'SEMANA OUTUBRO'!$B:$B,"*UNTA FACIL*",'SEMANA OUTUBRO'!$C:$C,400)+SUMIFS('SEMANA NOVEMBRO'!$I:$I,'SEMANA NOVEMBRO'!$B:$B,"*UNTA FACIL*",'SEMANA NOVEMBRO'!$C:$C,400)+SUMIFS('SEMANA DEZEMBRO'!$I:$I,'SEMANA DEZEMBRO'!$B:$B,"*UNTA FACIL*",'SEMANA DEZEMBRO'!$C:$C,400) -> 134292 | E27: =SUMIFS('SEMANA JANEIRO'!$I:$I,'SEMANA JANEIRO'!$B:$B,"*UNTA FACIL*",'SEMANA JANEIRO'!$C:$C,600)+SUMIFS('SEMANA FEVEREIRO'!$I:$I,'SEMANA FEVEREIRO'!$B:$B,"*UNTA FACIL*",'SEMANA FEVEREIRO'!$C:$C,600)+SUMIFS('SEMANA MARÇO'!$I:$I,'SEMANA MARÇO'!$B:$B,"*UNTA FACIL*",'SEMANA MARÇO'!$C:$C,600)+SUMIFS('SEMANA ABRIL'!$I:$I,'SEMANA ABRIL'!$B:$B,"*UNTA FACIL*",'SEMANA ABRIL'!$C:$C,600)+SUMIFS('SEMANA MAIO'!$I:$I,'SEMANA MAIO'!$B:$B,"*UNTA FACIL*",'SEMANA MAIO'!$C:$C,600)+SUMIFS('SEMANA JUNHO'!$I:$I,'SEMANA JUNHO'!$B:$B,"*UNTA FACIL*",'SEMANA JUNHO'!$C:$C,600)+SUMIFS('SEMANA JULHO'!$I:$I,'SEMANA JULHO'!$B:$B,"*UNTA FACIL*",'SEMANA JULHO'!$C:$C,600)+SUMIFS('SEMANA AGOSTO'!$I:$I,'SEMANA AGOSTO'!$B:$B,"*UNTA FACIL*",'SEMANA AGOSTO'!$C:$C,600)+SUMIFS('SEMANA SETEMBRO'!$I:$I,'SEMANA SETEMBRO'!$B:$B,"*UNTA FACIL*",'SEMANA SETEMBRO'!$C:$C,600)+SUMIFS('SEMANA OUTUBRO'!$I:$I,'SEMANA OUTUBRO'!$B:$B,"*UNTA FACIL*",'SEMANA OUTUBRO'!$C:$C,600)+SUMIFS('SEMANA NOVEMBRO'!$I:$I,'SEMANA NOVEMBRO'!$B:$B,"*UNTA FACIL*",'SEMANA NOVEMBRO'!$C:$C,600)+SUMIFS('SEMANA DEZEMBRO'!$I:$I,'SEMANA DEZEMBRO'!$B:$B,"*UNTA FACIL*",'SEMANA DEZEMBRO'!$C:$C,600) -> 78600 | F27: =SUMIF('SEMANA JANEIRO'!$B:$B,"*UNTA FACIL*",'SEMANA JANEIRO'!$I:$I)+SUMIF('SEMANA FEVEREIRO'!$B:$B,"*UNTA FACIL*",'SEMANA FEVEREIRO'!$I:$I)+SUMIF('SEMANA MARÇO'!$B:$B,"*UNTA FACIL*",'SEMANA MARÇO'!$I:$I)+SUMIF('SEMANA ABRIL'!$B:$B,"*UNTA FACIL*",'SEMANA ABRIL'!$I:$I)+SUMIF('SEMANA MAIO'!$B:$B,"*UNTA FACIL*",'SEMANA MAIO'!$I:$I)+SUMIF('SEMANA JUNHO'!$B:$B,"*UNTA FACIL*",'SEMANA JUNHO'!$I:$I)+SUMIF('SEMANA JULHO'!$B:$B,"*UNTA FACIL*",'SEMANA JULHO'!$I:$I)+SUMIF('SEMANA AGOSTO'!$B:$B,"*UNTA FACIL*",'SEMANA AGOSTO'!$I:$I)+SUMIF('SEMANA SETEMBRO'!$B:$B,"*UNTA FACIL*",'SEMANA SETEMBRO'!$I:$I)+SUMIF('SEMANA OUTUBRO'!$B:$B,"*UNTA FACIL*",'SEMANA OUTUBRO'!$I:$I)+SUMIF('SEMANA NOVEMBRO'!$B:$B,"*UNTA FACIL*",'SEMANA NOVEMBRO'!$I:$I)+SUMIF('SEMANA DEZEMBRO'!$B:$B,"*UNTA FACIL*",'SEMANA DEZEMBRO'!$I:$I)-C27-D27-E27 -> 0 | G27: =C27+D27+E27+F27 -> 260364
A29: 🥈 2º | B29: PURATOS | C29: =(SUMIFS('SEMANA JANEIRO'!$I:$I,'SEMANA JANEIRO'!$B:$B,"*DESTAK*",'SEMANA JANEIRO'!$C:$C,180)+SUMIFS('SEMANA FEVEREIRO'!$I:$I,'SEMANA FEVEREIRO'!$B:$B,"*DESTAK*",'SEMANA FEVEREIRO'!$C:$C,180)+SUMIFS('SEMANA MARÇO'!$I:$I,'SEMANA MARÇO'!$B:$B,"*DESTAK*",'SEMANA MARÇO'!$C:$C,180)+SUMIFS('SEMANA ABRIL'!$I:$I,'SEMANA ABRIL'!$B:$B,"*DESTAK*",'SEMANA ABRIL'!$C:$C,180)+SUMIFS('SEMANA MAIO'!$I:$I,'SEMANA MAIO'!$B:$B,"*DESTAK*",'SEMANA MAIO'!$C:$C,180)+SUMIFS('SEMANA JUNHO'!$I:$I,'SEMANA JUNHO'!$B:$B,"*DESTAK*",'SEMANA JUNHO'!$C:$C,180)+SUMIFS('SEMANA JULHO'!$I:$I,'SEMANA JULHO'!$B:$B,"*DESTAK*",'SEMANA JULHO'!$C:$C,180)+SUMIFS('SEMANA AGOSTO'!$I:$I,'SEMANA AGOSTO'!$B:$B,"*DESTAK*",'SEMANA AGOSTO'!$C:$C,180)+SUMIFS('SEMANA SETEMBRO'!$I:$I,'SEMANA SETEMBRO'!$B:$B,"*DESTAK*",'SEMANA SETEMBRO'!$C:$C,180)+SUMIFS('SEMANA OUTUBRO'!$I:$I,'SEMANA OUTUBRO'!$B:$B,"*DESTAK*",'SEMANA OUTUBRO'!$C:$C,180)+SUMIFS('SEMANA NOVEMBRO'!$I:$I,'SEMANA NOVEMBRO'!$B:$B,"*DESTAK*",'SEMANA NOVEMBRO'!$C:$C,180)+SUMIFS('SEMANA DEZEMBRO'!$I:$I,'SEMANA DEZEMBRO'!$B:$B,"*DESTAK*",'SEMANA DEZEMBRO'!$C:$C,180))+(SUMIFS('SEMANA JANEIRO'!$I:$I,'SEMANA JANEIRO'!$B:$B,"*NORCAU*",'SEMANA JANEIRO'!$C:$C,180)+SUMIFS('SEMANA FEVEREIRO'!$I:$I,'SEMANA FEVEREIRO'!$B:$B,"*NORCAU*",'SEMANA FEVEREIRO'!$C:$C,180)+SUMIFS('SEMANA MARÇO'!$I:$I,'SEMANA MARÇO'!$B:$B,"*NORCAU*",'SEMANA MARÇO'!$C:$C,180)+SUMIFS('SEMANA ABRIL'!$I:$I,'SEMANA ABRIL'!$B:$B,"*NORCAU*",'SEMANA ABRIL'!$C:$C,180)+SUMIFS('SEMANA MAIO'!$I:$I,'SEMANA MAIO'!$B:$B,"*NORCAU*",'SEMANA MAIO'!$C:$C,180)+SUMIFS('SEMANA JUNHO'!$I:$I,'SEMANA JUNHO'!$B:$B,"*NORCAU*",'SEMANA JUNHO'!$C:$C,180)+SUMIFS('SEMANA JULHO'!$I:$I,'SEMANA JULHO'!$B:$B,"*NORCAU*",'SEMANA JULHO'!$C:$C,180)+SUMIFS('SEMANA AGOSTO'!$I:$I,'SEMANA AGOSTO'!$B:$B,"*NORCAU*",'SEMANA AGOSTO'!$C:$C,180)+SUMIFS('SEMANA SETEMBRO'!$I:$I,'SEMANA SETEMBRO'!$B:$B,"*NORCAU*",'SEMANA SETEMBRO'!$C:$C,180)+SUMIFS('SEMANA OUTUBRO'!$I:$I,'SEMANA OUTUBRO'!$B:$B,"*NORCAU*",'SEMANA OUTUBRO'!$C:$C,180)+SUMIFS('SEMANA NOVEMBRO'!$I:$I,'SEMANA NOVEMBRO'!$B:$B,"*NORCAU*",'SEMANA NOVEMBRO'!$C:$C,180)+SUMIFS('SEMANA DEZEMBRO'!$I:$I,'SEMANA DEZEMBRO'!$B:$B,"*NORCAU*",'SEMANA DEZEMBRO'!$C:$C,180)) -> 0 | D29: =(SUMIFS('SEMANA JANEIRO'!$I:$I,'SEMANA JANEIRO'!$B:$B,"*DESTAK*",'SEMANA JANEIRO'!$C:$C,400)+SUMIFS('SEMANA FEVEREIRO'!$I:$I,'SEMANA FEVEREIRO'!$B:$B,"*DESTAK*",'SEMANA FEVEREIRO'!$C:$C,400)+SUMIFS('SEMANA MARÇO'!$I:$I,'SEMANA MARÇO'!$B:$B,"*DESTAK*",'SEMANA MARÇO'!$C:$C,400)+SUMIFS('SEMANA ABRIL'!$I:$I,'SEMANA ABRIL'!$B:$B,"*DESTAK*",'SEMANA ABRIL'!$C:$C,400)+SUMIFS('SEMANA MAIO'!$I:$I,'SEMANA MAIO'!$B:$B,"*DESTAK*",'SEMANA MAIO'!$C:$C,400)+SUMIFS('SEMANA JUNHO'!$I:$I,'SEMANA JUNHO'!$B:$B,"*DESTAK*",'SEMANA JUNHO'!$C:$C,400)+SUMIFS('SEMANA JULHO'!$I:$I,'SEMANA JULHO'!$B:$B,"*DESTAK*",'SEMANA JULHO'!$C:$C,400)+SUMIFS('SEMANA AGOSTO'!$I:$I,'SEMANA AGOSTO'!$B:$B,"*DESTAK*",'SEMANA AGOSTO'!$C:$C,400)+SUMIFS('SEMANA SETEMBRO'!$I:$I,'SEMANA SETEMBRO'!$B:$B,"*DESTAK*",'SEMANA SETEMBRO'!$C:$C,400)+SUMIFS('SEMANA OUTUBRO'!$I:$I,'SEMANA OUTUBRO'!$B:$B,"*DESTAK*",'SEMANA OUTUBRO'!$C:$C,400)+SUMIFS('SEMANA NOVEMBRO'!$I:$I,'SEMANA NOVEMBRO'!$B:$B,"*DESTAK*",'SEMANA NOVEMBRO'!$C:$C,400)+SUMIFS('SEMANA DEZEMBRO'!$I:$I,'SEMANA DEZEMBRO'!$B:$B,"*DESTAK*",'SEMANA DEZEMBRO'!$C:$C,400))+(SUMIFS('SEMANA JANEIRO'!$I:$I,'SEMANA JANEIRO'!$B:$B,"*NORCAU*",'SEMANA JANEIRO'!$C:$C,400)+SUMIFS('SEMANA FEVEREIRO'!$I:$I,'SEMANA FEVEREIRO'!$B:$B,"*NORCAU*",'SEMANA FEVEREIRO'!$C:$C,400)+SUMIFS('SEMANA MARÇO'!$I:$I,'SEMANA MARÇO'!$B:$B,"*NORCAU*",'SEMANA MARÇO'!$C:$C,400)+SUMIFS('SEMANA ABRIL'!$I:$I,'SEMANA ABRIL'!$B:$B,"*NORCAU*",'SEMANA ABRIL'!$C:$C,400)+SUMIFS('SEMANA MAIO'!$I:$I,'SEMANA MAIO'!$B:$B,"*NORCAU*",'SEMANA MAIO'!$C:$C,400)+SUMIFS('SEMANA JUNHO'!$I:$I,'SEMANA JUNHO'!$B:$B,"*NORCAU*",'SEMANA JUNHO'!$C:$C,400)+SUMIFS('SEMANA JULHO'!$I:$I,'SEMANA JULHO'!$B:$B,"*NORCAU*",'SEMANA JULHO'!$C:$C,400)+SUMIFS('SEMANA AGOSTO'!$I:$I,'SEMANA AGOSTO'!$B:$B,"*NORCAU*",'SEMANA AGOSTO'!$C:$C,400)+SUMIFS('SEMANA SETEMBRO'!$I:$I,'SEMANA SETEMBRO'!$B:$B,"*NORCAU*",'SEMANA SETEMBRO'!$C:$C,400)+SUMIFS('SEMANA OUTUBRO'!$I:$I,'SEMANA OUTUBRO'!$B:$B,"*NORCAU*",'SEMANA OUTUBRO'!$C:$C,400)+SUMIFS('SEMANA NOVEMBRO'!$I:$I,'SEMANA NOVEMBRO'!$B:$B,"*NORCAU*",'SEMANA NOVEMBRO'!$C:$C,400)+SUMIFS('SEMANA DEZEMBRO'!$I:$I,'SEMANA DEZEMBRO'!$B:$B,"*NORCAU*",'SEMANA DEZEMBRO'!$C:$C,400)) -> 0 | E29: =(SUMIFS('SEMANA JANEIRO'!$I:$I,'SEMANA JANEIRO'!$B:$B,"*DESTAK*",'SEMANA JANEIRO'!$C:$C,600)+SUMIFS('SEMANA FEVEREIRO'!$I:$I,'SEMANA FEVEREIRO'!$B:$B,"*DESTAK*",'SEMANA FEVEREIRO'!$C:$C,600)+SUMIFS('SEMANA MARÇO'!$I:$I,'SEMANA MARÇO'!$B:$B,"*DESTAK*",'SEMANA MARÇO'!$C:$C,600)+SUMIFS('SEMANA ABRIL'!$I:$I,'SEMANA ABRIL'!$B:$B,"*DESTAK*",'SEMANA ABRIL'!$C:$C,600)+SUMIFS('SEMANA MAIO'!$I:$I,'SEMANA MAIO'!$B:$B,"*DESTAK*",'SEMANA MAIO'!$C:$C,600)+SUMIFS('SEMANA JUNHO'!$I:$I,'SEMANA JUNHO'!$B:$B,"*DESTAK*",'SEMANA JUNHO'!$C:$C,600)+SUMIFS('SEMANA JULHO'!$I:$I,'SEMANA JULHO'!$B:$B,"*DESTAK*",'SEMANA JULHO'!$C:$C,600)+SUMIFS('SEMANA AGOSTO'!$I:$I,'SEMANA AGOSTO'!$B:$B,"*DESTAK*",'SEMANA AGOSTO'!$C:$C,600)+SUMIFS('SEMANA SETEMBRO'!$I:$I,'SEMANA SETEMBRO'!$B:$B,"*DESTAK*",'SEMANA SETEMBRO'!$C:$C,600)+SUMIFS('SEMANA OUTUBRO'!$I:$I,'SEMANA OUTUBRO'!$B:$B,"*DESTAK*",'SEMANA OUTUBRO'!$C:$C,600)+SUMIFS('SEMANA NOVEMBRO'!$I:$I,'SEMANA NOVEMBRO'!$B:$B,"*DESTAK*",'SEMANA NOVEMBRO'!$C:$C,600)+SUMIFS('SEMANA DEZEMBRO'!$I:$I,'SEMANA DEZEMBRO'!$B:$B,"*DESTAK*",'SEMANA DEZEMBRO'!$C:$C,600))+(SUMIFS('SEMANA JANEIRO'!$I:$I,'SEMANA JANEIRO'!$B:$B,"*NORCAU*",'SEMANA JANEIRO'!$C:$C,600)+SUMIFS('SEMANA FEVEREIRO'!$I:$I,'SEMANA FEVEREIRO'!$B:$B,"*NORCAU*",'SEMANA FEVEREIRO'!$C:$C,600)+SUMIFS('SEMANA MARÇO'!$I:$I,'SEMANA MARÇO'!$B:$B,"*NORCAU*",'SEMANA MARÇO'!$C:$C,600)+SUMIFS('SEMANA ABRIL'!$I:$I,'SEMANA ABRIL'!$B:$B,"*NORCAU*",'SEMANA ABRIL'!$C:$C,600)+SUMIFS('SEMANA MAIO'!$I:$I,'SEMANA MAIO'!$B:$B,"*NORCAU*",'SEMANA MAIO'!$C:$C,600)+SUMIFS('SEMANA JUNHO'!$I:$I,'SEMANA JUNHO'!$B:$B,"*NORCAU*",'SEMANA JUNHO'!$C:$C,600)+SUMIFS('SEMANA JULHO'!$I:$I,'SEMANA JULHO'!$B:$B,"*NORCAU*",'SEMANA JULHO'!$C:$C,600)+SUMIFS('SEMANA AGOSTO'!$I:$I,'SEMANA AGOSTO'!$B:$B,"*NORCAU*",'SEMANA AGOSTO'!$C:$C,600)+SUMIFS('SEMANA SETEMBRO'!$I:$I,'SEMANA SETEMBRO'!$B:$B,"*NORCAU*",'SEMANA SETEMBRO'!$C:$C,600)+SUMIFS('SEMANA OUTUBRO'!$I:$I,'SEMANA OUTUBRO'!$B:$B,"*NORCAU*",'SEMANA OUTUBRO'!$C:$C,600)+SUMIFS('SEMANA NOVEMBRO'!$I:$I,'SEMANA NOVEMBRO'!$B:$B,"*NORCAU*",'SEMANA NOVEMBRO'!$C:$C,600)+SUMIFS('SEMANA DEZEMBRO'!$I:$I,'SEMANA DEZEMBRO'!$B:$B,"*NORCAU*",'SEMANA DEZEMBRO'!$C:$C,600)) -> 180714 | F29: =(SUMIF('SEMANA JANEIRO'!$B:$B,"*DESTAK*",'SEMANA JANEIRO'!$I:$I)+SUMIF('SEMANA FEVEREIRO'!$B:$B,"*DESTAK*",'SEMANA FEVEREIRO'!$I:$I)+SUMIF('SEMANA MARÇO'!$B:$B,"*DESTAK*",'SEMANA MARÇO'!$I:$I)+SUMIF('SEMANA ABRIL'!$B:$B,"*DESTAK*",'SEMANA ABRIL'!$I:$I)+SUMIF('SEMANA MAIO'!$B:$B,"*DESTAK*",'SEMANA MAIO'!$I:$I)+SUMIF('SEMANA JUNHO'!$B:$B,"*DESTAK*",'SEMANA JUNHO'!$I:$I)+SUMIF('SEMANA JULHO'!$B:$B,"*DESTAK*",'SEMANA JULHO'!$I:$I)+SUMIF('SEMANA AGOSTO'!$B:$B,"*DESTAK*",'SEMANA AGOSTO'!$I:$I)+SUMIF('SEMANA SETEMBRO'!$B:$B,"*DESTAK*",'SEMANA SETEMBRO'!$I:$I)+SUMIF('SEMANA OUTUBRO'!$B:$B,"*DESTAK*",'SEMANA OUTUBRO'!$I:$I)+SUMIF('SEMANA NOVEMBRO'!$B:$B,"*DESTAK*",'SEMANA NOVEMBRO'!$I:$I)+SUMIF('SEMANA DEZEMBRO'!$B:$B,"*DESTAK*",'SEMANA DEZEMBRO'!$I:$I))+(SUMIF('SEMANA JANEIRO'!$B:$B,"*NORCAU*",'SEMANA JANEIRO'!$I:$I)+SUMIF('SEMANA FEVEREIRO'!$B:$B,"*NORCAU*",'SEMANA FEVEREIRO'!$I:$I)+SUMIF('SEMANA MARÇO'!$B:$B,"*NORCAU*",'SEMANA MARÇO'!$I:$I)+SUMIF('SEMANA ABRIL'!$B:$B,"*NORCAU*",'SEMANA ABRIL'!$I:$I)+SUMIF('SEMANA MAIO'!$B:$B,"*NORCAU*",'SEMANA MAIO'!$I:$I)+SUMIF('SEMANA JUNHO'!$B:$B,"*NORCAU*",'SEMANA JUNHO'!$I:$I)+SUMIF('SEMANA JULHO'!$B:$B,"*NORCAU*",'SEMANA JULHO'!$I:$I)+SUMIF('SEMANA AGOSTO'!$B:$B,"*NORCAU*",'SEMANA AGOSTO'!$I:$I)+SUMIF('SEMANA SETEMBRO'!$B:$B,"*NORCAU*",'SEMANA SETEMBRO'!$I:$I)+SUMIF('SEMANA OUTUBRO'!$B:$B,"*NORCAU*",'SEMANA OUTUBRO'!$I:$I)+SUMIF('SEMANA NOVEMBRO'!$B:$B,"*NORCAU*",'SEMANA NOVEMBRO'!$I:$I)+SUMIF('SEMANA DEZEMBRO'!$B:$B,"*NORCAU*",'SEMANA DEZEMBRO'!$I:$I))-C29-D29-E29 -> 13680 | G29: =C29+D29+E29+F29 -> 194394
B30: » DESTAK | C30: =SUMIFS('SEMANA JANEIRO'!$I:$I,'SEMANA JANEIRO'!$B:$B,"*DESTAK*",'SEMANA JANEIRO'!$C:$C,180)+SUMIFS('SEMANA FEVEREIRO'!$I:$I,'SEMANA FEVEREIRO'!$B:$B,"*DESTAK*",'SEMANA FEVEREIRO'!$C:$C,180)+SUMIFS('SEMANA MARÇO'!$I:$I,'SEMANA MARÇO'!$B:$B,"*DESTAK*",'SEMANA MARÇO'!$C:$C,180)+SUMIFS('SEMANA ABRIL'!$I:$I,'SEMANA ABRIL'!$B:$B,"*DESTAK*",'SEMANA ABRIL'!$C:$C,180)+SUMIFS('SEMANA MAIO'!$I:$I,'SEMANA MAIO'!$B:$B,"*DESTAK*",'SEMANA MAIO'!$C:$C,180)+SUMIFS('SEMANA JUNHO'!$I:$I,'SEMANA JUNHO'!$B:$B,"*DESTAK*",'SEMANA JUNHO'!$C:$C,180)+SUMIFS('SEMANA JULHO'!$I:$I,'SEMANA JULHO'!$B:$B,"*DESTAK*",'SEMANA JULHO'!$C:$C,180)+SUMIFS('SEMANA AGOSTO'!$I:$I,'SEMANA AGOSTO'!$B:$B,"*DESTAK*",'SEMANA AGOSTO'!$C:$C,180)+SUMIFS('SEMANA SETEMBRO'!$I:$I,'SEMANA SETEMBRO'!$B:$B,"*DESTAK*",'SEMANA SETEMBRO'!$C:$C,180)+SUMIFS('SEMANA OUTUBRO'!$I:$I,'SEMANA OUTUBRO'!$B:$B,"*DESTAK*",'SEMANA OUTUBRO'!$C:$C,180)+SUMIFS('SEMANA NOVEMBRO'!$I:$I,'SEMANA NOVEMBRO'!$B:$B,"*DESTAK*",'SEMANA NOVEMBRO'!$C:$C,180)+SUMIFS('SEMANA DEZEMBRO'!$I:$I,'SEMANA DEZEMBRO'!$B:$B,"*DESTAK*",'SEMANA DEZEMBRO'!$C:$C,180) -> 0 | D30: =SUMIFS('SEMANA JANEIRO'!$I:$I,'SEMANA JANEIRO'!$B:$B,"*DESTAK*",'SEMANA JANEIRO'!$C:$C,400)+SUMIFS('SEMANA FEVEREIRO'!$I:$I,'SEMANA FEVEREIRO'!$B:$B,"*DESTAK*",'SEMANA FEVEREIRO'!$C:$C,400)+SUMIFS('SEMANA MARÇO'!$I:$I,'SEMANA MARÇO'!$B:$B,"*DESTAK*",'SEMANA MARÇO'!$C:$C,400)+SUMIFS('SEMANA ABRIL'!$I:$I,'SEMANA ABRIL'!$B:$B,"*DESTAK*",'SEMANA ABRIL'!$C:$C,400)+SUMIFS('SEMANA MAIO'!$I:$I,'SEMANA MAIO'!$B:$B,"*DESTAK*",'SEMANA MAIO'!$C:$C,400)+SUMIFS('SEMANA JUNHO'!$I:$I,'SEMANA JUNHO'!$B:$B,"*DESTAK*",'SEMANA JUNHO'!$C:$C,400)+SUMIFS('SEMANA JULHO'!$I:$I,'SEMANA JULHO'!$B:$B,"*DESTAK*",'SEMANA JULHO'!$C:$C,400)+SUMIFS('SEMANA AGOSTO'!$I:$I,'SEMANA AGOSTO'!$B:$B,"*DESTAK*",'SEMANA AGOSTO'!$C:$C,400)+SUMIFS('SEMANA SETEMBRO'!$I:$I,'SEMANA SETEMBRO'!$B:$B,"*DESTAK*",'SEMANA SETEMBRO'!$C:$C,400)+SUMIFS('SEMANA OUTUBRO'!$I:$I,'SEMANA OUTUBRO'!$B:$B,"*DESTAK*",'SEMANA OUTUBRO'!$C:$C,400)+SUMIFS('SEMANA NOVEMBRO'!$I:$I,'SEMANA NOVEMBRO'!$B:$B,"*DESTAK*",'SEMANA NOVEMBRO'!$C:$C,400)+SUMIFS('SEMANA DEZEMBRO'!$I:$I,'SEMANA DEZEMBRO'!$B:$B,"*DESTAK*",'SEMANA DEZEMBRO'!$C:$C,400) -> 0 | E30: =SUMIFS('SEMANA JANEIRO'!$I:$I,'SEMANA JANEIRO'!$B:$B,"*DESTAK*",'SEMANA JANEIRO'!$C:$C,600)+SUMIFS('SEMANA FEVEREIRO'!$I:$I,'SEMANA FEVEREIRO'!$B:$B,"*DESTAK*",'SEMANA FEVEREIRO'!$C:$C,600)+SUMIFS('SEMANA MARÇO'!$I:$I,'SEMANA MARÇO'!$B:$B,"*DESTAK*",'SEMANA MARÇO'!$C:$C,600)+SUMIFS('SEMANA ABRIL'!$I:$I,'SEMANA ABRIL'!$B:$B,"*DESTAK*",'SEMANA ABRIL'!$C:$C,600)+SUMIFS('SEMANA MAIO'!$I:$I,'SEMANA MAIO'!$B:$B,"*DESTAK*",'SEMANA MAIO'!$C:$C,600)+SUMIFS('SEMANA JUNHO'!$I:$I,'SEMANA JUNHO'!$B:$B,"*DESTAK*",'SEMANA JUNHO'!$C:$C,600)+SUMIFS('SEMANA JULHO'!$I:$I,'SEMANA JULHO'!$B:$B,"*DESTAK*",'SEMANA JULHO'!$C:$C,600)+SUMIFS('SEMANA AGOSTO'!$I:$I,'SEMANA AGOSTO'!$B:$B,"*DESTAK*",'SEMANA AGOSTO'!$C:$C,600)+SUMIFS('SEMANA SETEMBRO'!$I:$I,'SEMANA SETEMBRO'!$B:$B,"*DESTAK*",'SEMANA SETEMBRO'!$C:$C,600)+SUMIFS('SEMANA OUTUBRO'!$I:$I,'SEMANA OUTUBRO'!$B:$B,"*DESTAK*",'SEMANA OUTUBRO'!$C:$C,600)+SUMIFS('SEMANA NOVEMBRO'!$I:$I,'SEMANA NOVEMBRO'!$B:$B,"*DESTAK*",'SEMANA NOVEMBRO'!$C:$C,600)+SUMIFS('SEMANA DEZEMBRO'!$I:$I,'SEMANA DEZEMBRO'!$B:$B,"*DESTAK*",'SEMANA DEZEMBRO'!$C:$C,600) -> 132546 | F30: =SUMIF('SEMANA JANEIRO'!$B:$B,"*DESTAK*",'SEMANA JANEIRO'!$I:$I)+SUMIF('SEMANA FEVEREIRO'!$B:$B,"*DESTAK*",'SEMANA FEVEREIRO'!$I:$I)+SUMIF('SEMANA MARÇO'!$B:$B,"*DESTAK*",'SEMANA MARÇO'!$I:$I)+SUMIF('SEMANA ABRIL'!$B:$B,"*DESTAK*",'SEMANA ABRIL'!$I:$I)+SUMIF('SEMANA MAIO'!$B:$B,"*DESTAK*",'SEMANA MAIO'!$I:$I)+SUMIF('SEMANA JUNHO'!$B:$B,"*DESTAK*",'SEMANA JUNHO'!$I:$I)+SUMIF('SEMANA JULHO'!$B:$B,"*DESTAK*",'SEMANA JULHO'!$I:$I)+SUMIF('SEMANA AGOSTO'!$B:$B,"*DESTAK*",'SEMANA AGOSTO'!$I:$I)+SUMIF('SEMANA SETEMBRO'!$B:$B,"*DESTAK*",'SEMANA SETEMBRO'!$I:$I)+SUMIF('SEMANA OUTUBRO'!$B:$B,"*DESTAK*",'SEMANA OUTUBRO'!$I:$I)+SUMIF('SEMANA NOVEMBRO'!$B:$B,"*DESTAK*",'SEMANA NOVEMBRO'!$I:$I)+SUMIF('SEMANA DEZEMBRO'!$B:$B,"*DESTAK*",'SEMANA DEZEMBRO'!$I:$I)-C30-D30-E30 -> 13680 | G30: =C30+D30+E30+F30 -> 146226
B31: » NORCAU | C31: =SUMIFS('SEMANA JANEIRO'!$I:$I,'SEMANA JANEIRO'!$B:$B,"*NORCAU*",'SEMANA JANEIRO'!$C:$C,180)+SUMIFS('SEMANA FEVEREIRO'!$I:$I,'SEMANA FEVEREIRO'!$B:$B,"*NORCAU*",'SEMANA FEVEREIRO'!$C:$C,180)+SUMIFS('SEMANA MARÇO'!$I:$I,'SEMANA MARÇO'!$B:$B,"*NORCAU*",'SEMANA MARÇO'!$C:$C,180)+SUMIFS('SEMANA ABRIL'!$I:$I,'SEMANA ABRIL'!$B:$B,"*NORCAU*",'SEMANA ABRIL'!$C:$C,180)+SUMIFS('SEMANA MAIO'!$I:$I,'SEMANA MAIO'!$B:$B,"*NORCAU*",'SEMANA MAIO'!$C:$C,180)+SUMIFS('SEMANA JUNHO'!$I:$I,'SEMANA JUNHO'!$B:$B,"*NORCAU*",'SEMANA JUNHO'!$C:$C,180)+SUMIFS('SEMANA JULHO'!$I:$I,'SEMANA JULHO'!$B:$B,"*NORCAU*",'SEMANA JULHO'!$C:$C,180)+SUMIFS('SEMANA AGOSTO'!$I:$I,'SEMANA AGOSTO'!$B:$B,"*NORCAU*",'SEMANA AGOSTO'!$C:$C,180)+SUMIFS('SEMANA SETEMBRO'!$I:$I,'SEMANA SETEMBRO'!$B:$B,"*NORCAU*",'SEMANA SETEMBRO'!$C:$C,180)+SUMIFS('SEMANA OUTUBRO'!$I:$I,'SEMANA OUTUBRO'!$B:$B,"*NORCAU*",'SEMANA OUTUBRO'!$C:$C,180)+SUMIFS('SEMANA NOVEMBRO'!$I:$I,'SEMANA NOVEMBRO'!$B:$B,"*NORCAU*",'SEMANA NOVEMBRO'!$C:$C,180)+SUMIFS('SEMANA DEZEMBRO'!$I:$I,'SEMANA DEZEMBRO'!$B:$B,"*NORCAU*",'SEMANA DEZEMBRO'!$C:$C,180) -> 0 | D31: =SUMIFS('SEMANA JANEIRO'!$I:$I,'SEMANA JANEIRO'!$B:$B,"*NORCAU*",'SEMANA JANEIRO'!$C:$C,400)+SUMIFS('SEMANA FEVEREIRO'!$I:$I,'SEMANA FEVEREIRO'!$B:$B,"*NORCAU*",'SEMANA FEVEREIRO'!$C:$C,400)+SUMIFS('SEMANA MARÇO'!$I:$I,'SEMANA MARÇO'!$B:$B,"*NORCAU*",'SEMANA MARÇO'!$C:$C,400)+SUMIFS('SEMANA ABRIL'!$I:$I,'SEMANA ABRIL'!$B:$B,"*NORCAU*",'SEMANA ABRIL'!$C:$C,400)+SUMIFS('SEMANA MAIO'!$I:$I,'SEMANA MAIO'!$B:$B,"*NORCAU*",'SEMANA MAIO'!$C:$C,400)+SUMIFS('SEMANA JUNHO'!$I:$I,'SEMANA JUNHO'!$B:$B,"*NORCAU*",'SEMANA JUNHO'!$C:$C,400)+SUMIFS('SEMANA JULHO'!$I:$I,'SEMANA JULHO'!$B:$B,"*NORCAU*",'SEMANA JULHO'!$C:$C,400)+SUMIFS('SEMANA AGOSTO'!$I:$I,'SEMANA AGOSTO'!$B:$B,"*NORCAU*",'SEMANA AGOSTO'!$C:$C,400)+SUMIFS('SEMANA SETEMBRO'!$I:$I,'SEMANA SETEMBRO'!$B:$B,"*NORCAU*",'SEMANA SETEMBRO'!$C:$C,400)+SUMIFS('SEMANA OUTUBRO'!$I:$I,'SEMANA OUTUBRO'!$B:$B,"*NORCAU*",'SEMANA OUTUBRO'!$C:$C,400)+SUMIFS('SEMANA NOVEMBRO'!$I:$I,'SEMANA NOVEMBRO'!$B:$B,"*NORCAU*",'SEMANA NOVEMBRO'!$C:$C,400)+SUMIFS('SEMANA DEZEMBRO'!$I:$I,'SEMANA DEZEMBRO'!$B:$B,"*NORCAU*",'SEMANA DEZEMBRO'!$C:$C,400) -> 0 | E31: =SUMIFS('SEMANA JANEIRO'!$I:$I,'SEMANA JANEIRO'!$B:$B,"*NORCAU*",'SEMANA JANEIRO'!$C:$C,600)+SUMIFS('SEMANA FEVEREIRO'!$I:$I,'SEMANA FEVEREIRO'!$B:$B,"*NORCAU*",'SEMANA FEVEREIRO'!$C:$C,600)+SUMIFS('SEMANA MARÇO'!$I:$I,'SEMANA MARÇO'!$B:$B,"*NORCAU*",'SEMANA MARÇO'!$C:$C,600)+SUMIFS('SEMANA ABRIL'!$I:$I,'SEMANA ABRIL'!$B:$B,"*NORCAU*",'SEMANA ABRIL'!$C:$C,600)+SUMIFS('SEMANA MAIO'!$I:$I,'SEMANA MAIO'!$B:$B,"*NORCAU*",'SEMANA MAIO'!$C:$C,600)+SUMIFS('SEMANA JUNHO'!$I:$I,'SEMANA JUNHO'!$B:$B,"*NORCAU*",'SEMANA JUNHO'!$C:$C,600)+SUMIFS('SEMANA JULHO'!$I:$I,'SEMANA JULHO'!$B:$B,"*NORCAU*",'SEMANA JULHO'!$C:$C,600)+SUMIFS('SEMANA AGOSTO'!$I:$I,'SEMANA AGOSTO'!$B:$B,"*NORCAU*",'SEMANA AGOSTO'!$C:$C,600)+SUMIFS('SEMANA SETEMBRO'!$I:$I,'SEMANA SETEMBRO'!$B:$B,"*NORCAU*",'SEMANA SETEMBRO'!$C:$C,600)+SUMIFS('SEMANA OUTUBRO'!$I:$I,'SEMANA OUTUBRO'!$B:$B,"*NORCAU*",'SEMANA OUTUBRO'!$C:$C,600)+SUMIFS('SEMANA NOVEMBRO'!$I:$I,'SEMANA NOVEMBRO'!$B:$B,"*NORCAU*",'SEMANA NOVEMBRO'!$C:$C,600)+SUMIFS('SEMANA DEZEMBRO'!$I:$I,'SEMANA DEZEMBRO'!$B:$B,"*NORCAU*",'SEMANA DEZEMBRO'!$C:$C,600) -> 48168 | F31: =SUMIF('SEMANA JANEIRO'!$B:$B,"*NORCAU*",'SEMANA JANEIRO'!$I:$I)+SUMIF('SEMANA FEVEREIRO'!$B:$B,"*NORCAU*",'SEMANA FEVEREIRO'!$I:$I)+SUMIF('SEMANA MARÇO'!$B:$B,"*NORCAU*",'SEMANA MARÇO'!$I:$I)+SUMIF('SEMANA ABRIL'!$B:$B,"*NORCAU*",'SEMANA ABRIL'!$I:$I)+SUMIF('SEMANA MAIO'!$B:$B,"*NORCAU*",'SEMANA MAIO'!$I:$I)+SUMIF('SEMANA JUNHO'!$B:$B,"*NORCAU*",'SEMANA JUNHO'!$I:$I)+SUMIF('SEMANA JULHO'!$B:$B,"*NORCAU*",'SEMANA JULHO'!$I:$I)+SUMIF('SEMANA AGOSTO'!$B:$B,"*NORCAU*",'SEMANA AGOSTO'!$I:$I)+SUMIF('SEMANA SETEMBRO'!$B:$B,"*NORCAU*",'SEMANA SETEMBRO'!$I:$I)+SUMIF('SEMANA OUTUBRO'!$B:$B,"*NORCAU*",'SEMANA OUTUBRO'!$I:$I)+SUMIF('SEMANA NOVEMBRO'!$B:$B,"*NORCAU*",'SEMANA NOVEMBRO'!$I:$I)+SUMIF('SEMANA DEZEMBRO'!$B:$B,"*NORCAU*",'SEMANA DEZEMBRO'!$I:$I)-C31-D31-E31 -> 0 | G31: =C31+D31+E31+F31 -> 48168
A32: 🥉 3º | B32: ICEBERG CHEF | C32: =SUMIFS('SEMANA JANEIRO'!$I:$I,'SEMANA JANEIRO'!$B:$B,"*ICEBERG*",'SEMANA JANEIRO'!$C:$C,180)+SUMIFS('SEMANA FEVEREIRO'!$I:$I,'SEMANA FEVEREIRO'!$B:$B,"*ICEBERG*",'SEMANA FEVEREIRO'!$C:$C,180)+SUMIFS('SEMANA MARÇO'!$I:$I,'SEMANA MARÇO'!$B:$B,"*ICEBERG*",'SEMANA MARÇO'!$C:$C,180)+SUMIFS('SEMANA ABRIL'!$I:$I,'SEMANA ABRIL'!$B:$B,"*ICEBERG*",'SEMANA ABRIL'!$C:$C,180)+SUMIFS('SEMANA MAIO'!$I:$I,'SEMANA MAIO'!$B:$B,"*ICEBERG*",'SEMANA MAIO'!$C:$C,180)+SUMIFS('SEMANA JUNHO'!$I:$I,'SEMANA JUNHO'!$B:$B,"*ICEBERG*",'SEMANA JUNHO'!$C:$C,180)+SUMIFS('SEMANA JULHO'!$I:$I,'SEMANA JULHO'!$B:$B,"*ICEBERG*",'SEMANA JULHO'!$C:$C,180)+SUMIFS('SEMANA AGOSTO'!$I:$I,'SEMANA AGOSTO'!$B:$B,"*ICEBERG*",'SEMANA AGOSTO'!$C:$C,180)+SUMIFS('SEMANA SETEMBRO'!$I:$I,'SEMANA SETEMBRO'!$B:$B,"*ICEBERG*",'SEMANA SETEMBRO'!$C:$C,180)+SUMIFS('SEMANA OUTUBRO'!$I:$I,'SEMANA OUTUBRO'!$B:$B,"*ICEBERG*",'SEMANA OUTUBRO'!$C:$C,180)+SUMIFS('SEMANA NOVEMBRO'!$I:$I,'SEMANA NOVEMBRO'!$B:$B,"*ICEBERG*",'SEMANA NOVEMBRO'!$C:$C,180)+SUMIFS('SEMANA DEZEMBRO'!$I:$I,'SEMANA DEZEMBRO'!$B:$B,"*ICEBERG*",'SEMANA DEZEMBRO'!$C:$C,180) -> 0 | D32: =SUMIFS('SEMANA JANEIRO'!$I:$I,'SEMANA JANEIRO'!$B:$B,"*ICEBERG*",'SEMANA JANEIRO'!$C:$C,400)+SUMIFS('SEMANA FEVEREIRO'!$I:$I,'SEMANA FEVEREIRO'!$B:$B,"*ICEBERG*",'SEMANA FEVEREIRO'!$C:$C,400)+SUMIFS('SEMANA MARÇO'!$I:$I,'SEMANA MARÇO'!$B:$B,"*ICEBERG*",'SEMANA MARÇO'!$C:$C,400)+SUMIFS('SEMANA ABRIL'!$I:$I,'SEMANA ABRIL'!$B:$B,"*ICEBERG*",'SEMANA ABRIL'!$C:$C,400)+SUMIFS('SEMANA MAIO'!$I:$I,'SEMANA MAIO'!$B:$B,"*ICEBERG*",'SEMANA MAIO'!$C:$C,400)+SUMIFS('SEMANA JUNHO'!$I:$I,'SEMANA JUNHO'!$B:$B,"*ICEBERG*",'SEMANA JUNHO'!$C:$C,400)+SUMIFS('SEMANA JULHO'!$I:$I,'SEMANA JULHO'!$B:$B,"*ICEBERG*",'SEMANA JULHO'!$C:$C,400)+SUMIFS('SEMANA AGOSTO'!$I:$I,'SEMANA AGOSTO'!$B:$B,"*ICEBERG*",'SEMANA AGOSTO'!$C:$C,400)+SUMIFS('SEMANA SETEMBRO'!$I:$I,'SEMANA SETEMBRO'!$B:$B,"*ICEBERG*",'SEMANA SETEMBRO'!$C:$C,400)+SUMIFS('SEMANA OUTUBRO'!$I:$I,'SEMANA OUTUBRO'!$B:$B,"*ICEBERG*",'SEMANA OUTUBRO'!$C:$C,400)+SUMIFS('SEMANA NOVEMBRO'!$I:$I,'SEMANA NOVEMBRO'!$B:$B,"*ICEBERG*",'SEMANA NOVEMBRO'!$C:$C,400)+SUMIFS('SEMANA DEZEMBRO'!$I:$I,'SEMANA DEZEMBRO'!$B:$B,"*ICEBERG*",'SEMANA DEZEMBRO'!$C:$C,400) -> 108408 | E32: =SUMIFS('SEMANA JANEIRO'!$I:$I,'SEMANA JANEIRO'!$B:$B,"*ICEBERG*",'SEMANA JANEIRO'!$C:$C,600)+SUMIFS('SEMANA FEVEREIRO'!$I:$I,'SEMANA FEVEREIRO'!$B:$B,"*ICEBERG*",'SEMANA FEVEREIRO'!$C:$C,600)+SUMIFS('SEMANA MARÇO'!$I:$I,'SEMANA MARÇO'!$B:$B,"*ICEBERG*",'SEMANA MARÇO'!$C:$C,600)+SUMIFS('SEMANA ABRIL'!$I:$I,'SEMANA ABRIL'!$B:$B,"*ICEBERG*",'SEMANA ABRIL'!$C:$C,600)+SUMIFS('SEMANA MAIO'!$I:$I,'SEMANA MAIO'!$B:$B,"*ICEBERG*",'SEMANA MAIO'!$C:$C,600)+SUMIFS('SEMANA JUNHO'!$I:$I,'SEMANA JUNHO'!$B:$B,"*ICEBERG*",'SEMANA JUNHO'!$C:$C,600)+SUMIFS('SEMANA JULHO'!$I:$I,'SEMANA JULHO'!$B:$B,"*ICEBERG*",'SEMANA JULHO'!$C:$C,600)+SUMIFS('SEMANA AGOSTO'!$I:$I,'SEMANA AGOSTO'!$B:$B,"*ICEBERG*",'SEMANA AGOSTO'!$C:$C,600)+SUMIFS('SEMANA SETEMBRO'!$I:$I,'SEMANA SETEMBRO'!$B:$B,"*ICEBERG*",'SEMANA SETEMBRO'!$C:$C,600)+SUMIFS('SEMANA OUTUBRO'!$I:$I,'SEMANA OUTUBRO'!$B:$B,"*ICEBERG*",'SEMANA OUTUBRO'!$C:$C,600)+SUMIFS('SEMANA NOVEMBRO'!$I:$I,'SEMANA NOVEMBRO'!$B:$B,"*ICEBERG*",'SEMANA NOVEMBRO'!$C:$C,600)+SUMIFS('SEMANA DEZEMBRO'!$I:$I,'SEMANA DEZEMBRO'!$B:$B,"*ICEBERG*",'SEMANA DEZEMBRO'!$C:$C,600) -> 0 | F32: =SUMIF('SEMANA JANEIRO'!$B:$B,"*ICEBERG*",'SEMANA JANEIRO'!$I:$I)+SUMIF('SEMANA FEVEREIRO'!$B:$B,"*ICEBERG*",'SEMANA FEVEREIRO'!$I:$I)+SUMIF('SEMANA MARÇO'!$B:$B,"*ICEBERG*",'SEMANA MARÇO'!$I:$I)+SUMIF('SEMANA ABRIL'!$B:$B,"*ICEBERG*",'SEMANA ABRIL'!$I:$I)+SUMIF('SEMANA MAIO'!$B:$B,"*ICEBERG*",'SEMANA MAIO'!$I:$I)+SUMIF('SEMANA JUNHO'!$B:$B,"*ICEBERG*",'SEMANA JUNHO'!$I:$I)+SUMIF('SEMANA JULHO'!$B:$B,"*ICEBERG*",'SEMANA JULHO'!$I:$I)+SUMIF('SEMANA AGOSTO'!$B:$B,"*ICEBERG*",'SEMANA AGOSTO'!$I:$I)+SUMIF('SEMANA SETEMBRO'!$B:$B,"*ICEBERG*",'SEMANA SETEMBRO'!$I:$I)+SUMIF('SEMANA OUTUBRO'!$B:$B,"*ICEBERG*",'SEMANA OUTUBRO'!$I:$I)+SUMIF('SEMANA NOVEMBRO'!$B:$B,"*ICEBERG*",'SEMANA NOVEMBRO'!$I:$I)+SUMIF('SEMANA DEZEMBRO'!$B:$B,"*ICEBERG*",'SEMANA DEZEMBRO'!$I:$I)-C32-D32-E32 -> 2115 | G32: =C32+D32+E32+F32 -> 110523
A33: 4º | B33: ADIMIX | C33: =SUMIFS('SEMANA JANEIRO'!$I:$I,'SEMANA JANEIRO'!$B:$B,"*ADIMIX*",'SEMANA JANEIRO'!$C:$C,180)+SUMIFS('SEMANA FEVEREIRO'!$I:$I,'SEMANA FEVEREIRO'!$B:$B,"*ADIMIX*",'SEMANA FEVEREIRO'!$C:$C,180)+SUMIFS('SEMANA MARÇO'!$I:$I,'SEMANA MARÇO'!$B:$B,"*ADIMIX*",'SEMANA MARÇO'!$C:$C,180)+SUMIFS('SEMANA ABRIL'!$I:$I,'SEMANA ABRIL'!$B:$B,"*ADIMIX*",'SEMANA ABRIL'!$C:$C,180)+SUMIFS('SEMANA MAIO'!$I:$I,'SEMANA MAIO'!$B:$B,"*ADIMIX*",'SEMANA MAIO'!$C:$C,180)+SUMIFS('SEMANA JUNHO'!$I:$I,'SEMANA JUNHO'!$B:$B,"*ADIMIX*",'SEMANA JUNHO'!$C:$C,180)+SUMIFS('SEMANA JULHO'!$I:$I,'SEMANA JULHO'!$B:$B,"*ADIMIX*",'SEMANA JULHO'!$C:$C,180)+SUMIFS('SEMANA AGOSTO'!$I:$I,'SEMANA AGOSTO'!$B:$B,"*ADIMIX*",'SEMANA AGOSTO'!$C:$C,180)+SUMIFS('SEMANA SETEMBRO'!$I:$I,'SEMANA SETEMBRO'!$B:$B,"*ADIMIX*",'SEMANA SETEMBRO'!$C:$C,180)+SUMIFS('SEMANA OUTUBRO'!$I:$I,'SEMANA OUTUBRO'!$B:$B,"*ADIMIX*",'SEMANA OUTUBRO'!$C:$C,180)+SUMIFS('SEMANA NOVEMBRO'!$I:$I,'SEMANA NOVEMBRO'!$B:$B,"*ADIMIX*",'SEMANA NOVEMBRO'!$C:$C,180)+SUMIFS('SEMANA DEZEMBRO'!$I:$I,'SEMANA DEZEMBRO'!$B:$B,"*ADIMIX*",'SEMANA DEZEMBRO'!$C:$C,180) -> 0 | D33: =SUMIFS('SEMANA JANEIRO'!$I:$I,'SEMANA JANEIRO'!$B:$B,"*ADIMIX*",'SEMANA JANEIRO'!$C:$C,400)+SUMIFS('SEMANA FEVEREIRO'!$I:$I,'SEMANA FEVEREIRO'!$B:$B,"*ADIMIX*",'SEMANA FEVEREIRO'!$C:$C,400)+SUMIFS('SEMANA MARÇO'!$I:$I,'SEMANA MARÇO'!$B:$B,"*ADIMIX*",'SEMANA MARÇO'!$C:$C,400)+SUMIFS('SEMANA ABRIL'!$I:$I,'SEMANA ABRIL'!$B:$B,"*ADIMIX*",'SEMANA ABRIL'!$C:$C,400)+SUMIFS('SEMANA MAIO'!$I:$I,'SEMANA MAIO'!$B:$B,"*ADIMIX*",'SEMANA MAIO'!$C:$C,400)+SUMIFS('SEMANA JUNHO'!$I:$I,'SEMANA JUNHO'!$B:$B,"*ADIMIX*",'SEMANA JUNHO'!$C:$C,400)+SUMIFS('SEMANA JULHO'!$I:$I,'SEMANA JULHO'!$B:$B,"*ADIMIX*",'SEMANA JULHO'!$C:$C,400)+SUMIFS('SEMANA AGOSTO'!$I:$I,'SEMANA AGOSTO'!$B:$B,"*ADIMIX*",'SEMANA AGOSTO'!$C:$C,400)+SUMIFS('SEMANA SETEMBRO'!$I:$I,'SEMANA SETEMBRO'!$B:$B,"*ADIMIX*",'SEMANA SETEMBRO'!$C:$C,400)+SUMIFS('SEMANA OUTUBRO'!$I:$I,'SEMANA OUTUBRO'!$B:$B,"*ADIMIX*",'SEMANA OUTUBRO'!$C:$C,400)+SUMIFS('SEMANA NOVEMBRO'!$I:$I,'SEMANA NOVEMBRO'!$B:$B,"*ADIMIX*",'SEMANA NOVEMBRO'!$C:$C,400)+SUMIFS('SEMANA DEZEMBRO'!$I:$I,'SEMANA DEZEMBRO'!$B:$B,"*ADIMIX*",'SEMANA DEZEMBRO'!$C:$C,400) -> 0 | E33: =SUMIFS('SEMANA JANEIRO'!$I:$I,'SEMANA JANEIRO'!$B:$B,"*ADIMIX*",'SEMANA JANEIRO'!$C:$C,600)+SUMIFS('SEMANA FEVEREIRO'!$I:$I,'SEMANA FEVEREIRO'!$B:$B,"*ADIMIX*",'SEMANA FEVEREIRO'!$C:$C,600)+SUMIFS('SEMANA MARÇO'!$I:$I,'SEMANA MARÇO'!$B:$B,"*ADIMIX*",'SEMANA MARÇO'!$C:$C,600)+SUMIFS('SEMANA ABRIL'!$I:$I,'SEMANA ABRIL'!$B:$B,"*ADIMIX*",'SEMANA ABRIL'!$C:$C,600)+SUMIFS('SEMANA MAIO'!$I:$I,'SEMANA MAIO'!$B:$B,"*ADIMIX*",'SEMANA MAIO'!$C:$C,600)+SUMIFS('SEMANA JUNHO'!$I:$I,'SEMANA JUNHO'!$B:$B,"*ADIMIX*",'SEMANA JUNHO'!$C:$C,600)+SUMIFS('SEMANA JULHO'!$I:$I,'SEMANA JULHO'!$B:$B,"*ADIMIX*",'SEMANA JULHO'!$C:$C,600)+SUMIFS('SEMANA AGOSTO'!$I:$I,'SEMANA AGOSTO'!$B:$B,"*ADIMIX*",'SEMANA AGOSTO'!$C:$C,600)+SUMIFS('SEMANA SETEMBRO'!$I:$I,'SEMANA SETEMBRO'!$B:$B,"*ADIMIX*",'SEMANA SETEMBRO'!$C:$C,600)+SUMIFS('SEMANA OUTUBRO'!$I:$I,'SEMANA OUTUBRO'!$B:$B,"*ADIMIX*",'SEMANA OUTUBRO'!$C:$C,600)+SUMIFS('SEMANA NOVEMBRO'!$I:$I,'SEMANA NOVEMBRO'!$B:$B,"*ADIMIX*",'SEMANA NOVEMBRO'!$C:$C,600)+SUMIFS('SEMANA DEZEMBRO'!$I:$I,'SEMANA DEZEMBRO'!$B:$B,"*ADIMIX*",'SEMANA DEZEMBRO'!$C:$C,600) -> 88332 | F33: =SUMIF('SEMANA JANEIRO'!$B:$B,"*ADIMIX*",'SEMANA JANEIRO'!$I:$I)+SUMIF('SEMANA FEVEREIRO'!$B:$B,"*ADIMIX*",'SEMANA FEVEREIRO'!$I:$I)+SUMIF('SEMANA MARÇO'!$B:$B,"*ADIMIX*",'SEMANA MARÇO'!$I:$I)+SUMIF('SEMANA ABRIL'!$B:$B,"*ADIMIX*",'SEMANA ABRIL'!$I:$I)+SUMIF('SEMANA MAIO'!$B:$B,"*ADIMIX*",'SEMANA MAIO'!$I:$I)+SUMIF('SEMANA JUNHO'!$B:$B,"*ADIMIX*",'SEMANA JUNHO'!$I:$I)+SUMIF('SEMANA JULHO'!$B:$B,"*ADIMIX*",'SEMANA JULHO'!$I:$I)+SUMIF('SEMANA AGOSTO'!$B:$B,"*ADIMIX*",'SEMANA AGOSTO'!$I:$I)+SUMIF('SEMANA SETEMBRO'!$B:$B,"*ADIMIX*",'SEMANA SETEMBRO'!$I:$I)+SUMIF('SEMANA OUTUBRO'!$B:$B,"*ADIMIX*",'SEMANA OUTUBRO'!$I:$I)+SUMIF('SEMANA NOVEMBRO'!$B:$B,"*ADIMIX*",'SEMANA NOVEMBRO'!$I:$I)+SUMIF('SEMANA DEZEMBRO'!$B:$B,"*ADIMIX*",'SEMANA DEZEMBRO'!$I:$I)-C33-D33-E33 -> 0 | G33: =C33+D33+E33+F33 -> 88332
A34: 5º | B34: FESTPAN | C34: =SUMIFS('SEMANA JANEIRO'!$I:$I,'SEMANA JANEIRO'!$B:$B,"*FESTPAN*",'SEMANA JANEIRO'!$C:$C,180)+SUMIFS('SEMANA FEVEREIRO'!$I:$I,'SEMANA FEVEREIRO'!$B:$B,"*FESTPAN*",'SEMANA FEVEREIRO'!$C:$C,180)+SUMIFS('SEMANA MARÇO'!$I:$I,'SEMANA MARÇO'!$B:$B,"*FESTPAN*",'SEMANA MARÇO'!$C:$C,180)+SUMIFS('SEMANA ABRIL'!$I:$I,'SEMANA ABRIL'!$B:$B,"*FESTPAN*",'SEMANA ABRIL'!$C:$C,180)+SUMIFS('SEMANA MAIO'!$I:$I,'SEMANA MAIO'!$B:$B,"*FESTPAN*",'SEMANA MAIO'!$C:$C,180)+SUMIFS('SEMANA JUNHO'!$I:$I,'SEMANA JUNHO'!$B:$B,"*FESTPAN*",'SEMANA JUNHO'!$C:$C,180)+SUMIFS('SEMANA JULHO'!$I:$I,'SEMANA JULHO'!$B:$B,"*FESTPAN*",'SEMANA JULHO'!$C:$C,180)+SUMIFS('SEMANA AGOSTO'!$I:$I,'SEMANA AGOSTO'!$B:$B,"*FESTPAN*",'SEMANA AGOSTO'!$C:$C,180)+SUMIFS('SEMANA SETEMBRO'!$I:$I,'SEMANA SETEMBRO'!$B:$B,"*FESTPAN*",'SEMANA SETEMBRO'!$C:$C,180)+SUMIFS('SEMANA OUTUBRO'!$I:$I,'SEMANA OUTUBRO'!$B:$B,"*FESTPAN*",'SEMANA OUTUBRO'!$C:$C,180)+SUMIFS('SEMANA NOVEMBRO'!$I:$I,'SEMANA NOVEMBRO'!$B:$B,"*FESTPAN*",'SEMANA NOVEMBRO'!$C:$C,180)+SUMIFS('SEMANA DEZEMBRO'!$I:$I,'SEMANA DEZEMBRO'!$B:$B,"*FESTPAN*",'SEMANA DEZEMBRO'!$C:$C,180) -> 0 | D34: =SUMIFS('SEMANA JANEIRO'!$I:$I,'SEMANA JANEIRO'!$B:$B,"*FESTPAN*",'SEMANA JANEIRO'!$C:$C,400)+SUMIFS('SEMANA FEVEREIRO'!$I:$I,'SEMANA FEVEREIRO'!$B:$B,"*FESTPAN*",'SEMANA FEVEREIRO'!$C:$C,400)+SUMIFS('SEMANA MARÇO'!$I:$I,'SEMANA MARÇO'!$B:$B,"*FESTPAN*",'SEMANA MARÇO'!$C:$C,400)+SUMIFS('SEMANA ABRIL'!$I:$I,'SEMANA ABRIL'!$B:$B,"*FESTPAN*",'SEMANA ABRIL'!$C:$C,400)+SUMIFS('SEMANA MAIO'!$I:$I,'SEMANA MAIO'!$B:$B,"*FESTPAN*",'SEMANA MAIO'!$C:$C,400)+SUMIFS('SEMANA JUNHO'!$I:$I,'SEMANA JUNHO'!$B:$B,"*FESTPAN*",'SEMANA JUNHO'!$C:$C,400)+SUMIFS('SEMANA JULHO'!$I:$I,'SEMANA JULHO'!$B:$B,"*FESTPAN*",'SEMANA JULHO'!$C:$C,400)+SUMIFS('SEMANA AGOSTO'!$I:$I,'SEMANA AGOSTO'!$B:$B,"*FESTPAN*",'SEMANA AGOSTO'!$C:$C,400)+SUMIFS('SEMANA SETEMBRO'!$I:$I,'SEMANA SETEMBRO'!$B:$B,"*FESTPAN*",'SEMANA SETEMBRO'!$C:$C,400)+SUMIFS('SEMANA OUTUBRO'!$I:$I,'SEMANA OUTUBRO'!$B:$B,"*FESTPAN*",'SEMANA OUTUBRO'!$C:$C,400)+SUMIFS('SEMANA NOVEMBRO'!$I:$I,'SEMANA NOVEMBRO'!$B:$B,"*FESTPAN*",'SEMANA NOVEMBRO'!$C:$C,400)+SUMIFS('SEMANA DEZEMBRO'!$I:$I,'SEMANA DEZEMBRO'!$B:$B,"*FESTPAN*",'SEMANA DEZEMBRO'!$C:$C,400) -> 43632 | E34: =SUMIFS('SEMANA JANEIRO'!$I:$I,'SEMANA JANEIRO'!$B:$B,"*FESTPAN*",'SEMANA JANEIRO'!$C:$C,600)+SUMIFS('SEMANA FEVEREIRO'!$I:$I,'SEMANA FEVEREIRO'!$B:$B,"*FESTPAN*",'SEMANA FEVEREIRO'!$C:$C,600)+SUMIFS('SEMANA MARÇO'!$I:$I,'SEMANA MARÇO'!$B:$B,"*FESTPAN*",'SEMANA MARÇO'!$C:$C,600)+SUMIFS('SEMANA ABRIL'!$I:$I,'SEMANA ABRIL'!$B:$B,"*FESTPAN*",'SEMANA ABRIL'!$C:$C,600)+SUMIFS('SEMANA MAIO'!$I:$I,'SEMANA MAIO'!$B:$B,"*FESTPAN*",'SEMANA MAIO'!$C:$C,600)+SUMIFS('SEMANA JUNHO'!$I:$I,'SEMANA JUNHO'!$B:$B,"*FESTPAN*",'SEMANA JUNHO'!$C:$C,600)+SUMIFS('SEMANA JULHO'!$I:$I,'SEMANA JULHO'!$B:$B,"*FESTPAN*",'SEMANA JULHO'!$C:$C,600)+SUMIFS('SEMANA AGOSTO'!$I:$I,'SEMANA AGOSTO'!$B:$B,"*FESTPAN*",'SEMANA AGOSTO'!$C:$C,600)+SUMIFS('SEMANA SETEMBRO'!$I:$I,'SEMANA SETEMBRO'!$B:$B,"*FESTPAN*",'SEMANA SETEMBRO'!$C:$C,600)+SUMIFS('SEMANA OUTUBRO'!$I:$I,'SEMANA OUTUBRO'!$B:$B,"*FESTPAN*",'SEMANA OUTUBRO'!$C:$C,600)+SUMIFS('SEMANA NOVEMBRO'!$I:$I,'SEMANA NOVEMBRO'!$B:$B,"*FESTPAN*",'SEMANA NOVEMBRO'!$C:$C,600)+SUMIFS('SEMANA DEZEMBRO'!$I:$I,'SEMANA DEZEMBRO'!$B:$B,"*FESTPAN*",'SEMANA DEZEMBRO'!$C:$C,600) -> 0 | F34: =SUMIF('SEMANA JANEIRO'!$B:$B,"*FESTPAN*",'SEMANA JANEIRO'!$I:$I)+SUMIF('SEMANA FEVEREIRO'!$B:$B,"*FESTPAN*",'SEMANA FEVEREIRO'!$I:$I)+SUMIF('SEMANA MARÇO'!$B:$B,"*FESTPAN*",'SEMANA MARÇO'!$I:$I)+SUMIF('SEMANA ABRIL'!$B:$B,"*FESTPAN*",'SEMANA ABRIL'!$I:$I)+SUMIF('SEMANA MAIO'!$B:$B,"*FESTPAN*",'SEMANA MAIO'!$I:$I)+SUMIF('SEMANA JUNHO'!$B:$B,"*FESTPAN*",'SEMANA JUNHO'!$I:$I)+SUMIF('SEMANA JULHO'!$B:$B,"*FESTPAN*",'SEMANA JULHO'!$I:$I)+SUMIF('SEMANA AGOSTO'!$B:$B,"*FESTPAN*",'SEMANA AGOSTO'!$I:$I)+SUMIF('SEMANA SETEMBRO'!$B:$B,"*FESTPAN*",'SEMANA SETEMBRO'!$I:$I)+SUMIF('SEMANA OUTUBRO'!$B:$B,"*FESTPAN*",'SEMANA OUTUBRO'!$I:$I)+SUMIF('SEMANA NOVEMBRO'!$B:$B,"*FESTPAN*",'SEMANA NOVEMBRO'!$I:$I)+SUMIF('SEMANA DEZEMBRO'!$B:$B,"*FESTPAN*",'SEMANA DEZEMBRO'!$I:$I)-C34-D34-E34 -> 0 | G34: =C34+D34+E34+F34 -> 43632
A35: 6º | B35: QUALICOCO | C35: =SUMIFS('SEMANA JANEIRO'!$I:$I,'SEMANA JANEIRO'!$B:$B,"*QUALICOCO*",'SEMANA JANEIRO'!$C:$C,180)+SUMIFS('SEMANA FEVEREIRO'!$I:$I,'SEMANA FEVEREIRO'!$B:$B,"*QUALICOCO*",'SEMANA FEVEREIRO'!$C:$C,180)+SUMIFS('SEMANA MARÇO'!$I:$I,'SEMANA MARÇO'!$B:$B,"*QUALICOCO*",'SEMANA MARÇO'!$C:$C,180)+SUMIFS('SEMANA ABRIL'!$I:$I,'SEMANA ABRIL'!$B:$B,"*QUALICOCO*",'SEMANA ABRIL'!$C:$C,180)+SUMIFS('SEMANA MAIO'!$I:$I,'SEMANA MAIO'!$B:$B,"*QUALICOCO*",'SEMANA MAIO'!$C:$C,180)+SUMIFS('SEMANA JUNHO'!$I:$I,'SEMANA JUNHO'!$B:$B,"*QUALICOCO*",'SEMANA JUNHO'!$C:$C,180)+SUMIFS('SEMANA JULHO'!$I:$I,'SEMANA JULHO'!$B:$B,"*QUALICOCO*",'SEMANA JULHO'!$C:$C,180)+SUMIFS('SEMANA AGOSTO'!$I:$I,'SEMANA AGOSTO'!$B:$B,"*QUALICOCO*",'SEMANA AGOSTO'!$C:$C,180)+SUMIFS('SEMANA SETEMBRO'!$I:$I,'SEMANA SETEMBRO'!$B:$B,"*QUALICOCO*",'SEMANA SETEMBRO'!$C:$C,180)+SUMIFS('SEMANA OUTUBRO'!$I:$I,'SEMANA OUTUBRO'!$B:$B,"*QUALICOCO*",'SEMANA OUTUBRO'!$C:$C,180)+SUMIFS('SEMANA NOVEMBRO'!$I:$I,'SEMANA NOVEMBRO'!$B:$B,"*QUALICOCO*",'SEMANA NOVEMBRO'!$C:$C,180)+SUMIFS('SEMANA DEZEMBRO'!$I:$I,'SEMANA DEZEMBRO'!$B:$B,"*QUALICOCO*",'SEMANA DEZEMBRO'!$C:$C,180) -> 0 | D35: =SUMIFS('SEMANA JANEIRO'!$I:$I,'SEMANA JANEIRO'!$B:$B,"*QUALICOCO*",'SEMANA JANEIRO'!$C:$C,400)+SUMIFS('SEMANA FEVEREIRO'!$I:$I,'SEMANA FEVEREIRO'!$B:$B,"*QUALICOCO*",'SEMANA FEVEREIRO'!$C:$C,400)+SUMIFS('SEMANA MARÇO'!$I:$I,'SEMANA MARÇO'!$B:$B,"*QUALICOCO*",'SEMANA MARÇO'!$C:$C,400)+SUMIFS('SEMANA ABRIL'!$I:$I,'SEMANA ABRIL'!$B:$B,"*QUALICOCO*",'SEMANA ABRIL'!$C:$C,400)+SUMIFS('SEMANA MAIO'!$I:$I,'SEMANA MAIO'!$B:$B,"*QUALICOCO*",'SEMANA MAIO'!$C:$C,400)+SUMIFS('SEMANA JUNHO'!$I:$I,'SEMANA JUNHO'!$B:$B,"*QUALICOCO*",'SEMANA JUNHO'!$C:$C,400)+SUMIFS('SEMANA JULHO'!$I:$I,'SEMANA JULHO'!$B:$B,"*QUALICOCO*",'SEMANA JULHO'!$C:$C,400)+SUMIFS('SEMANA AGOSTO'!$I:$I,'SEMANA AGOSTO'!$B:$B,"*QUALICOCO*",'SEMANA AGOSTO'!$C:$C,400)+SUMIFS('SEMANA SETEMBRO'!$I:$I,'SEMANA SETEMBRO'!$B:$B,"*QUALICOCO*",'SEMANA SETEMBRO'!$C:$C,400)+SUMIFS('SEMANA OUTUBRO'!$I:$I,'SEMANA OUTUBRO'!$B:$B,"*QUALICOCO*",'SEMANA OUTUBRO'!$C:$C,400)+SUMIFS('SEMANA NOVEMBRO'!$I:$I,'SEMANA NOVEMBRO'!$B:$B,"*QUALICOCO*",'SEMANA NOVEMBRO'!$C:$C,400)+SUMIFS('SEMANA DEZEMBRO'!$I:$I,'SEMANA DEZEMBRO'!$B:$B,"*QUALICOCO*",'SEMANA DEZEMBRO'!$C:$C,400) -> 0 | E35: =SUMIFS('SEMANA JANEIRO'!$I:$I,'SEMANA JANEIRO'!$B:$B,"*QUALICOCO*",'SEMANA JANEIRO'!$C:$C,600)+SUMIFS('SEMANA FEVEREIRO'!$I:$I,'SEMANA FEVEREIRO'!$B:$B,"*QUALICOCO*",'SEMANA FEVEREIRO'!$C:$C,600)+SUMIFS('SEMANA MARÇO'!$I:$I,'SEMANA MARÇO'!$B:$B,"*QUALICOCO*",'SEMANA MARÇO'!$C:$C,600)+SUMIFS('SEMANA ABRIL'!$I:$I,'SEMANA ABRIL'!$B:$B,"*QUALICOCO*",'SEMANA ABRIL'!$C:$C,600)+SUMIFS('SEMANA MAIO'!$I:$I,'SEMANA MAIO'!$B:$B,"*QUALICOCO*",'SEMANA MAIO'!$C:$C,600)+SUMIFS('SEMANA JUNHO'!$I:$I,'SEMANA JUNHO'!$B:$B,"*QUALICOCO*",'SEMANA JUNHO'!$C:$C,600)+SUMIFS('SEMANA JULHO'!$I:$I,'SEMANA JULHO'!$B:$B,"*QUALICOCO*",'SEMANA JULHO'!$C:$C,600)+SUMIFS('SEMANA AGOSTO'!$I:$I,'SEMANA AGOSTO'!$B:$B,"*QUALICOCO*",'SEMANA AGOSTO'!$C:$C,600)+SUMIFS('SEMANA SETEMBRO'!$I:$I,'SEMANA SETEMBRO'!$B:$B,"*QUALICOCO*",'SEMANA SETEMBRO'!$C:$C,600)+SUMIFS('SEMANA OUTUBRO'!$I:$I,'SEMANA OUTUBRO'!$B:$B,"*QUALICOCO*",'SEMANA OUTUBRO'!$C:$C,600)+SUMIFS('SEMANA NOVEMBRO'!$I:$I,'SEMANA NOVEMBRO'!$B:$B,"*QUALICOCO*",'SEMANA NOVEMBRO'!$C:$C,600)+SUMIFS('SEMANA DEZEMBRO'!$I:$I,'SEMANA DEZEMBRO'!$B:$B,"*QUALICOCO*",'SEMANA DEZEMBRO'!$C:$C,600) -> 0 | F35: =SUMIF('SEMANA JANEIRO'!$B:$B,"*QUALICOCO*",'SEMANA JANEIRO'!$I:$I)+SUMIF('SEMANA FEVEREIRO'!$B:$B,"*QUALICOCO*",'SEMANA FEVEREIRO'!$I:$I)+SUMIF('SEMANA MARÇO'!$B:$B,"*QUALICOCO*",'SEMANA MARÇO'!$I:$I)+SUMIF('SEMANA ABRIL'!$B:$B,"*QUALICOCO*",'SEMANA ABRIL'!$I:$I)+SUMIF('SEMANA MAIO'!$B:$B,"*QUALICOCO*",'SEMANA MAIO'!$I:$I)+SUMIF('SEMANA JUNHO'!$B:$B,"*QUALICOCO*",'SEMANA JUNHO'!$I:$I)+SUMIF('SEMANA JULHO'!$B:$B,"*QUALICOCO*",'SEMANA JULHO'!$I:$I)+SUMIF('SEMANA AGOSTO'!$B:$B,"*QUALICOCO*",'SEMANA AGOSTO'!$I:$I)+SUMIF('SEMANA SETEMBRO'!$B:$B,"*QUALICOCO*",'SEMANA SETEMBRO'!$I:$I)+SUMIF('SEMANA OUTUBRO'!$B:$B,"*QUALICOCO*",'SEMANA OUTUBRO'!$I:$I)+SUMIF('SEMANA NOVEMBRO'!$B:$B,"*QUALICOCO*",'SEMANA NOVEMBRO'!$I:$I)+SUMIF('SEMANA DEZEMBRO'!$B:$B,"*QUALICOCO*",'SEMANA DEZEMBRO'!$I:$I)-C35-D35-E35 -> 34008 | G35: =C35+D35+E35+F35 -> 34008
A36: 7º | B36: DONA JURA | C36: =SUMIFS('SEMANA JANEIRO'!$I:$I,'SEMANA JANEIRO'!$B:$B,"*DONA JURA*",'SEMANA JANEIRO'!$C:$C,180)+SUMIFS('SEMANA FEVEREIRO'!$I:$I,'SEMANA FEVEREIRO'!$B:$B,"*DONA JURA*",'SEMANA FEVEREIRO'!$C:$C,180)+SUMIFS('SEMANA MARÇO'!$I:$I,'SEMANA MARÇO'!$B:$B,"*DONA JURA*",'SEMANA MARÇO'!$C:$C,180)+SUMIFS('SEMANA ABRIL'!$I:$I,'SEMANA ABRIL'!$B:$B,"*DONA JURA*",'SEMANA ABRIL'!$C:$C,180)+SUMIFS('SEMANA MAIO'!$I:$I,'SEMANA MAIO'!$B:$B,"*DONA JURA*",'SEMANA MAIO'!$C:$C,180)+SUMIFS('SEMANA JUNHO'!$I:$I,'SEMANA JUNHO'!$B:$B,"*DONA JURA*",'SEMANA JUNHO'!$C:$C,180)+SUMIFS('SEMANA JULHO'!$I:$I,'SEMANA JULHO'!$B:$B,"*DONA JURA*",'SEMANA JULHO'!$C:$C,180)+SUMIFS('SEMANA AGOSTO'!$I:$I,'SEMANA AGOSTO'!$B:$B,"*DONA JURA*",'SEMANA AGOSTO'!$C:$C,180)+SUMIFS('SEMANA SETEMBRO'!$I:$I,'SEMANA SETEMBRO'!$B:$B,"*DONA JURA*",'SEMANA SETEMBRO'!$C:$C,180)+SUMIFS('SEMANA OUTUBRO'!$I:$I,'SEMANA OUTUBRO'!$B:$B,"*DONA JURA*",'SEMANA OUTUBRO'!$C:$C,180)+SUMIFS('SEMANA NOVEMBRO'!$I:$I,'SEMANA NOVEMBRO'!$B:$B,"*DONA JURA*",'SEMANA NOVEMBRO'!$C:$C,180)+SUMIFS('SEMANA DEZEMBRO'!$I:$I,'SEMANA DEZEMBRO'!$B:$B,"*DONA JURA*",'SEMANA DEZEMBRO'!$C:$C,180) -> 0 | D36: =SUMIFS('SEMANA JANEIRO'!$I:$I,'SEMANA JANEIRO'!$B:$B,"*DONA JURA*",'SEMANA JANEIRO'!$C:$C,400)+SUMIFS('SEMANA FEVEREIRO'!$I:$I,'SEMANA FEVEREIRO'!$B:$B,"*DONA JURA*",'SEMANA FEVEREIRO'!$C:$C,400)+SUMIFS('SEMANA MARÇO'!$I:$I,'SEMANA MARÇO'!$B:$B,"*DONA JURA*",'SEMANA MARÇO'!$C:$C,400)+SUMIFS('SEMANA ABRIL'!$I:$I,'SEMANA ABRIL'!$B:$B,"*DONA JURA*",'SEMANA ABRIL'!$C:$C,400)+SUMIFS('SEMANA MAIO'!$I:$I,'SEMANA MAIO'!$B:$B,"*DONA JURA*",'SEMANA MAIO'!$C:$C,400)+SUMIFS('SEMANA JUNHO'!$I:$I,'SEMANA JUNHO'!$B:$B,"*DONA JURA*",'SEMANA JUNHO'!$C:$C,400)+SUMIFS('SEMANA JULHO'!$I:$I,'SEMANA JULHO'!$B:$B,"*DONA JURA*",'SEMANA JULHO'!$C:$C,400)+SUMIFS('SEMANA AGOSTO'!$I:$I,'SEMANA AGOSTO'!$B:$B,"*DONA JURA*",'SEMANA AGOSTO'!$C:$C,400)+SUMIFS('SEMANA SETEMBRO'!$I:$I,'SEMANA SETEMBRO'!$B:$B,"*DONA JURA*",'SEMANA SETEMBRO'!$C:$C,400)+SUMIFS('SEMANA OUTUBRO'!$I:$I,'SEMANA OUTUBRO'!$B:$B,"*DONA JURA*",'SEMANA OUTUBRO'!$C:$C,400)+SUMIFS('SEMANA NOVEMBRO'!$I:$I,'SEMANA NOVEMBRO'!$B:$B,"*DONA JURA*",'SEMANA NOVEMBRO'!$C:$C,400)+SUMIFS('SEMANA DEZEMBRO'!$I:$I,'SEMANA DEZEMBRO'!$B:$B,"*DONA JURA*",'SEMANA DEZEMBRO'!$C:$C,400) -> 24888 | E36: =SUMIFS('SEMANA JANEIRO'!$I:$I,'SEMANA JANEIRO'!$B:$B,"*DONA JURA*",'SEMANA JANEIRO'!$C:$C,600)+SUMIFS('SEMANA FEVEREIRO'!$I:$I,'SEMANA FEVEREIRO'!$B:$B,"*DONA JURA*",'SEMANA FEVEREIRO'!$C:$C,600)+SUMIFS('SEMANA MARÇO'!$I:$I,'SEMANA MARÇO'!$B:$B,"*DONA JURA*",'SEMANA MARÇO'!$C:$C,600)+SUMIFS('SEMANA ABRIL'!$I:$I,'SEMANA ABRIL'!$B:$B,"*DONA JURA*",'SEMANA ABRIL'!$C:$C,600)+SUMIFS('SEMANA MAIO'!$I:$I,'SEMANA MAIO'!$B:$B,"*DONA JURA*",'SEMANA MAIO'!$C:$C,600)+SUMIFS('SEMANA JUNHO'!$I:$I,'SEMANA JUNHO'!$B:$B,"*DONA JURA*",'SEMANA JUNHO'!$C:$C,600)+SUMIFS('SEMANA JULHO'!$I:$I,'SEMANA JULHO'!$B:$B,"*DONA JURA*",'SEMANA JULHO'!$C:$C,600)+SUMIFS('SEMANA AGOSTO'!$I:$I,'SEMANA AGOSTO'!$B:$B,"*DONA JURA*",'SEMANA AGOSTO'!$C:$C,600)+SUMIFS('SEMANA SETEMBRO'!$I:$I,'SEMANA SETEMBRO'!$B:$B,"*DONA JURA*",'SEMANA SETEMBRO'!$C:$C,600)+SUMIFS('SEMANA OUTUBRO'!$I:$I,'SEMANA OUTUBRO'!$B:$B,"*DONA JURA*",'SEMANA OUTUBRO'!$C:$C,600)+SUMIFS('SEMANA NOVEMBRO'!$I:$I,'SEMANA NOVEMBRO'!$B:$B,"*DONA JURA*",'SEMANA NOVEMBRO'!$C:$C,600)+SUMIFS('SEMANA DEZEMBRO'!$I:$I,'SEMANA DEZEMBRO'!$B:$B,"*DONA JURA*",'SEMANA DEZEMBRO'!$C:$C,600) -> 0 | F36: =SUMIF('SEMANA JANEIRO'!$B:$B,"*DONA JURA*",'SEMANA JANEIRO'!$I:$I)+SUMIF('SEMANA FEVEREIRO'!$B:$B,"*DONA JURA*",'SEMANA FEVEREIRO'!$I:$I)+SUMIF('SEMANA MARÇO'!$B:$B,"*DONA JURA*",'SEMANA MARÇO'!$I:$I)+SUMIF('SEMANA ABRIL'!$B:$B,"*DONA JURA*",'SEMANA ABRIL'!$I:$I)+SUMIF('SEMANA MAIO'!$B:$B,"*DONA JURA*",'SEMANA MAIO'!$I:$I)+SUMIF('SEMANA JUNHO'!$B:$B,"*DONA JURA*",'SEMANA JUNHO'!$I:$I)+SUMIF('SEMANA JULHO'!$B:$B,"*DONA JURA*",'SEMANA JULHO'!$I:$I)+SUMIF('SEMANA AGOSTO'!$B:$B,"*DONA JURA*",'SEMANA AGOSTO'!$I:$I)+SUMIF('SEMANA SETEMBRO'!$B:$B,"*DONA JURA*",'SEMANA SETEMBRO'!$I:$I)+SUMIF('SEMANA OUTUBRO'!$B:$B,"*DONA JURA*",'SEMANA OUTUBRO'!$I:$I)+SUMIF('SEMANA NOVEMBRO'!$B:$B,"*DONA JURA*",'SEMANA NOVEMBRO'!$I:$I)+SUMIF('SEMANA DEZEMBRO'!$B:$B,"*DONA JURA*",'SEMANA DEZEMBRO'!$I:$I)-C36-D36-E36 -> 0 | G36: =C36+D36+E36+F36 -> 24888
