Workbook
Name EMB_600: CONFIG_LISTAS!$D$2
Name EMB_COCO: CONFIG_LISTAS!$C$2:$C$3
Name EMB_CORANTE: CONFIG_LISTAS!$B$2
Name EMB_TODAS: CONFIG_LISTAS!$A$2:$A$9

Sheet GOOGLE_SHEETS_FINAL
A1: VERSÃO FINAL • GOOGLE SHEETS
A3: # | B3: Item | C3: Orientação | D3: Onde mexer | E3: Observação
A4: 1 | B4: Status da versão | C4: Preparada para abrir no Google Sheets | D4: Google Sheets / Apps Script | E4: Arquivo limpo e com aba de automações em Apps Script.
A5: 2 | B5: Como usar | C5: 1) Subir no Google Drive → Abrir com Google Planilhas | D5: Google Sheets / Apps Script | E5: Depois salve como Google Sheets para liberar edição online.
A6: 3 | B6: Automação principal | C6: Copiar o código da aba APPS_SCRIPT para Extensões → Apps Script | D6: Google Sheets / Apps Script | E6: No Sheets, cole o código, salve e recarregue a planilha.
A7: 4 | B7: Menu criado | C7: Produção 2026 | D7: Google Sheets / Apps Script | E7: Depois de colar o script, aparece menu para Atualizar resumo, Formatar datas e Reaplicar validações.
A8: 5 | B8: Datas | C8: Padrão brasileiro | D8: Google Sheets / Apps Script | E8: dd/mm/aaaa nas abas principais.
A9: 6 | B9: Preenchimento | C9: Abas SEMANA | D9: Google Sheets / Apps Script | E9: Preencha Produto, Embalagem e Caixas. Pallets, Real CX e Total de latas ficam automáticos.
A10: 7 | B10: Dashboard | C10: Automático | D10: Google Sheets / Apps Script | E10: Dashboard, Resumo Mensal e Gráficos puxam dados das abas semanais e de gás.
A11: 8 | B11: Cores do resultado | C11: Verde / Vermelho / Cinza | D11: Google Sheets / Apps Script | E11: Verde acima da meta, vermelho abaixo, cinza zerado/sem dado.
A12: 9 | B12: Observação importante | C12: Macros VBA não funcionam no Google Sheets | D12: Google Sheets / Apps Script | E12: Por isso deixei a automação em Apps Script na aba APPS_SCRIPT.

Sheet APPS_SCRIPT
A1: CÓDIGO PARA COLAR NO GOOGLE SHEETS → Extensões > Apps Script
A3: /** * AUTOMAÇÕES GOOGLE SHEETS • PROGRAMAÇÃO DE PRODUÇÃO 2026 * Como usar: Extensões > Apps Script > cole este código > Salvar > recarregar a planilha. */ const MESES = ['JANEIRO','FEVEREIRO','MARÇO','ABRIL','MAIO','JUNHO','JULHO','AGOSTO','SETEMBRO','OUTUBRO','NOVEMBRO','DEZEMBRO']; function onOpen() { SpreadsheetApp.getUi() .createMenu('Produção 2026') .addItem('Atualizar resumo e dashboard', 'atualizarTudo') .addItem('Formatar datas em PT-BR', 'formatarDatasBR') .addItem('Reaplicar validações', 'aplicarValidacoes') .addItem('Organizar visual das abas semanais', 'organizarAbasSemana') .addToUi(); } function onEdit(e) { if (!e || !e.range) return; const sh = e.range.getSheet(); const nome = sh.getName(); if (!nome.startsWith('SEMANA ')) return; const row = e.range.getRow(); const col = e.range.getColumn(); if (row < 4) return; // Ao editar Produto, Embalagem ou Caixas, reaplica fórmulas da linha. if ([2,3,4,8].includes(col)) { aplicarFormulasLinhaSemana_(sh, row); } } function aplicarFormulasLinhaSemana_(sh, row) { const produto = sh.getRange(row, 2).getValue(); if (!produto && !sh.getRange(row, 4).getValue()) return; sh.getRange(row, 5).setValue('CX'); sh.getRange(row, 6).setFormula(`=IF($B${row}="","",IF(SUMIFS(CONFIG_PALLETS!$C:$C,CONFIG_PALLETS!$A:$A,TRIM($B${row}),CONFIG_PALLETS!$B:$B,$C${row}&" ml")>0,SUMIFS(CONFIG_PALLETS!$C:$C,CONFIG_PALLETS!$A:$A,TRIM($B${row}),CONFIG_PALLETS!$B:$B,$C${row}&" ml"),IF(SUMIFS(CONFIG_PALLETS!$C:$C,CONFIG_PALLETS!$A:$A,"GERAL",CONFIG_PALLETS!$B:$B,$C${row}&" ml")>0,SUMIFS(CONFIG_PALLETS!$C:$C,CONFIG_PALLETS!$A:$A,"GERAL",CONFIG_PALLETS!$B:$B,$C${row}&" ml"),"")))`); sh.getRange(row, 7).setFormula(`=IFERROR(ROUNDUP(D${row}/F${row},0),"")`); sh.getRange(row, 9).setFormula(`=IF(H${row}="","",H${row}*IF(SUMIFS(CONFIG_PALLETS!$D:$D,CONFIG_PALLETS!$A:$A,IF(ISNUMBER(SEARCH("ESPUMA",$B${row})),"ESPUMA",IF(OR(ISNUMBER(SEARCH("OLEO DE COCO",$B${row})),ISNUMBER(SEARCH("ÓLEO DE COCO",$B${row})),ISNUMBER(SEARCH("COPRA",$B${row}))),"ÓLEO DE COCO",IF(ISNUMBER(SEARCH("CORANTE",$B${row})),"CORANTE",TRIM($B${row})))),CONFIG_PALLETS!$B:$B,$C${row}&" ml")>0,SUMIFS(CONFIG_PALLETS!$D:$D,CONFIG_PALLETS!$A:$A,IF(ISNUMBER(SEARCH("ESPUMA",$B${row})),"ESPUMA",IF(OR(ISNUMBER(SEARCH("OLEO DE COCO",$B${row})),ISNUMBER(SEARCH("ÓLEO DE COCO",$B${row})),ISNUMBER(SEARCH("COPRA",$B${row}))),"ÓLEO DE COCO",IF(ISNUMBER(SEARCH("CORANTE",$B${row})),"CORANTE",TRIM($B${row})))),CONFIG_PALLETS!$B:$B,$C${row}&" ml"),IF(SUMIFS(CONFIG_PALLETS!$D:$D,CONFIG_PALLETS!$A:$A,"GERAL",CONFIG_PALLETS!$B:$B,$C${row}&" ml")>0,SUMIFS(CONFIG_PALLETS!$D:$D,CONFIG_PALLETS!$A:$A,"GERAL",CONFIG_PALLETS!$B:$B,$C${row}&" ml"),12)))`); } function atualizarTudo() { formatarDatasBR(); aplicarValidacoes(); organizarAbasSemana(); SpreadsheetApp.flush(); } function formatarDatasBR() { const ss = SpreadsheetApp.getActive(); ss.getSheets().forEach(sh => { const name = sh.getName(); if (name.includes('JANEIRO') || name.includes('FEVEREIRO') || name.includes('MARÇO') || name.includes('ABRIL') || name.includes('MAIO') || name.includes('JUNHO') || name.includes('JULHO') || name.includes('AGOSTO') || name.includes('SETEMBRO') || name.includes('OUTUBRO') || name.includes('NOVEMBRO') || name.includes('DEZEMBRO') || name === 'GÁS' || name === 'BASE_DADOS') { sh.getRange('A:A').setNumberFormat('dd/mm/yyyy'); } }); } function aplicarValidacoes() { const ss = SpreadsheetApp.getActive(); const cfg = ss.getSheetByName('CONFIG_LISTAS'); if (!cfg) return; const produtoRule = SpreadsheetApp.newDataValidation().requireValueInRange(cfg.getRange('F2:F'), true).setAllowInvalid(true).build(); const embRule = SpreadsheetApp.newDataValidation().requireValueInRange(cfg.getRange('A2:A'), true).setAllowInvalid(true).build(); MESES.forEach(m => { const sh = ss.getSheetByName('SEMANA ' + m); if (!sh) return; sh.getRange('B4:B220').setDataValidation(produtoRule); sh.getRange('C4:C220').setDataValidation(embRule); }); } function organizarAbasSemana() { const ss = SpreadsheetApp.getActive(); MESES.forEach(m => { const sh = ss.getSheetByName('SEMANA ' + m); if (!sh) return; sh.setFrozenRows(3); sh.getRange('A:A').setNumberFormat('dd/mm/yyyy'); sh.getRange('D:D').setNumberFormat('#,##0'); sh.getRange('G:I').setNumberFormat('#,##0'); }); }

Sheet INSTRUCOES
A1: INSTRUÇÕES DE USO DA PLANILHA
A3: 1. PREENCHIMENTO DIÁRIO
A4: - Preencha apenas:
A5: • Produto
A6: • Embalagem
A7: • Caixas
A9: - O restante é automático, não precisa mexer:
A10: • CX/Pallet
A11: • Pallets (PBR)
A12: • Real (CX)
A13: • Total de latas
A15: 2. DIAS SEM PRODUÇÃO
... A51: Se fizer isso certo, a planilha funciona sozinha 👍

Sheet CAPA
A1: CONTROLE DE PRODUÇÃO 2026
A3: Versão premium • visão executiva • preenchimento operacional simplificado
B5: TOTAL REALIZADO NO ANO | D5: META ACUMULADA | F5: ATINGIMENTO GERAL | H5: MELHOR MÊS
B6: =DASHBOARD!A6 | D6: =DASHBOARD!C6 | F6: =DASHBOARD!E6 | H6: =DASHBOARD!G6
A10: MAPA RÁPIDO DA PLANILHA
A11: 1. Abas SEMANA | B11: Preencher PRODUTO, EMBALAGEM e CAIXAS. As demais colunas fazem a leitura automática.
A12: 2. Abas GRAFICO | B12: Acompanhar realizado, meta e desempenho diário/mensal.
A13: 3. DASHBOARD | B13: Ver resumo executivo do ano, ranking e comparativos.
A14: 4. INSTRUÇÕES | B14: Consultar regras de uso, legenda e lógica dos totais.
A17: RECOMENDAÇÃO DE USO
A18: • Lance os itens do dia apenas na área amarela de preenchimento.
A19: • Use as linhas TOTAL somente para conferência; elas já foram ajustadas para não entrar na seleção manual.
A20: • Evite inserir fórmulas nas abas semanais fora dos campos já estruturados.
A21: • Para impressão ou apresentação, priorize as abas DASHBOARD, RESUMO_MENSAL e GRAFICO do mês.

Sheet JANEIRO
B1: ORDEM DE PRODUÇÃO - JANEIRO
B3: OP | C3: LOTE | E3: LOTE CLIENTE | G3: PRODUTO | K3: CLIENTE | M3: QTDE(Kg) | N3: FABRICAÇÃO
B4: 2026/001 | C4: 26010001 | G4: LISSE 600ML | K4: ADIMIX | M4: 7.980 LATAS | N4: 46027
C5: 26010002 | G5: LISSE 600ML | M5: 7.980 LATAS | N5: 46028
B6: 2026/002 | C6: 26010003 | G6: ALL BREAD 600ML | K6: ALL BREAD | M6: 9.168 LATAS | N6: 46037
B7: 2026/003 | C7: 26010004 | G7: UNTA FACIL 600ML | K7: IN LOCO | M7: 15.960 LATAS | N7: 46029
C8: 26010005 | G8: UNTA FACIL ECO 600ML | M8: 8.976 LATAS | N8: 46041 | O8: 308cxs
B9: 2026/004 | C9: 26010006 | G9: DESTAK 600ML | K9: PURATOS | M9: 22.800 LATAS | N9: 46031
B10: 2026/005 | C10: 26010007 | G10: TTF MEL 600ML | K10: TTF | M10: 3.420 LATAS | N10: 46041
B11: 2026/006 | C11: 26010008 | G11: OL 40 | K11: SMART | M11: 420 KG | N11: 46027
C12: 26010009 | G12: OL 40 | M12: 420 KG | N12: 46027
C13: 26010010 | G13: OL 40 | M13: 420 KG | N13: 46027
C14: 26010011 | G14: OL 40 | M14: 420 KG | N14: 46027
C15: 26010012 | G15: OL 40 | M15: 420 KG | N15: 46027
C16: 26010013 | G16: OL 40 | M16: 420 KG | N16: 46027
C17: 26010014 | G17: OL 40 | M17: 420 KG | N17: 46028
C18: 26010015 | G18: OL 40 | M18: 420 KG | N18: 46028
C19: 26010016 | G19: OL 40 | M19: 420 KG | N19: 46029
C20: 26010017 | G20: OL 40 | M20: 420 KG | N20: 46029
C21: 26010018 | G21: OL 40 | M21: 420 KG | N21: 46029
C22: 26010019 | G22: OL 40 | M22: 420 KG | N22: 46029
C23: 26010020 | G23: OL 40 | M23: 420 KG | N23: 46029
... C46: 26060043 | G46: AL 10 | M46: 1.444 KG | N46: 46028
B47: 2026/007 | C47: 26060044 | E47: AL 43 | G47: AL 10 - 25LTRS | K47: MATEUS | M47: 67 BBs | N47: 46028
B48: 2026/008 | C48: 26010045 | G48: DESTAK 5L | K48: PURATOS | M48: 2.500 LTRS | N48: 46035
C49: 26010046 | G49: DESTAK 5L | M49: 5.000 LTRS | N49: 46036
C50: 26010047 | G50: DESTAK 5L | M50: 1.000 LTRS | N50: 46037
C51: 26010048 | G51: DESTAK 5L | M51: 3.000 LTRS | O51: FALTARÃO 12 PALLETS PARA ENTREGAR
B52: 2026/009 | C52: 26030050 | G52: CORANTE AMARELO | K52: SMART | M52: 30 KG | N52: 46045
C53: 26030051 | G53: CORANTE AZUL | M53: 28 KG | N53: 46073
C54: 26030052 | G54: CORANTE VIOLETA | M54: 25 KG | N54: 46045
C55: 26030053 | G55: CORANTE ROSA | M55: 24 KG | N55: 46073
C56: 26030054 | G56: CORANTE VERMELHO | M56: 30 KG | N56: 46045
B57: 2026/010 | E57: 26030050 | G57: CORANTE AMARELO | K57: REPETECO | M57: 1.440 LATAS | N57: 46045
E58: 26030051 | G58: CORANTE AZUL | M58: 1.440 LATAS | N58: 46045
E59: 26030052 | G59: CORANTE VIOLETA | M59: 1.440 LATAS | N59: 46045
E60: 26030053 | G60: CORANTE ROSA | M60: 1.440 LATAS
E61: 26030054 | G61: CORANTE VERMELHO | M61: 1.440 LATAS | N61: 46045
B62: 2026/011 | E62: 26030051 | G62: CORANTE AZUL | K62: IN LOCO | M62: 2.880 LATAS | N62: 46078
B63: 2026/012 | C63: 26020055 | G63: ESPUMA GENGIBRE | K63: SMART | M63: 2.340 KG | N63: 46042
...

Sheet SEMANA JANEIRO
A1: LANÇAMENTO DE PRODUÇÃO • PREENCHIMENTO RÁPIDO | J1: _TOTAL_CX_NUM | K1: _TOTAL_PALLETS_NUM | L1: _TOTAL_REALCX_NUM | M1: _TOTAL_LATAS_NUM
A2: Preencha produto, embalagem e caixas. As demais colunas ajudam a leitura diária. | G2: Legenda: verde = acima da meta • vermelho = abaixo da meta | P2: Pallet PBR: 600ml=95 | 400ml=125 | 200ml=330 | 180ml=240 cx
A3: 46027 | B3: PRODUTO | C3: EMBALAGEM | D3: CAIXAS | E3: UN | F3: CX/PALLET | G3: PALLETS (PBR) | H3: REAL (CX) | I3: TOTAL LATAS | P3: A bengala de energia da ENEL caiu, paramos eram 15:30.
L4: =IF(H4="","",H4) | N4: =IF(I4="","",I4)
B5: ADIMIX (PRECISION) | C5: 600 | D5: 665 | E5: CX | F5: =IF($B5="","",IF(SUMIFS(CONFIG_PALLETS!$C:$C,CONFIG_PALLETS!$A:$A,TRIM($B5),CONFIG_PALLETS!$B:$B,$C5&" ml")>0,SUMIFS(CONFIG_PALLETS!$C:$C,CONFIG_PALLETS!$A:$A,TRIM($B5),CONFIG_PALLETS!$B:$B,$C5&" ml"),IF(SUMIFS(CONFIG_PALLETS!$C:$C,CONFIG_PALLETS!$A:$A,"GERAL",CONFIG_PALLETS!$B:$B,$C5&" ml")>0,SUMIFS(CONFIG_PALLETS!$C:$C,CONFIG_PALLETS!$A:$A,"GERAL",CONFIG_PALLETS!$B:$B,$C5&" ml"),""))) | G5: =IFERROR(ROUNDUP(D5/F5,0),"") | H5: 667 | I5: =IF(H5="","",H5*IF(SUMIFS(CONFIG_PALLETS!$D:$D,CONFIG_PALLETS!$A:$A,IF(ISNUMBER(SEARCH("ESPUMA",$B5)),"ESPUMA",IF(OR(ISNUMBER(SEARCH("OLEO DE COCO",$B5)),ISNUMBER(SEARCH("ÓLEO DE COCO",$B5)),ISNUMBER(SEARCH("COPRA",$B5))),"ÓLEO DE COCO",IF(ISNUMBER(SEARCH("CORANTE",$B5)),"CORANTE",TRIM($B5)))),CONFIG_PALLETS!$B:$B,$C5&" ml")>0,SUMIFS(CONFIG_PALLETS!$D:$D,CONFIG_PALLETS!$A:$A,IF(ISNUMBER(SEARCH("ESPUMA",$B5)),"ESPUMA",IF(OR(ISNUMBER(SEARCH("OLEO DE COCO",$B5)),ISNUMBER(SEARCH("ÓLEO DE COCO",$B5)),ISNUMBER(SEARCH("COPRA",$B5))),"ÓLEO DE COCO",IF(ISNUMBER(SEARCH("CORANTE",$B5)),"CORANTE",TRIM($B5)))),CONFIG_PALLETS!$B:$B,$C5&" ml"),IF(SUMIFS(CONFIG_PALLETS!$D:$D,CONFIG_PALLETS!$A:$A,"GERAL",CONFIG_PALLETS!$B:$B,$C5&" ml")>0,SUMIFS(CONFIG_PALLETS!$D:$D,CONFIG_PALLETS!$A:$A,"GERAL",CONFIG_PALLETS!$B:$B,$C5&" ml"),12))) | J5: =IF(D5="","",ROUNDUP(D5/IF(AND(C5="600 ml",ISNUMBER(SEARCH("NORCAU",B5))),95,IF(AND(C5="600 ml",ISNUMBER(SEARCH("APURATOS",B5))),190,IF(C5="600 ml",95,IF(C5="400 ml",125,IF(C5="200 ml",330,IF(C5="180 ml",240,1)))))),0)) | L5: =IF(H5="","",H5) | N5: =IF(I5="","",I5)
B6: ADIMIX (FADEVA) | C6: 600 | D6: 665 | E6: CX | F6: =IF($B6="","",IF(SUMIFS(CONFIG_PALLETS!$C:$C,CONFIG_PALLETS!$A:$A,TRIM($B6),CONFIG_PALLETS!$B:$B,$C6&" ml")>0,SUMIFS(CONFIG_PALLETS!$C:$C,CONFIG_PALLETS!$A:$A,TRIM($B6),CONFIG_PALLETS!$B:$B,$C6&" ml"),IF(SUMIFS(CONFIG_PALLETS!$C:$C,CONFIG_PALLETS!$A:$A,"GERAL",CONFIG_PALLETS!$B:$B,$C6&" ml")>0,SUMIFS(CONFIG_PALLETS!$C:$C,CONFIG_PALLETS!$A:$A,"GERAL",CONFIG_PALLETS!$B:$B,$C6&" ml"),""))) | G6: =IFERROR(ROUNDUP(D6/F6,0),"") | H6: 29 | I6: =IF(H6="","",H6*IF(SUMIFS(CONFIG_PALLETS!$D:$D,CONFIG_PALLETS!$A:$A,IF(ISNUMBER(SEARCH("ESPUMA",$B6)),"ESPUMA",IF(OR(ISNUMBER(SEARCH("OLEO DE COCO",$B6)),ISNUMBER(SEARCH("ÓLEO DE COCO",$B6)),ISNUMBER(SEARCH("COPRA",$B6))),"ÓLEO DE COCO",IF(ISNUMBER(SEARCH("CORANTE",$B6)),"CORANTE",TRIM($B6)))),CONFIG_PALLETS!$B:$B,$C6&" ml")>0,SUMIFS(CONFIG_PALLETS!$D:$D,CONFIG_PALLETS!$A:$A,IF(ISNUMBER(SEARCH("ESPUMA",$B6)),"ESPUMA",IF(OR(ISNUMBER(SEARCH("OLEO DE COCO",$B6)),ISNUMBER(SEARCH("ÓLEO DE COCO",$B6)),ISNUMBER(SEARCH("COPRA",$B6))),"ÓLEO DE COCO",IF(ISNUMBER(SEARCH("CORANTE",$B6)),"CORANTE",TRIM($B6)))),CONFIG_PALLETS!$B:$B,$C6&" ml"),IF(SUMIFS(CONFIG_PALLETS!$D:$D,CONFIG_PALLETS!$A:$A,"GERAL",CONFIG_PALLETS!$B:$B,$C6&" ml")>0,SUMIFS(CONFIG_PALLETS!$D:$D,CONFIG_PALLETS!$A:$A,"GERAL",CONFIG_PALLETS!$B:$B,$C6&" ml"),12))) | J6: =IF(D6="","",ROUNDUP(D6/IF(AND(C6="600 ml",ISNUMBER(SEARCH("NORCAU",B6))),95,IF(AND(C6="600 ml",ISNUMBER(SEARCH("APURATOS",B6))),190,IF(C6="600 ml",95,IF(C6="400 ml",125,IF(C6="200 ml",330,IF(C6="180 ml",240,1)))))),0)) | L6: =IF(H6="","",H6) | N6: =IF(I6="","",I6)
E7: CX | F7: =IF($B7="","",IF(SUMIFS(CONFIG_PALLETS!$C:$C,CONFIG_PALLETS!$A:$A,TRIM($B7),CONFIG_PALLETS!$B:$B,$C7&" ml")>0,SUMIFS(CONFIG_PALLETS!$C:$C,CONFIG_PALLETS!$A:$A,TRIM($B7),CONFIG_PALLETS!$B:$B,$C7&" ml"),IF(SUMIFS(CONFIG_PALLETS!$C:$C,CONFIG_PALLETS!$A:$A,"GERAL",CONFIG_PALLETS!$B:$B,$C7&" ml")>0,SUMIFS(CONFIG_PALLETS!$C:$C,CONFIG_PALLETS!$A:$A,"GERAL",CONFIG_PALLETS!$B:$B,$C7&" ml"),""))) | G7: =IFERROR(ROUNDUP(D7/F7,0),"") | I7: =IF(H7="","",H7*IF(SUMIFS(CONFIG_PALLETS!$D:$D,CONFIG_PALLETS!$A:$A,IF(ISNUMBER(SEARCH("ESPUMA",$B7)),"ESPUMA",IF(OR(ISNUMBER(SEARCH("OLEO DE COCO",$B7)),ISNUMBER(SEARCH("ÓLEO DE COCO",$B7)),ISNUMBER(SEARCH("COPRA",$B7))),"ÓLEO DE COCO",IF(ISNUMBER(SEARCH("CORANTE",$B7)),"CORANTE",TRIM($B7)))),CONFIG_PALLETS!$B:$B,$C7&" ml")>0,SUMIFS(CONFIG_PALLETS!$D:$D,CONFIG_PALLETS!$A:$A,IF(ISNUMBER(SEARCH("ESPUMA",$B7)),"ESPUMA",IF(OR(ISNUMBER(SEARCH("OLEO DE COCO",$B7)),ISNUMBER(SEARCH("ÓLEO DE COCO",$B7)),ISNUMBER(SEARCH("COPRA",$B7))),"ÓLEO DE COCO",IF(ISNUMBER(SEARCH("CORANTE",$B7)),"CORANTE",TRIM($B7)))),CONFIG_PALLETS!$B:$B,$C7&" ml"),IF(SUMIFS(CONFIG_PALLETS!$D:$D,CONFIG_PALLETS!$A:$A,"GERAL",CONFIG_PALLETS!$B:$B,$C7&" ml")>0,SUMIFS(CONFIG_PALLETS!$D:$D,CONFIG_PALLETS!$A:$A,"GERAL",CONFIG_PALLETS!$B:$B,$C7&" ml"),12))) | J7: =IF(D7="","",ROUNDUP(D7/IF(AND(C7="600 ml",ISNUMBER(SEARCH("NORCAU",B7))),95,IF(AND(C7="600 ml",ISNUMBER(SEARCH("APURATOS",B7))),190,IF(C7="600 ml",95,IF(C7="400 ml",125,IF(C7="200 ml",330,IF(C7="180 ml",240,1)))))),0)) | L7: =IF(H7="","",H7) | N7: =IF(I7="","",I7)
J8: =IF(D8="","",ROUNDUP(D8/IF(AND(C8="600 ml",ISNUMBER(SEARCH("NORCAU",B8))),95,IF(AND(C8="600 ml",ISNUMBER(SEARCH("APURATOS",B8))),190,IF(C8="600 ml",95,IF(C8="400 ml",125,IF(C8="200 ml",330,IF(C8="180 ml",240,1)))))),0)) | L8: =IF(H8="","",H8) | N8: =IF(I8="","",I8)
B9: TOTAL | D9: =IF(J9="","",TEXT(J9,"#,##0")) | G9: =IF(K9="","",TEXT(K9,"#,##0")) | H9: =IF(L9="","",TEXT(L9,"#,##0")) | I9: =IF(M9="","",TEXT(M9,"#,##0")) | J9: =SUM(D4:D8) | K9: =SUM(G4:G8) | L9: =SUM(H4:H8) | M9: =SUM(I4:I8) | N9: =IF(I9="","",I9) | O9: =SUM(N5:N8)
J10: =IF(D10="","",ROUNDUP(D10/IF(AND(C10="600 ml",ISNUMBER(SEARCH("NORCAU",B10))),95,IF(AND(C10="600 ml",ISNUMBER(SEARCH("APURATOS",B10))),190,IF(C10="600 ml",95,IF(C10="400 ml",125,IF(C10="200 ml",330,IF(C10="180 ml",240,1)))))),0)) | L10: =IF(H10="","",H10) | N10: =IF(I10="","",I10)
A11: 46028 | B11: PRODUTO | C11: EMBALAGEM | D11: CAIXAS | E11: UN | F11: CX/PALLET | G11: PALLETS (PBR) | H11: REAL (CX) | I11: TOTAL LATAS
J12: =IF(D12="","",ROUNDUP(D12/IF(AND(C12="600 ml",ISNUMBER(SEARCH("NORCAU",B12))),95,IF(AND(C12="600 ml",ISNUMBER(SEARCH("APURATOS",B12))),190,IF(C12="600 ml",95,IF(C12="400 ml",125,IF(C12="200 ml",330,IF(C12="180 ml",240,1)))))),0)) | L12: =IF(H12="","",H12) | N12: =IF(I12="","",I12) | P12: A luz voltou as 15:15.
B13: ADIMIX (FADEVA) | C13: 600 | D13: =D6-L6 | E13: CX | F13: =IF($B13="","",IF(SUMIFS(CONFIG_PALLETS!$C:$C,CONFIG_PALLETS!$A:$A,TRIM($B13),CONFIG_PALLETS!$B:$B,$C13&" ml")>0,SUMIFS(CONFIG_PALLETS!$C:$C,CONFIG_PALLETS!$A:$A,TRIM($B13),CONFIG_PALLETS!$B:$B,$C13&" ml"),IF(SUMIFS(CONFIG_PALLETS!$C:$C,CONFIG_PALLETS!$A:$A,"GERAL",CONFIG_PALLETS!$B:$B,$C13&" ml")>0,SUMIFS(CONFIG_PALLETS!$C:$C,CONFIG_PALLETS!$A:$A,"GERAL",CONFIG_PALLETS!$B:$B,$C13&" ml"),""))) | G13: =IFERROR(ROUNDUP(D13/F13,0),"") | H13: 156 | I13: =IF(H13="","",H13*IF(SUMIFS(CONFIG_PALLETS!$D:$D,CONFIG_PALLETS!$A:$A,IF(ISNUMBER(SEARCH("ESPUMA",$B13)),"ESPUMA",IF(OR(ISNUMBER(SEARCH("OLEO DE COCO",$B13)),ISNUMBER(SEARCH("ÓLEO DE COCO",$B13)),ISNUMBER(SEARCH("COPRA",$B13))),"ÓLEO DE COCO",IF(ISNUMBER(SEARCH("CORANTE",$B13)),"CORANTE",TRIM($B13)))),CONFIG_PALLETS!$B:$B,$C13&" ml")>0,SUMIFS(CONFIG_PALLETS!$D:$D,CONFIG_PALLETS!$A:$A,IF(ISNUMBER(SEARCH("ESPUMA",$B13)),"ESPUMA",IF(OR(ISNUMBER(SEARCH("OLEO DE COCO",$B13)),ISNUMBER(SEARCH("ÓLEO DE COCO",$B13)),ISNUMBER(SEARCH("COPRA",$B13))),"ÓLEO DE COCO",IF(ISNUMBER(SEARCH("CORANTE",$B13)),"CORANTE",TRIM($B13)))),CONFIG_PALLETS!$B:$B,$C13&" ml"),IF(SUMIFS(CONFIG_PALLETS!$D:$D,CONFIG_PALLETS!$A:$A,"GERAL",CONFIG_PALLETS!$B:$B,$C13&" ml")>0,SUMIFS(CONFIG_PALLETS!$D:$D,CONFIG_PALLETS!$A:$A,"GERAL",CONFIG_PALLETS!$B:$B,$C13&" ml"),12))) | J13: =IF(D13="","",ROUNDUP(D13/IF(AND(C13="600 ml",ISNUMBER(SEARCH("NORCAU",B13))),95,IF(AND(C13="600 ml",ISNUMBER(SEARCH("APURATOS",B13))),190,IF(C13="600 ml",95,IF(C13="400 ml",125,IF(C13="200 ml",330,IF(C13="180 ml",240,1)))))),0)) | L13: =IF(H13="","",H13) | N13: =IF(I13="","",I13)
E14: CX | F14: =IF($B14="","",IF(SUMIFS(CONFIG_PALLETS!$C:$C,CONFIG_PALLETS!$A:$A,TRIM($B14),CONFIG_PALLETS!$B:$B,$C14&" ml")>0,SUMIFS(CONFIG_PALLETS!$C:$C,CONFIG_PALLETS!$A:$A,TRIM($B14),CONFIG_PALLETS!$B:$B,$C14&" ml"),IF(SUMIFS(CONFIG_PALLETS!$C:$C,CONFIG_PALLETS!$A:$A,"GERAL",CONFIG_PALLETS!$B:$B,$C14&" ml")>0,SUMIFS(CONFIG_PALLETS!$C:$C,CONFIG_PALLETS!$A:$A,"GERAL",CONFIG_PALLETS!$B:$B,$C14&" ml"),""))) | G14: =IFERROR(ROUNDUP(D14/F14,0),"") | I14: =IF(H14="","",H14*IF(SUMIFS(CONFIG_PALLETS!$D:$D,CONFIG_PALLETS!$A:$A,IF(ISNUMBER(SEARCH("ESPUMA",$B14)),"ESPUMA",IF(OR(ISNUMBER(SEARCH("OLEO DE COCO",$B14)),ISNUMBER(SEARCH("ÓLEO DE COCO",$B14)),ISNUMBER(SEARCH("COPRA",$B14))),"ÓLEO DE COCO",IF(ISNUMBER(SEARCH("CORANTE",$B14)),"CORANTE",TRIM($B14)))),CONFIG_PALLETS!$B:$B,$C14&" ml")>0,SUMIFS(CONFIG_PALLETS!$D:$D,CONFIG_PALLETS!$A:$A,IF(ISNUMBER(SEARCH("ESPUMA",$B14)),"ESPUMA",IF(OR(ISNUMBER(SEARCH("OLEO DE COCO",$B14)),ISNUMBER(SEARCH("ÓLEO DE COCO",$B14)),ISNUMBER(SEARCH("COPRA",$B14))),"ÓLEO DE COCO",IF(ISNUMBER(SEARCH("CORANTE",$B14)),"CORANTE",TRIM($B14)))),CONFIG_PALLETS!$B:$B,$C14&" ml"),IF(SUMIFS(CONFIG_PALLETS!$D:$D,CONFIG_PALLETS!$A:$A,"GERAL",CONFIG_PALLETS!$B:$B,$C14&" ml")>0,SUMIFS(CONFIG_PALLETS!$D:$D,CONFIG_PALLETS!$A:$A,"GERAL",CONFIG_PALLETS!$B:$B,$C14&" ml"),12))) | J14: =IF(D14="","",ROUNDUP(D14/IF(AND(C14="600 ml",ISNUMBER(SEARCH("NORCAU",B14))),95,IF(AND(C14="600 ml",ISNUMBER(SEARCH("APURATOS",B14))),190,IF(C14="600 ml",95,IF(C14="400 ml",125,IF(C14="200 ml",330,IF(C14="180 ml",240,1)))))),0)) | L14: =IF(H14="","",H14) | N14: =IF(I14="","",I14)
J15: =IF(D15="","",ROUNDUP(D15/IF(AND(C15="600 ml",ISNUMBER(SEARCH("NORCAU",B15))),95,IF(AND(C15="600 ml",ISNUMBER(SEARCH("APURATOS",B15))),190,IF(C15="600 ml",95,IF(C15="400 ml",125,IF(C15="200 ml",330,IF(C15="180 ml",240,1)))))),0)) | L15: =IF(H15="","",H15) | N15: =IF(I15="","",I15)
B16: TOTAL | D16: =IF(J16="","",TEXT(J16,"#,##0")) | G16: =IF(K16="","",TEXT(K16,"#,##0")) | H16: =IF(L16="","",TEXT(L16,"#,##0")) | I16: =IF(M16="","",TEXT(M16,"#,##0")) | J16: =SUM(D12:D15) | K16: =SUM(G12:G15) | L16: =SUM(H12:H15) | M16: =SUM(I12:I15) | N16: =IF(I16="","",I16) | O16: =SUM(N13:N15)
J17: =IF(D17="","",ROUNDUP(D17/IF(AND(C17="600 ml",ISNUMBER(SEARCH("NORCAU",B17))),95,IF(AND(C17="600 ml",ISNUMBER(SEARCH("APURATOS",B17))),190,IF(C17="600 ml",95,IF(C17="400 ml",125,IF(C17="200 ml",330,IF(C17="180 ml",240,1)))))),0)) | L17: =IF(H17="","",H17) | N17: =IF(I17="","",I17)
A18: 46029 | B18: PRODUTO | C18: EMBALAGEM | D18: CAIXAS | E18: UN | F18: CX/PALLET | G18: PALLETS (PBR) | H18: REAL (CX) | I18: TOTAL LATAS
J19: =IF(D19="","",ROUNDUP(D19/IF(AND(C19="600 ml",ISNUMBER(SEARCH("NORCAU",B19))),95,IF(AND(C19="600 ml",ISNUMBER(SEARCH("APURATOS",B19))),190,IF(C19="600 ml",95,IF(C19="400 ml",125,IF(C19="200 ml",330,IF(C19="180 ml",240,1)))))),0)) | L19: =IF(H19="","",H19) | N19: =IF(I19="","",I19)
B20: ADIMIX | C20: 600 | D20: =D13-L13 | E20: CX | F20: =IF($B20="","",IF(SUMIFS(CONFIG_PALLETS!$C:$C,CONFIG_PALLETS!$A:$A,TRIM($B20),CONFIG_PALLETS!$B:$B,$C20&" ml")>0,SUMIFS(CONFIG_PALLETS!$C:$C,CONFIG_PALLETS!$A:$A,TRIM($B20),CONFIG_PALLETS!$B:$B,$C20&" ml"),IF(SUMIFS(CONFIG_PALLETS!$C:$C,CONFIG_PALLETS!$A:$A,"GERAL",CONFIG_PALLETS!$B:$B,$C20&" ml")>0,SUMIFS(CONFIG_PALLETS!$C:$C,CONFIG_PALLETS!$A:$A,"GERAL",CONFIG_PALLETS!$B:$B,$C20&" ml"),""))) | G20: =IFERROR(ROUNDUP(D20/F20,0),"") | H20: 494 | I20: =IF(H20="","",H20*IF(SUMIFS(CONFIG_PALLETS!$D:$D,CONFIG_PALLETS!$A:$A,IF(ISNUMBER(SEARCH("ESPUMA",$B20)),"ESPUMA",IF(OR(ISNUMBER(SEARCH("OLEO DE COCO",$B20)),ISNUMBER(SEARCH("ÓLEO DE COCO",$B20)),ISNUMBER(SEARCH("COPRA",$B20))),"ÓLEO DE COCO",IF(ISNUMBER(SEARCH("CORANTE",$B20)),"CORANTE",TRIM($B20)))),CONFIG_PALLETS!$B:$B,$C20&" ml")>0,SUMIFS(CONFIG_PALLETS!$D:$D,CONFIG_PALLETS!$A:$A,IF(ISNUMBER(SEARCH("ESPUMA",$B20)),"ESPUMA",IF(OR(ISNUMBER(SEARCH("OLEO DE COCO",$B20)),ISNUMBER(SEARCH("ÓLEO DE COCO",$B20)),ISNUMBER(SEARCH("COPRA",$B20))),"ÓLEO DE COCO",IF(ISNUMBER(SEARCH("CORANTE",$B20)),"CORANTE",TRIM($B20)))),CONFIG_PALLETS!$B:$B,$C20&" ml"),IF(SUMIFS(CONFIG_PALLETS!$D:$D,CONFIG_PALLETS!$A:$A,"GERAL",CONFIG_PALLETS!$B:$B,$C20&" ml")>0,SUMIFS(CONFIG_PALLETS!$D:$D,CONFIG_PALLETS!$A:$A,"GERAL",CONFIG_PALLETS!$B:$B,$C20&" ml"),12))) | J20: =IF(D20="","",ROUNDUP(D20/IF(AND(C20="600 ml",ISNUMBER(SEARCH("NORCAU",B20))),95,IF(AND(C20="600 ml",ISNUMBER(SEARCH("APURATOS",B20))),190,IF(C20="600 ml",95,IF(C20="400 ml",125,IF(C20="200 ml",330,IF(C20="180 ml",240,1)))))),0)) | L20: =IF(H20="","",H20) | N20: =IF(I20="","",I20)
B21: UNTA FACIL | C21: 600 | D21: 1348 | E21: CX | F21: =IF($B21="","",IF(SUMIFS(CONFIG_PALLETS!$C:$C,CONFIG_PALLETS!$A:$A,TRIM($B21),CONFIG_PALLETS!$B:$B,$C21&" ml")>0,SUMIFS(CONFIG_PALLETS!$C:$C,CONFIG_PALLETS!$A:$A,TRIM($B21),CONFIG_PALLETS!$B:$B,$C21&" ml"),IF(SUMIFS(CONFIG_PALLETS!$C:$C,CONFIG_PALLETS!$A:$A,"GERAL",CONFIG_PALLETS!$B:$B,$C21&" ml")>0,SUMIFS(CONFIG_PALLETS!$C:$C,CONFIG_PALLETS!$A:$A,"GERAL",CONFIG_PALLETS!$B:$B,$C21&" ml"),""))) | G21: =IFERROR(ROUNDUP(D21/F21,0),"") | H21: 509 | I21: =IF(H21="","",H21*IF(SUMIFS(CONFIG_PALLETS!$D:$D,CONFIG_PALLETS!$A:$A,IF(ISNUMBER(SEARCH("ESPUMA",$B21)),"ESPUMA",IF(OR(ISNUMBER(SEARCH("OLEO DE COCO",$B21)),ISNUMBER(SEARCH("ÓLEO DE COCO",$B21)),ISNUMBER(SEARCH("COPRA",$B21))),"ÓLEO DE COCO",IF(ISNUMBER(SEARCH("CORANTE",$B21)),"CORANTE",TRIM($B21)))),CONFIG_PALLETS!$B:$B,$C21&" ml")>0,SUMIFS(CONFIG_PALLETS!$D:$D,CONFIG_PALLETS!$A:$A,IF(ISNUMBER(SEARCH("ESPUMA",$B21)),"ESPUMA",IF(OR(ISNUMBER(SEARCH("OLEO DE COCO",$B21)),ISNUMBER(SEARCH("ÓLEO DE COCO",$B21)),ISNUMBER(SEARCH("COPRA",$B21))),"ÓLEO DE COCO",IF(ISNUMBER(SEARCH("CORANTE",$B21)),"CORANTE",TRIM($B21)))),CONFIG_PALLETS!$B:$B,$C21&" ml"),IF(SUMIFS(CONFIG_PALLETS!$D:$D,CONFIG_PALLETS!$A:$A,"GERAL",CONFIG_PALLETS!$B:$B,$C21&" ml")>0,SUMIFS(CONFIG_PALLETS!$D:$D,CONFIG_PALLETS!$A:$A,"GERAL",CONFIG_PALLETS!$B:$B,$C21&" ml"),12))) | J21: =IF(D21="","",ROUNDUP(D21/IF(AND(C21="600 ml",ISNUMBER(SEARCH("NORCAU",B21))),95,IF(AND(C21="600 ml",ISNUMBER(SEARCH("APURATOS",B21))),190,IF(C21="600 ml",95,IF(C21="400 ml",125,IF(C21="200 ml",330,IF(C21="180 ml",240,1)))))),0)) | L21: =IF(H21="","",H21) | N21: =IF(I21="","",I21)
E22: CX | F22: =IF($B22="","",IF(SUMIFS(CONFIG_PALLETS!$C:$C,CONFIG_PALLETS!$A:$A,TRIM($B22),CONFIG_PALLETS!$B:$B,$C22&" ml")>0,SUMIFS(CONFIG_PALLETS!$C:$C,CONFIG_PALLETS!$A:$A,TRIM($B22),CONFIG_PALLETS!$B:$B,$C22&" ml"),IF(SUMIFS(CONFIG_PALLETS!$C:$C,CONFIG_PALLETS!$A:$A,"GERAL",CONFIG_PALLETS!$B:$B,$C22&" ml")>0,SUMIFS(CONFIG_PALLETS!$C:$C,CONFIG_PALLETS!$A:$A,"GERAL",CONFIG_PALLETS!$B:$B,$C22&" ml"),""))) | G22: =IFERROR(ROUNDUP(D22/F22,0),"") | I22: =IF(H22="","",H22*IF(SUMIFS(CONFIG_PALLETS!$D:$D,CONFIG_PALLETS!$A:$A,IF(ISNUMBER(SEARCH("ESPUMA",$B22)),"ESPUMA",IF(OR(ISNUMBER(SEARCH("OLEO DE COCO",$B22)),ISNUMBER(SEARCH("ÓLEO DE COCO",$B22)),ISNUMBER(SEARCH("COPRA",$B22))),"ÓLEO DE COCO",IF(ISNUMBER(SEARCH("CORANTE",$B22)),"CORANTE",TRIM($B22)))),CONFIG_PALLETS!$B:$B,$C22&" ml")>0,SUMIFS(CONFIG_PALLETS!$D:$D,CONFIG_PALLETS!$A:$A,IF(ISNUMBER(SEARCH("ESPUMA",$B22)),"ESPUMA",IF(OR(ISNUMBER(SEARCH("OLEO DE COCO",$B22)),ISNUMBER(SEARCH("ÓLEO DE COCO",$B22)),ISNUMBER(SEARCH("COPRA",$B22))),"ÓLEO DE COCO",IF(ISNUMBER(SEARCH("CORANTE",$B22)),"CORANTE",TRIM($B22)))),CONFIG_PALLETS!$B:$B,$C22&" ml"),IF(SUMIFS(CONFIG_PALLETS!$D:$D,CONFIG_PALLETS!$A:$A,"GERAL",CONFIG_PALLETS!$B:$B,$C22&" ml")>0,SUMIFS(CONFIG_PALLETS!$D:$D,CONFIG_PALLETS!$A:$A,"GERAL",CONFIG_PALLETS!$B:$B,$C22&" ml"),12))) | J22: =IF(D22="","",ROUNDUP(D22/IF(AND(C22="600 ml",ISNUMBER(SEARCH("NORCAU",B22))),95,IF(AND(C22="600 ml",ISNUMBER(SEARCH("APURATOS",B22))),190,IF(C22="600 ml",95,IF(C22="400 ml",125,IF(C22="200 ml",330,IF(C22="180 ml",240,1)))))),0)) | L22: =IF(H22="","",H22) | N22: =IF(I22="","",I22)
J23: =IF(D23="","",ROUNDUP(D23/IF(AND(C23="600 ml",ISNUMBER(SEARCH("NORCAU",B23))),95,IF(AND(C23="600 ml",ISNUMBER(SEARCH("APURATOS",B23))),190,IF(C23="600 ml",95,IF(C23="400 ml",125,IF(C23="200 ml",330,IF(C23="180 ml",240,1)))))),0)) | L23: =IF(H23="","",H23) | N23: =IF(I23="","",I23)
B24: TOTAL | D24: =IF(J24="","",TEXT(J24,"#,##0")) | G24: =IF(K24="","",TEXT(K24,"#,##0")) | H24: =IF(L24="","",TEXT(L24,"#,##0")) | I24: =IF(M24="","",TEXT(M24,"#,##0")) | J24: =SUM(D19:D23) | K24: =SUM(G19:G23) | L24: =SUM(H19:H23) | M24: =SUM(I19:I23) | N24: =IF(I24="","",I24) | O24: =SUM(N20:N23)
J25: =IF(D25="","",ROUNDUP(D25/IF(AND(C25="600 ml",ISNUMBER(SEARCH("NORCAU",B25))),95,IF(AND(C25="600 ml",ISNUMBER(SEARCH("APURATOS",B25))),190,IF(C25="600 ml",95,IF(C25="400 ml",125,IF(C25="200 ml",330,IF(C25="180 ml",240,1)))))),0)) | L25: =IF(H25="","",H25) | N25: =IF(I25="","",I25)
A26: 46030 | B26: PRODUTO | C26: EMBALAGEM | D26: CAIXAS | E26: UN | F26: CX/PALLET | G26: PALLETS (PBR) | H26: REAL (CX) | I26: TOTAL LATAS | P26: Acabou o gás eram 08:40, voltamos 10:30.
J27: =IF(D27="","",ROUNDUP(D27/IF(AND(C27="600 ml",ISNUMBER(SEARCH("NORCAU",B27))),95,IF(AND(C27="600 ml",ISNUMBER(SEARCH("APURATOS",B27))),190,IF(C27="600 ml",95,IF(C27="400 ml",125,IF(C27="200 ml",330,IF(C27="180 ml",240,1)))))),0)) | L27: =IF(H27="","",H27) | N27: =IF(I27="","",I27)
B28: UNTA FACIL | C28: 600 | D28: =D21-L21 | E28: CX | F28: =IF($B28="","",IF(SUMIFS(CONFIG_PALLETS!$C:$C,CONFIG_PALLETS!$A:$A,TRIM($B28),CONFIG_PALLETS!$B:$B,$C28&" ml")>0,SUMIFS(CONFIG_PALLETS!$C:$C,CONFIG_PALLETS!$A:$A,TRIM($B28),CONFIG_PALLETS!$B:$B,$C28&" ml"),IF(SUMIFS(CONFIG_PALLETS!$C:$C,CONFIG_PALLETS!$A:$A,"GERAL",CONFIG_PALLETS!$B:$B,$C28&" ml")>0,SUMIFS(CONFIG_PALLETS!$C:$C,CONFIG_PALLETS!$A:$A,"GERAL",CONFIG_PALLETS!$B:$B,$C28&" ml"),""))) | G28: =IFERROR(ROUNDUP(D28/F28,0),"") | H28: 821 | I28: =IF(H28="","",H28*IF(SUMIFS(CONFIG_PALLETS!$D:$D,CONFIG_PALLETS!$A:$A,IF(ISNUMBER(SEARCH("ESPUMA",$B28)),"ESPUMA",IF(OR(ISNUMBER(SEARCH("OLEO DE COCO",$B28)),ISNUMBER(SEARCH("ÓLEO DE COCO",$B28)),ISNUMBER(SEARCH("COPRA",$B28))),"ÓLEO DE COCO",IF(ISNUMBER(SEARCH("CORANTE",$B28)),"CORANTE",TRIM($B28)))),CONFIG_PALLETS!$B:$B,$C28&" ml")>0,SUMIFS(CONFIG_PALLETS!$D:$D,CONFIG_PALLETS!$A:$A,IF(ISNUMBER(SEARCH("ESPUMA",$B28)),"ESPUMA",IF(OR(ISNUMBER(SEARCH("OLEO DE COCO",$B28)),ISNUMBER(SEARCH("ÓLEO DE COCO",$B28)),ISNUMBER(SEARCH("COPRA",$B28))),"ÓLEO DE COCO",IF(ISNUMBER(SEARCH("CORANTE",$B28)),"CORANTE",TRIM($B28)))),CONFIG_PALLETS!$B:$B,$C28&" ml"),IF(SUMIFS(CONFIG_PALLETS!$D:$D,CONFIG_PALLETS!$A:$A,"GERAL",CONFIG_PALLETS!$B:$B,$C28&" ml")>0,SUMIFS(CONFIG_PALLETS!$D:$D,CONFIG_PALLETS!$A:$A,"GERAL",CONFIG_PALLETS!$B:$B,$C28&" ml"),12))) | J28: =IF(D28="","",ROUNDUP(D28/IF(AND(C28="600 ml",ISNUMBER(SEARCH("NORCAU",B28))),95,IF(AND(C28="600 ml",ISNUMBER(SEARCH("APURATOS",B28))),190,IF(C28="600 ml",95,IF(C28="400 ml",125,IF(C28="200 ml",330,IF(C28="180 ml",240,1)))))),0)) | L28: =IF(H28="","",H28) | N28: =IF(I28="","",I28)
E29: CX | F29: =IF($B29="","",IF(SUMIFS(CONFIG_PALLETS!$C:$C,CONFIG_PALLETS!$A:$A,TRIM($B29),CONFIG_PALLETS!$B:$B,$C29&" ml")>0,SUMIFS(CONFIG_PALLETS!$C:$C,CONFIG_PALLETS!$A:$A,TRIM($B29),CONFIG_PALLETS!$B:$B,$C29&" ml"),IF(SUMIFS(CONFIG_PALLETS!$C:$C,CONFIG_PALLETS!$A:$A,"GERAL",CONFIG_PALLETS!$B:$B,$C29&" ml")>0,SUMIFS(CONFIG_PALLETS!$C:$C,CONFIG_PALLETS!$A:$A,"GERAL",CONFIG_PALLETS!$B:$B,$C29&" ml"),""))) | G29: =IFERROR(ROUNDUP(D29/F29,0),"") | I29: =IF(H29="","",H29*IF(SUMIFS(CONFIG_PALLETS!$D:$D,CONFIG_PALLETS!$A:$A,IF(ISNUMBER(SEARCH("ESPUMA",$B29)),"ESPUMA",IF(OR(ISNUMBER(SEARCH("OLEO DE COCO",$B29)),ISNUMBER(SEARCH("ÓLEO DE COCO",$B29)),ISNUMBER(SEARCH("COPRA",$B29))),"ÓLEO DE COCO",IF(ISNUMBER(SEARCH("CORANTE",$B29)),"CORANTE",TRIM($B29)))),CONFIG_PALLETS!$B:$B,$C29&" ml")>0,SUMIFS(CONFIG_PALLETS!$D:$D,CONFIG_PALLETS!$A:$A,IF(ISNUMBER(SEARCH("ESPUMA",$B29)),"ESPUMA",IF(OR(ISNUMBER(SEARCH("OLEO DE COCO",$B29)),ISNUMBER(SEARCH("ÓLEO DE COCO",$B29)),ISNUMBER(SEARCH("COPRA",$B29))),"ÓLEO DE COCO",IF(ISNUMBER(SEARCH("CORANTE",$B29)),"CORANTE",TRIM($B29)))),CONFIG_PALLETS!$B:$B,$C29&" ml"),IF(SUMIFS(CONFIG_PALLETS!$D:$D,CONFIG_PALLETS!$A:$A,"GERAL",CONFIG_PALLETS!$B:$B,$C29&" ml")>0,SUMIFS(CONFIG_PALLETS!$D:$D,CONFIG_PALLETS!$A:$A,"GERAL",CONFIG_PALLETS!$B:$B,$C29&" ml"),12))) | J29: =IF(D29="","",ROUNDUP(D29/IF(AND(C29="600 ml",ISNUMBER(SEARCH("NORCAU",B29))),95,IF(AND(C29="600 ml",ISNUMBER(SEARCH("APURATOS",B29))),190,IF(C29="600 ml",95,IF(C29="400 ml",125,IF(C29="200 ml",330,IF(C29="180 ml",240,1)))))),0)) | L29: =IF(H29="","",H29) | N29: =IF(I29="","",I29)
E30: CX | F30: =IF($B30="","",IF(SUMIFS(CONFIG_PALLETS!$C:$C,CONFIG_PALLETS!$A:$A,TRIM($B30),CONFIG_PALLETS!$B:$B,$C30&" ml")>0,SUMIFS(CONFIG_PALLETS!$C:$C,CONFIG_PALLETS!$A:$A,TRIM($B30),CONFIG_PALLETS!$B:$B,$C30&" ml"),IF(SUMIFS(CONFIG_PALLETS!$C:$C,CONFIG_PALLETS!$A:$A,"GERAL",CONFIG_PALLETS!$B:$B,$C30&" ml")>0,SUMIFS(CONFIG_PALLETS!$C:$C,CONFIG_PALLETS!$A:$A,"GERAL",CONFIG_PALLETS!$B:$B,$C30&" ml"),""))) | G30: =IFERROR(ROUNDUP(D30/F30,0),"") | I30: =IF(H30="","",H30*IF(SUMIFS(CONFIG_PALLETS!$D:$D,CONFIG_PALLETS!$A:$A,IF(ISNUMBER(SEARCH("ESPUMA",$B30)),"ESPUMA",IF(OR(ISNUMBER(SEARCH("OLEO DE COCO",$B30)),ISNUMBER(SEARCH("ÓLEO DE COCO",$B30)),ISNUMBER(SEARCH("COPRA",$B30))),"ÓLEO DE COCO",IF(ISNUMBER(SEARCH("CORANTE",$B30)),"CORANTE",TRIM($B30)))),CONFIG_PALLETS!$B:$B,$C30&" ml")>0,SUMIFS(CONFIG_PALLETS!$D:$D,CONFIG_PALLETS!$A:$A,IF(ISNUMBER(SEARCH("ESPUMA",$B30)),"ESPUMA",IF(OR(ISNUMBER(SEARCH("OLEO DE COCO",$B30)),ISNUMBER(SEARCH("ÓLEO DE COCO",$B30)),ISNUMBER(SEARCH("COPRA",$B30))),"ÓLEO DE COCO",IF(ISNUMBER(SEARCH("CORANTE",$B30)),"CORANTE",TRIM($B30)))),CONFIG_PALLETS!$B:$B,$C30&" ml"),IF(SUMIFS(CONFIG_PALLETS!$D:$D,CONFIG_PALLETS!$A:$A,"GERAL",CONFIG_PALLETS!$B:$B,$C30&" ml")>0,SUMIFS(CONFIG_PALLETS!$D:$D,CONFIG_PALLETS!$A:$A,"GERAL",CONFIG_PALLETS!$B:$B,$C30&" ml"),12))) | J30: =IF(D30="","",ROUNDUP(D30/IF(AND(C30="600 ml",ISNUMBER(SEARCH("NORCAU",B30))),95,IF(AND(C30="600 ml",ISNUMBER(SEARCH("APURATOS",B30))),190,IF(C30="600 ml",95,IF(C30="400 ml",125,IF(C30="200 ml",330,IF(C30="180 ml",240,1)))))),0)) | L30: =IF(H30="","",H30) | N30: =IF(I30="","",I30)
J31: =IF(D31="","",ROUNDUP(D31/IF(AND(C31="600 ml",ISNUMBER(SEARCH("NORCAU",B31))),95,IF(AND(C31="600 ml",ISNUMBER(SEARCH("APURATOS",B31))),190,IF(C31="600 ml",95,IF(C31="400 ml",125,IF(C31="200 ml",330,IF(C31="180 ml",240,1)))))),0)) | L31: =IF(H31="","",H31) | N31: =IF(I31="","",I31)
B32: TOTAL | D32: =IF(J32="","",TEXT(J32,"#,##0")) | G32: =IF(K32="","",TEXT(K32,"#,##0")) | H32: =IF(L32="","",TEXT(L32,"#,##0")) | I32: =IF(M32="","",TEXT(M32,"#,##0")) | J32: =SUM(D27:D31) | K32: =SUM(G27:G31) | L32: =SUM(H27:H31) | M32: =SUM(I27:I31) | N32: =IF(I32="","",I32) | O32: =SUM(N28:N31)
J33: =IF(D33="","",ROUNDUP(D33/IF(AND(C33="600 ml",ISNUMBER(SEARCH("NORCAU",B33))),95,IF(AND(C33="600 ml",ISNUMBER(SEARCH("APURATOS",B33))),190,IF(C33="600 ml",95,IF(C33="400 ml",125,IF(C33="200 ml",330,IF(C33="180 ml",240,1)))))),0)) | L33: =IF(H33="","",H33) | N33: =IF(I33="","",I33)
A34: 46031 | B34: PRODUTO | C34: EMBALAGEM | D34: CAIXAS | E34: UN | F34: CX/PALLET | G34: PALLETS (PBR) | H34: REAL (CX) | I34: TOTAL LATAS
J35: =IF(D35="","",ROUNDUP(D35/IF(AND(C35="600 ml",ISNUMBER(SEARCH("NORCAU",B35))),95,IF(AND(C35="600 ml",ISNUMBER(SEARCH("APURATOS",B35))),190,IF(C35="600 ml",95,IF(C35="400 ml",125,IF(C35="200 ml",330,IF(C35="180 ml",240,1)))))),0)) | L35: =IF(H35="","",H35) | N35: =IF(I35="","",I35) | P35: Explodiu o transformador.
B36: UNTA FACIL | C36: 600 | D36: =D28-L28 | E36: CX | F36: =IF($B36="","",IF(SUMIFS(CONFIG_PALLETS!$C:$C,CONFIG_PALLETS!$A:$A,TRIM($B36),CONFIG_PALLETS!$B:$B,$C36&" ml")>0,SUMIFS(CONFIG_PALLETS!$C:$C,CONFIG_PALLETS!$A:$A,TRIM($B36),CONFIG_PALLETS!$B:$B,$C36&" ml"),IF(SUMIFS(CONFIG_PALLETS!$C:$C,CONFIG_PALLETS!$A:$A,"GERAL",CONFIG_PALLETS!$B:$B,$C36&" ml")>0,SUMIFS(CONFIG_PALLETS!$C:$C,CONFIG_PALLETS!$A:$A,"GERAL",CONFIG_PALLETS!$B:$B,$C36&" ml"),""))) | G36: =IFERROR(ROUNDUP(D36/F36,0),"") | H36: 13 | I36: =IF(H36="","",H36*IF(SUMIFS(CONFIG_PALLETS!$D:$D,CONFIG_PALLETS!$A:$A,IF(ISNUMBER(SEARCH("ESPUMA",$B36)),"ESPUMA",IF(OR(ISNUMBER(SEARCH("OLEO DE COCO",$B36)),ISNUMBER(SEARCH("ÓLEO DE COCO",$B36)),ISNUMBER(SEARCH("COPRA",$B36))),"ÓLEO DE COCO",IF(ISNUMBER(SEARCH("CORANTE",$B36)),"CORANTE",TRIM($B36)))),CONFIG_PALLETS!$B:$B,$C36&" ml")>0,SUMIFS(CONFIG_PALLETS!$D:$D,CONFIG_PALLETS!$A:$A,IF(ISNUMBER(SEARCH("ESPUMA",$B36)),"ESPUMA",IF(OR(ISNUMBER(SEARCH("OLEO DE COCO",$B36)),ISNUMBER(SEARCH("ÓLEO DE COCO",$B36)),ISNUMBER(SEARCH("COPRA",$B36))),"ÓLEO DE COCO",IF(ISNUMBER(SEARCH("CORANTE",$B36)),"CORANTE",TRIM($B36)))),CONFIG_PALLETS!$B:$B,$C36&" ml"),IF(SUMIFS(CONFIG_PALLETS!$D:$D,CONFIG_PALLETS!$A:$A,"GERAL",CONFIG_PALLETS!$B:$B,$C36&" ml")>0,SUMIFS(CONFIG_PALLETS!$D:$D,CONFIG_PALLETS!$A:$A,"GERAL",CONFIG_PALLETS!$B:$B,$C36&" ml"),12))) | J36: =IF(D36="","",ROUNDUP(D36/IF(AND(C36="600 ml",ISNUMBER(SEARCH("NORCAU",B36))),95,IF(AND(C36="600 ml",ISNUMBER(SEARCH("APURATOS",B36))),190,IF(C36="600 ml",95,IF(C36="400 ml",125,IF(C36="200 ml",330,IF(C36="180 ml",240,1)))))),0)) | L36: =IF(H36="","",H36) | N36: =IF(I36="","",I36)
B37: PURATOS | C37: 600 | D37: 2660 | E37: CX | F37: =IF($B37="","",IF(SUMIFS(CONFIG_PALLETS!$C:$C,CONFIG_PALLETS!$A:$A,TRIM($B37),CONFIG_PALLETS!$B:$B,$C37&" ml")>0,SUMIFS(CONFIG_PALLETS!$C:$C,CONFIG_PALLETS!$A:$A,TRIM($B37),CONFIG_PALLETS!$B:$B,$C37&" ml"),IF(SUMIFS(CONFIG_PALLETS!$C:$C,CONFIG_PALLETS!$A:$A,"GERAL",CONFIG_PALLETS!$B:$B,$C37&" ml")>0,SUMIFS(CONFIG_PALLETS!$C:$C,CONFIG_PALLETS!$A:$A,"GERAL",CONFIG_PALLETS!$B:$B,$C37&" ml"),""))) | G37: =IFERROR(ROUNDUP(D37/F37,0),"") | H37: 1057 | I37: =IF(H37="","",H37*IF(SUMIFS(CONFIG_PALLETS!$D:$D,CONFIG_PALLETS!$A:$A,IF(ISNUMBER(SEARCH("ESPUMA",$B37)),"ESPUMA",IF(OR(ISNUMBER(SEARCH("OLEO DE COCO",$B37)),ISNUMBER(SEARCH("ÓLEO DE COCO",$B37)),ISNUMBER(SEARCH("COPRA",$B37))),"ÓLEO DE COCO",IF(ISNUMBER(SEARCH("CORANTE",$B37)),"CORANTE",TRIM($B37)))),CONFIG_PALLETS!$B:$B,$C37&" ml")>0,SUMIFS(CONFIG_PALLETS!$D:$D,CONFIG_PALLETS!$A:$A,IF(ISNUMBER(SEARCH("ESPUMA",$B37)),"ESPUMA",IF(OR(ISNUMBER(SEARCH("OLEO DE COCO",$B37)),ISNUMBER(SEARCH("ÓLEO DE COCO",$B37)),ISNUMBER(SEARCH("COPRA",$B37))),"ÓLEO DE COCO",IF(ISNUMBER(SEARCH("CORANTE",$B37)),"CORANTE",TRIM($B37)))),CONFIG_PALLETS!$B:$B,$C37&" ml"),IF(SUMIFS(CONFIG_PALLETS!$D:$D,CONFIG_PALLETS!$A:$A,"GERAL",CONFIG_PALLETS!$B:$B,$C37&" ml")>0,SUMIFS(CONFIG_PALLETS!$D:$D,CONFIG_PALLETS!$A:$A,"GERAL",CONFIG_PALLETS!$B:$B,$C37&" ml"),12))) | J37: =IF(D37="","",ROUNDUP(D37/IF(AND(C37="600 ml",ISNUMBER(SEARCH("NORCAU",B37))),95,IF(AND(C37="600 ml",ISNUMBER(SEARCH("APURATOS",B37))),190,IF(C37="600 ml",95,IF(C37="400 ml",125,IF(C37="200 ml",330,IF(C37="180 ml",240,1)))))),0)) | L37: =IF(H37="","",H37) | N37: =IF(I37="","",I37)
E38: CX | F38: =IF($B38="","",IF(SUMIFS(CONFIG_PALLETS!$C:$C,CONFIG_PALLETS!$A:$A,TRIM($B38),CONFIG_PALLETS!$B:$B,$C38&" ml")>0,SUMIFS(CONFIG_PALLETS!$C:$C,CONFIG_PALLETS!$A:$A,TRIM($B38),CONFIG_PALLETS!$B:$B,$C38&" ml"),IF(SUMIFS(CONFIG_PALLETS!$C:$C,CONFIG_PALLETS!$A:$A,"GERAL",CONFIG_PALLETS!$B:$B,$C38&" ml")>0,SUMIFS(CONFIG_PALLETS!$C:$C,CONFIG_PALLETS!$A:$A,"GERAL",CONFIG_PALLETS!$B:$B,$C38&" ml"),""))) | G38: =IFERROR(ROUNDUP(D38/F38,0),"") | I38: =IF(H38="","",H38*IF(SUMIFS(CONFIG_PALLETS!$D:$D,CONFIG_PALLETS!$A:$A,IF(ISNUMBER(SEARCH("ESPUMA",$B38)),"ESPUMA",IF(OR(ISNUMBER(SEARCH("OLEO DE COCO",$B38)),ISNUMBER(SEARCH("ÓLEO DE COCO",$B38)),ISNUMBER(SEARCH("COPRA",$B38))),"ÓLEO DE COCO",IF(ISNUMBER(SEARCH("CORANTE",$B38)),"CORANTE",TRIM($B38)))),CONFIG_PALLETS!$B:$B,$C38&" ml")>0,SUMIFS(CONFIG_PALLETS!$D:$D,CONFIG_PALLETS!$A:$A,IF(ISNUMBER(SEARCH("ESPUMA",$B38)),"ESPUMA",IF(OR(ISNUMBER(SEARCH("OLEO DE COCO",$B38)),ISNUMBER(SEARCH("ÓLEO DE COCO",$B38)),ISNUMBER(SEARCH("COPRA",$B38))),"ÓLEO DE COCO",IF(ISNUMBER(SEARCH("CORANTE",$B38)),"CORANTE",TRIM($B38)))),CONFIG_PALLETS!$B:$B,$C38&" ml"),IF(SUMIFS(CONFIG_PALLETS!$D:$D,CONFIG_PALLETS!$A:$A,"GERAL",CONFIG_PALLETS!$B:$B,$C38&" ml")>0,SUMIFS(CONFIG_PALLETS!$D:$D,CONFIG_PALLETS!$A:$A,"GERAL",CONFIG_PALLETS!$B:$B,$C38&" ml"),12))) | J38: =IF(D38="","",ROUNDUP(D38/IF(AND(C38="600 ml",ISNUMBER(SEARCH("NORCAU",B38))),95,IF(AND(C38="600 ml",ISNUMBER(SEARCH("APURATOS",B38))),190,IF(C38="600 ml",95,IF(C38="400 ml",125,IF(C38="200 ml",330,IF(C38="180 ml",240,1)))))),0)) | L38: =IF(H38="","",H38) | N38: =IF(I38="","",I38)
E39: CX | F39: =IF($B39="","",IF(SUMIFS(CONFIG_PALLETS!$C:$C,CONFIG_PALLETS!$A:$A,TRIM($B39),CONFIG_PALLETS!$B:$B,$C39&" ml")>0,SUMIFS(CONFIG_PALLETS!$C:$C,CONFIG_PALLETS!$A:$A,TRIM($B39),CONFIG_PALLETS!$B:$B,$C39&" ml"),IF(SUMIFS(CONFIG_PALLETS!$C:$C,CONFIG_PALLETS!$A:$A,"GERAL",CONFIG_PALLETS!$B:$B,$C39&" ml")>0,SUMIFS(CONFIG_PALLETS!$C:$C,CONFIG_PALLETS!$A:$A,"GERAL",CONFIG_PALLETS!$B:$B,$C39&" ml"),""))) | G39: =IFERROR(ROUNDUP(D39/F39,0),"") | I39: =IF(H39="","",H39*IF(SUMIFS(CONFIG_PALLETS!$D:$D,CONFIG_PALLETS!$A:$A,IF(ISNUMBER(SEARCH("ESPUMA",$B39)),"ESPUMA",IF(OR(ISNUMBER(SEARCH("OLEO DE COCO",$B39)),ISNUMBER(SEARCH("ÓLEO DE COCO",$B39)),ISNUMBER(SEARCH("COPRA",$B39))),"ÓLEO DE COCO",IF(ISNUMBER(SEARCH("CORANTE",$B39)),"CORANTE",TRIM($B39)))),CONFIG_PALLETS!$B:$B,$C39&" ml")>0,SUMIFS(CONFIG_PALLETS!$D:$D,CONFIG_PALLETS!$A:$A,IF(ISNUMBER(SEARCH("ESPUMA",$B39)),"ESPUMA",IF(OR(ISNUMBER(SEARCH("OLEO DE COCO",$B39)),ISNUMBER(SEARCH("ÓLEO DE COCO",$B39)),ISNUMBER(SEARCH("COPRA",$B39))),"ÓLEO DE COCO",IF(ISNUMBER(SEARCH("CORANTE",$B39)),"CORANTE",TRIM($B39)))),CONFIG_PALLETS!$B:$B,$C39&" ml"),IF(SUMIFS(CONFIG_PALLETS!$D:$D,CONFIG_PALLETS!$A:$A,"GERAL",CONFIG_PALLETS!$B:$B,$C39&" ml")>0,SUMIFS(CONFIG_PALLETS!$D:$D,CONFIG_PALLETS!$A:$A,"GERAL",CONFIG_PALLETS!$B:$B,$C39&" ml"),12))) | J39: =IF(D39="","",ROUNDUP(D39/IF(AND(C39="600 ml",ISNUMBER(SEARCH("NORCAU",B39))),95,IF(AND(C39="600 ml",ISNUMBER(SEARCH("APURATOS",B39))),190,IF(C39="600 ml",95,IF(C39="400 ml",125,IF(C39="200 ml",330,IF(C39="180 ml",240,1)))))),0)) | L39: =IF(H39="","",H39) | N39: =IF(I39="","",I39)
J40: =IF(D40="","",ROUNDUP(D40/IF(AND(C40="600 ml",ISNUMBER(SEARCH("NORCAU",B40))),95,IF(AND(C40="600 ml",ISNUMBER(SEARCH("APURATOS",B40))),190,IF(C40="600 ml",95,IF(C40="400 ml",125,IF(C40="200 ml",330,IF(C40="180 ml",240,1)))))),0)) | L40: =IF(H40="","",H40) | N40: =IF(I40="","",I40)
...

Sheet GRAFICO JANEIRO
A1: RESULTADOS E GRÁFICO - JANEIRO
B3: Total do mês | D3: Meta do mês | F3: Média por dia | H3: Melhor dia | J3: Atingimento | K3: Legenda | L3: Leitura
B4: =SUM(C9:C30) | D4: =COUNTA(A9:A30)*CONFIG!$B$3 | F4: =IFERROR(SUMIFS(C9:C30,A9:A30,"<="&TODAY(),F9:F30,"<>*Feriado*")/COUNTIFS(A9:A30,"<="&TODAY(),F9:F30,"<>*Feriado*"),0) | H4: =IFERROR(MAX(C9:C30),0) | J4: =IFERROR(B4/D4,0) | K4: Verde | L4: Acima da meta
K5: Vermelho | L5: Abaixo da meta
K6: Cinza | L6: Igual à meta
A8: Data | B8: Dias trabalhados | C8: Realizado | D8: Meta diária | E8: Diferença | F8: Observações | X8: Realizado gráfico | Y8: Meta gráfico
A9: 46023 | B9: 1 | C9: 0 | D9: =CONFIG!$B$3 | E9: =C9-D9 | F9: Feriado - Confraternização Universal | X9: =IF(COUNTIF($F9,"*Feriado*")>0,NA(),$C9) | Y9: =IF(COUNTIF($F9,"*Feriado*")>0,NA(),$D9)
A10: 46024 | B10: 2 | C10: 0 | D10: =CONFIG!$B$3 | E10: =C10-D10 | X10: =IF(COUNTIF($F10,"*Feriado*")>0,NA(),$C10) | Y10: =IF(COUNTIF($F10,"*Feriado*")>0,NA(),$D10)
A11: 46027 | B11: 3 | C11: ='SEMANA JANEIRO'!$M$9 | D11: =CONFIG!$B$3 | E11: =C11-D11 | X11: =IF(COUNTIF($F11,"*Feriado*")>0,NA(),$C11) | Y11: =IF(COUNTIF($F11,"*Feriado*")>0,NA(),$D11)
A12: 46028 | B12: 4 | C12: ='SEMANA JANEIRO'!$M$16 | D12: =CONFIG!$B$3 | E12: =C12-D12 | X12: =IF(COUNTIF($F12,"*Feriado*")>0,NA(),$C12) | Y12: =IF(COUNTIF($F12,"*Feriado*")>0,NA(),$D12)
A13: 46029 | B13: 5 | C13: ='SEMANA JANEIRO'!$M$24 | D13: =CONFIG!$B$3 | E13: =C13-D13 | X13: =IF(COUNTIF($F13,"*Feriado*")>0,NA(),$C13) | Y13: =IF(COUNTIF($F13,"*Feriado*")>0,NA(),$D13)
A14: 46030 | B14: 6 | C14: ='SEMANA JANEIRO'!$M$32 | D14: =CONFIG!$B$3 | E14: =C14-D14 | X14: =IF(COUNTIF($F14,"*Feriado*")>0,NA(),$C14) | Y14: =IF(COUNTIF($F14,"*Feriado*")>0,NA(),$D14)
A15: 46031 | B15: 7 | C15: ='SEMANA JANEIRO'!$M$41 | D15: =CONFIG!$B$3 | E15: =C15-D15 | X15: =IF(COUNTIF($F15,"*Feriado*")>0,NA(),$C15) | Y15: =IF(COUNTIF($F15,"*Feriado*")>0,NA(),$D15)
A16: 46034 | B16: 8 | C16: ='SEMANA JANEIRO'!$M$49 | D16: =CONFIG!$B$3 | E16: =C16-D16 | X16: =IF(COUNTIF($F16,"*Feriado*")>0,NA(),$C16) | Y16: =IF(COUNTIF($F16,"*Feriado*")>0,NA(),$D16)
A17: 46035 | B17: 9 | C17: ='SEMANA JANEIRO'!$M$57 | D17: =CONFIG!$B$3 | E17: =C17-D17 | X17: =IF(COUNTIF($F17,"*Feriado*")>0,NA(),$C17) | Y17: =IF(COUNTIF($F17,"*Feriado*")>0,NA(),$D17)
A18: 46036 | B18: 10 | C18: ='SEMANA JANEIRO'!$M$65 | D18: =CONFIG!$B$3 | E18: =C18-D18 | X18: =IF(COUNTIF($F18,"*Feriado*")>0,NA(),$C18) | Y18: =IF(COUNTIF($F18,"*Feriado*")>0,NA(),$D18)
A19: 46037 | B19: 11 | C19: ='SEMANA JANEIRO'!$M$74 | D19: =CONFIG!$B$3 | E19: =C19-D19 | X19: =IF(COUNTIF($F19,"*Feriado*")>0,NA(),$C19) | Y19: =IF(COUNTIF($F19,"*Feriado*")>0,NA(),$D19)
A20: 46038 | B20: 12 | C20: ='SEMANA JANEIRO'!$M$82 | D20: =CONFIG!$B$3 | E20: =C20-D20 | X20: =IF(COUNTIF($F20,"*Feriado*")>0,NA(),$C20) | Y20: =IF(COUNTIF($F20,"*Feriado*")>0,NA(),$D20)
A21: 46041 | B21: 13 | C21: ='SEMANA JANEIRO'!$M$92 | D21: =CONFIG!$B$3 | E21: =C21-D21 | X21: =IF(COUNTIF($F21,"*Feriado*")>0,NA(),$C21) | Y21: =IF(COUNTIF($F21,"*Feriado*")>0,NA(),$D21)
A22: 46042 | B22: 14 | C22: ='SEMANA JANEIRO'!$M$102 | D22: =CONFIG!$B$3 | E22: =C22-D22 | X22: =IF(COUNTIF($F22,"*Feriado*")>0,NA(),$C22) | Y22: =IF(COUNTIF($F22,"*Feriado*")>0,NA(),$D22)
A23: 46043 | B23: 15 | C23: 0 | D23: =CONFIG!$B$3 | E23: =C23-D23 | X23: =IF(COUNTIF($F23,"*Feriado*")>0,NA(),$C23) | Y23: =IF(COUNTIF($F23,"*Feriado*")>0,NA(),$D23)
A24: 46044 | B24: 16 | C24: ='SEMANA JANEIRO'!$M$120 | D24: =CONFIG!$B$3 | E24: =C24-D24 | X24: =IF(COUNTIF($F24,"*Feriado*")>0,NA(),$C24) | Y24: =IF(COUNTIF($F24,"*Feriado*")>0,NA(),$D24)
A25: 46045 | B25: 17 | C25: 0 | D25: =CONFIG!$B$3 | E25: =C25-D25 | X25: =IF(COUNTIF($F25,"*Feriado*")>0,NA(),$C25) | Y25: =IF(COUNTIF($F25,"*Feriado*")>0,NA(),$D25)
A26: 46048 | B26: 18 | C26: ='SEMANA JANEIRO'!$M$142 | D26: =CONFIG!$B$3 | E26: =C26-D26 | X26: =IF(COUNTIF($F26,"*Feriado*")>0,NA(),$C26) | Y26: =IF(COUNTIF($F26,"*Feriado*")>0,NA(),$D26)
A27: 46049 | B27: 19 | C27: ='SEMANA JANEIRO'!$M$150 | D27: =CONFIG!$B$3 | E27: =C27-D27 | X27: =IF(COUNTIF($F27,"*Feriado*")>0,NA(),$C27) | Y27: =IF(COUNTIF($F27,"*Feriado*")>0,NA(),$D27)
A28: 46050 | B28: 20 | C28: ='SEMANA JANEIRO'!$M$161 | D28: =CONFIG!$B$3 | E28: =C28-D28 | X28: =IF(COUNTIF($F28,"*Feriado*")>0,NA(),$C28) | Y28: =IF(COUNTIF($F28,"*Feriado*")>0,NA(),$D28)
A29: 46051 | B29: 21 | C29: ='SEMANA JANEIRO'!$M$169 | D29: =CONFIG!$B$3 | E29: =C29-D29 | X29: =IF(COUNTIF($F29,"*Feriado*")>0,NA(),$C29) | Y29: =IF(COUNTIF($F29,"*Feriado*")>0,NA(),$D29)
A30: 46052 | B30: 22 | C30: ='SEMANA JANEIRO'!$M$198 | D30: =CONFIG!$B$3 | E30: =C30-D30 | X30: =IF(COUNTIF($F30,"*Feriado*")>0,NA(),$C30) | Y30: =IF(COUNTIF($F30,"*Feriado*")>0,NA(),$D30)

Sheet FEVEREIRO
B1: ORDEM DE PRODUÇÃO - FEVEREIRO
B3: OP | C3: LOTE | E3: LOTE CLIENTE | G3: PRODUTO | K3: CLIENTE | M3: QTDE(Kg) | N3: FABRICAÇÃO
B4: 2026/031 | C4: 26010146 | E4: OL 131/32/33/34/35 | G4: OL 40/20 - 25LTRS | K4: INDIPAN | M4: 90 BBs | N4: 46055
B5: 2026/032 | C5: 26010147 | G5: UNTA FACIL 400ML | K5: IN LOCO | M5: 30.000 LATAS | N5: 46062
B6: 2026/033 | C6: 26010148 | G6: UNTA MAIS 400ML | K6: CASA DO PANIFICADOR | M6: 2.400 LATAS | N6: 46066
B7: 2026/034 | C7: 26010149 | G7: CHEF MASTER 400ML | K7: REPETECO | M7: 3.000 LATAS | N7: 46066
B8: 2026/035 | C8: 26010150 | G8: BONASSE 400ML | K8: ROCHAPAN | M8: 3.000 LATAS | N8: 46066
B9: 2026/036 | C9: 26010151 | G9: UNTA FORMA 400ML | K9: BRICOFLEX | M9: 1.500 LATAS | N9: 46071
B10: 2026/037 | C10: 26010152 | G10: UNTA FORMA 400ML | K10: TTF | M10: 1.500 LATAS | N10: 46071
B11: 2026/038 | C11: 26010153 | G11: UNTA FORMA 400ML | K11: DISPAN | M11: 4.500 LATAS | N11: 46072
B12: 2026/039 | E12: 2631392 | G12: DESMOLDANTE CHEF | K12: ICEBERG | M12: 27.192 LATAS | N12: 46064
B13: 2026/040 | C13: 26010154 | G13: OL 40 | K13: SMART | M13: 420 KG | N13: 46058
C14: 26010155 | G14: OL 40 | M14: 420 KG | N14: 46058
C15: 26010156 | G15: OL 40 | M15: 420 KG | N15: 46062
C16: 26010157 | G16: OL ABELHA | M16: 420 KG | N16: 46058
C17: 26010158 | G17: OL ABELHA | M17: 420 KG | N17: 46058
C18: 26010159 | G18: OL ABELHA | M18: 420 KG | N18: 46058
C19: 26010160 | G19: OL ABELHA | M19: 420 KG | N19: 46058
C20: 26010161 | G20: OL 40 | M20: 420 KG | N20: 46062
C21: 26010162 | G21: OL 40 | M21: 420 KG | N21: 46062
C22: 26010163 | G22: OL 40 | M22: 420 KG | N22: 46062
C23: 26010164 | G23: OL 40 | M23: 420 KG | N23: 46062
C24: 26010165 | G24: OL 40 | M24: 420 KG | N24: 46063
C25: 26010166 | G25: OL 40 | M25: 420 KG | N25: 46063
... C31: 26010172 | G31: OL 40 | M31: 420 KG | N31: 46064
B32: 2026/041 | C32: 26010173 30 | G32: LISSE 600ML | K32: ADIMIX | M32: 7.980 LATAS | N32: 46084
B33: 2026/042 | C33: 26010174 | G33: OL 40 | K33: SMART | M33: 420 KG | N33: 46064
C34: 26010175 | G34: OL 40 | M34: 420 KG | N34: 46064
C35: 26010176 | G35: OL 40 | M35: 420 KG | N35: 46064
C36: 26010177 | G36: OL 40 | M36: 420 KG | N36: 46064
C37: 26010178 | G37: OL 40 | M37: 420 KG | N37: 46065
C38: 26010179 | G38: OL 40 | M38: 420 KG | N38: 46065
C39: 26010180 | G39: OL 40 | M39: 420 KG | N39: 46065
C40: 26010181 | G40: OL 40 | M40: 420 KG | N40: 46065
C41: 26010182 | G41: OL 40 | M41: 420 KG | N41: 46065
C42: 26010183 | G42: OL 40 | M42: 420 KG | N42: 46066
C43: 26010184 | G43: OL 40 | M43: 420 KG | N43: 46066
C44: 26010185 | G44: OL 40 | M44: 420 KG | N44: 46066
C45: 26010186 | G45: OL 40 | M45: 420 KG | N45: 46066
... C57: 26010198 | G57: OL 40 | M57: 420 KG | N57: 46071
...

Sheet SEMANA FEVEREIRO
A1: LANÇAMENTO DE PRODUÇÃO • PREENCHIMENTO RÁPIDO | J1: _TOTAL_CX_NUM | K1: _TOTAL_PALLETS_NUM | L1: _TOTAL_REALCX_NUM | M1: _TOTAL_LATAS_NUM
A2: Preencha produto, embalagem e caixas. As demais colunas ajudam a leitura diária. | G2: Legenda: verde = acima da meta • vermelho = abaixo da meta | P2: Pallet PBR: 600ml=95 | 400ml=125 | 200ml=330 | 180ml=240 cx
A3: 46055 | B3: PRODUTO | C3: EMBALAGEM | D3: CAIXAS | E3: UN | F3: CX/PALLET | G3: PALLETS (PBR) | H3: REAL (CX) | I3: TOTAL LATAS
L4: =IF(H4="","",H4) | N4: =IF(I4="","",I4)
A5: 600 | B5: ALLBREAD | C5: 600 | D5: ='SEMANA JANEIRO'!D174-'SEMANA JANEIRO'!L174 | E5: CX | F5: =IF($B5="","",IF(SUMIFS(CONFIG_PALLETS!$C:$C,CONFIG_PALLETS!$A:$A,TRIM($B5),CONFIG_PALLETS!$B:$B,$C5&" ml")>0,SUMIFS(CONFIG_PALLETS!$C:$C,CONFIG_PALLETS!$A:$A,TRIM($B5),CONFIG_PALLETS!$B:$B,$C5&" ml"),IF(SUMIFS(CONFIG_PALLETS!$C:$C,CONFIG_PALLETS!$A:$A,"GERAL",CONFIG_PALLETS!$B:$B,$C5&" ml")>0,SUMIFS(CONFIG_PALLETS!$C:$C,CONFIG_PALLETS!$A:$A,"GERAL",CONFIG_PALLETS!$B:$B,$C5&" ml"),""))) | G5: =IFERROR(ROUNDUP(D5/F5,0),"") | H5: 438 | I5: =IF(H5="","",H5*IF(SUMIFS(CONFIG_PALLETS!$D:$D,CONFIG_PALLETS!$A:$A,IF(ISNUMBER(SEARCH("ESPUMA",$B5)),"ESPUMA",IF(OR(ISNUMBER(SEARCH("OLEO DE COCO",$B5)),ISNUMBER(SEARCH("ÓLEO DE COCO",$B5)),ISNUMBER(SEARCH("COPRA",$B5))),"ÓLEO DE COCO",IF(ISNUMBER(SEARCH("CORANTE",$B5)),"CORANTE",TRIM($B5)))),CONFIG_PALLETS!$B:$B,$C5&" ml")>0,SUMIFS(CONFIG_PALLETS!$D:$D,CONFIG_PALLETS!$A:$A,IF(ISNUMBER(SEARCH("ESPUMA",$B5)),"ESPUMA",IF(OR(ISNUMBER(SEARCH("OLEO DE COCO",$B5)),ISNUMBER(SEARCH("ÓLEO DE COCO",$B5)),ISNUMBER(SEARCH("COPRA",$B5))),"ÓLEO DE COCO",IF(ISNUMBER(SEARCH("CORANTE",$B5)),"CORANTE",TRIM($B5)))),CONFIG_PALLETS!$B:$B,$C5&" ml"),IF(SUMIFS(CONFIG_PALLETS!$D:$D,CONFIG_PALLETS!$A:$A,"GERAL",CONFIG_PALLETS!$B:$B,$C5&" ml")>0,SUMIFS(CONFIG_PALLETS!$D:$D,CONFIG_PALLETS!$A:$A,"GERAL",CONFIG_PALLETS!$B:$B,$C5&" ml"),12))) | J5: =IF(D5="","",ROUNDUP(D5/IF(AND(C5="600 ml",ISNUMBER(SEARCH("NORCAU",B5))),95,IF(AND(C5="600 ml",ISNUMBER(SEARCH("APURATOS",B5))),190,IF(C5="600 ml",95,IF(C5="400 ml",125,IF(C5="200 ml",330,IF(C5="180 ml",240,1)))))),0)) | L5: =IF(H5="","",H5) | N5: =IF(I5="","",I5)
B6: UNTA FACIL | C6: 600 | D6: 1330 | E6: CX | F6: =IF($B6="","",IF(SUMIFS(CONFIG_PALLETS!$C:$C,CONFIG_PALLETS!$A:$A,TRIM($B6),CONFIG_PALLETS!$B:$B,$C6&" ml")>0,SUMIFS(CONFIG_PALLETS!$C:$C,CONFIG_PALLETS!$A:$A,TRIM($B6),CONFIG_PALLETS!$B:$B,$C6&" ml"),IF(SUMIFS(CONFIG_PALLETS!$C:$C,CONFIG_PALLETS!$A:$A,"GERAL",CONFIG_PALLETS!$B:$B,$C6&" ml")>0,SUMIFS(CONFIG_PALLETS!$C:$C,CONFIG_PALLETS!$A:$A,"GERAL",CONFIG_PALLETS!$B:$B,$C6&" ml"),""))) | G6: =IFERROR(ROUNDUP(D6/F6,0),"") | H6: 506 | I6: =IF(H6="","",H6*IF(SUMIFS(CONFIG_PALLETS!$D:$D,CONFIG_PALLETS!$A:$A,IF(ISNUMBER(SEARCH("ESPUMA",$B6)),"ESPUMA",IF(OR(ISNUMBER(SEARCH("OLEO DE COCO",$B6)),ISNUMBER(SEARCH("ÓLEO DE COCO",$B6)),ISNUMBER(SEARCH("COPRA",$B6))),"ÓLEO DE COCO",IF(ISNUMBER(SEARCH("CORANTE",$B6)),"CORANTE",TRIM($B6)))),CONFIG_PALLETS!$B:$B,$C6&" ml")>0,SUMIFS(CONFIG_PALLETS!$D:$D,CONFIG_PALLETS!$A:$A,IF(ISNUMBER(SEARCH("ESPUMA",$B6)),"ESPUMA",IF(OR(ISNUMBER(SEARCH("OLEO DE COCO",$B6)),ISNUMBER(SEARCH("ÓLEO DE COCO",$B6)),ISNUMBER(SEARCH("COPRA",$B6))),"ÓLEO DE COCO",IF(ISNUMBER(SEARCH("CORANTE",$B6)),"CORANTE",TRIM($B6)))),CONFIG_PALLETS!$B:$B,$C6&" ml"),IF(SUMIFS(CONFIG_PALLETS!$D:$D,CONFIG_PALLETS!$A:$A,"GERAL",CONFIG_PALLETS!$B:$B,$C6&" ml")>0,SUMIFS(CONFIG_PALLETS!$D:$D,CONFIG_PALLETS!$A:$A,"GERAL",CONFIG_PALLETS!$B:$B,$C6&" ml"),12))) | J6: =IF(D6="","",ROUNDUP(D6/IF(AND(C6="600 ml",ISNUMBER(SEARCH("NORCAU",B6))),95,IF(AND(C6="600 ml",ISNUMBER(SEARCH("APURATOS",B6))),190,IF(C6="600 ml",95,IF(C6="400 ml",125,IF(C6="200 ml",330,IF(C6="180 ml",240,1)))))),0)) | L6: =IF(H6="","",H6) | N6: =IF(I6="","",I6)
E7: CX | F7: =IF($B7="","",IF(SUMIFS(CONFIG_PALLETS!$C:$C,CONFIG_PALLETS!$A:$A,TRIM($B7),CONFIG_PALLETS!$B:$B,$C7&" ml")>0,SUMIFS(CONFIG_PALLETS!$C:$C,CONFIG_PALLETS!$A:$A,TRIM($B7),CONFIG_PALLETS!$B:$B,$C7&" ml"),IF(SUMIFS(CONFIG_PALLETS!$C:$C,CONFIG_PALLETS!$A:$A,"GERAL",CONFIG_PALLETS!$B:$B,$C7&" ml")>0,SUMIFS(CONFIG_PALLETS!$C:$C,CONFIG_PALLETS!$A:$A,"GERAL",CONFIG_PALLETS!$B:$B,$C7&" ml"),""))) | G7: =IFERROR(ROUNDUP(D7/F7,0),"") | I7: =IF(H7="","",H7*IF(SUMIFS(CONFIG_PALLETS!$D:$D,CONFIG_PALLETS!$A:$A,IF(ISNUMBER(SEARCH("ESPUMA",$B7)),"ESPUMA",IF(OR(ISNUMBER(SEARCH("OLEO DE COCO",$B7)),ISNUMBER(SEARCH("ÓLEO DE COCO",$B7)),ISNUMBER(SEARCH("COPRA",$B7))),"ÓLEO DE COCO",IF(ISNUMBER(SEARCH("CORANTE",$B7)),"CORANTE",TRIM($B7)))),CONFIG_PALLETS!$B:$B,$C7&" ml")>0,SUMIFS(CONFIG_PALLETS!$D:$D,CONFIG_PALLETS!$A:$A,IF(ISNUMBER(SEARCH("ESPUMA",$B7)),"ESPUMA",IF(OR(ISNUMBER(SEARCH("OLEO DE COCO",$B7)),ISNUMBER(SEARCH("ÓLEO DE COCO",$B7)),ISNUMBER(SEARCH("COPRA",$B7))),"ÓLEO DE COCO",IF(ISNUMBER(SEARCH("CORANTE",$B7)),"CORANTE",TRIM($B7)))),CONFIG_PALLETS!$B:$B,$C7&" ml"),IF(SUMIFS(CONFIG_PALLETS!$D:$D,CONFIG_PALLETS!$A:$A,"GERAL",CONFIG_PALLETS!$B:$B,$C7&" ml")>0,SUMIFS(CONFIG_PALLETS!$D:$D,CONFIG_PALLETS!$A:$A,"GERAL",CONFIG_PALLETS!$B:$B,$C7&" ml"),12))) | J7: =IF(D7="","",ROUNDUP(D7/IF(AND(C7="600 ml",ISNUMBER(SEARCH("NORCAU",B7))),95,IF(AND(C7="600 ml",ISNUMBER(SEARCH("APURATOS",B7))),190,IF(C7="600 ml",95,IF(C7="400 ml",125,IF(C7="200 ml",330,IF(C7="180 ml",240,1)))))),0)) | L7: =IF(H7="","",H7) | N7: =IF(I7="","",I7)
J8: =IF(D8="","",ROUNDUP(D8/IF(AND(C8="600 ml",ISNUMBER(SEARCH("NORCAU",B8))),95,IF(AND(C8="600 ml",ISNUMBER(SEARCH("APURATOS",B8))),190,IF(C8="600 ml",95,IF(C8="400 ml",125,IF(C8="200 ml",330,IF(C8="180 ml",240,1)))))),0)) | L8: =IF(H8="","",H8) | N8: =IF(I8="","",I8)
B9: TOTAL | D9: =IF(J9="","",TEXT(J9,"#,##0")) | G9: =IF(K9="","",TEXT(K9,"#,##0")) | H9: =IF(L9="","",TEXT(L9,"#,##0")) | I9: =IF(M9="","",TEXT(M9,"#,##0")) | J9: =SUM(D4:D8) | K9: =SUM(G4:G8) | L9: =SUM(H4:H8) | M9: =SUM(I4:I8) | N9: =IF(I9="","",I9) | O9: =SUM(N5:N8)
J10: =IF(D10="","",ROUNDUP(D10/IF(AND(C10="600 ml",ISNUMBER(SEARCH("NORCAU",B10))),95,IF(AND(C10="600 ml",ISNUMBER(SEARCH("APURATOS",B10))),190,IF(C10="600 ml",95,IF(C10="400 ml",125,IF(C10="200 ml",330,IF(C10="180 ml",240,1)))))),0)) | L10: =IF(H10="","",H10) | N10: =IF(I10="","",I10)
A11: 46056 | B11: PRODUTO | C11: EMBALAGEM | D11: CAIXAS | E11: UN | F11: CX/PALLET | G11: PALLETS (PBR) | H11: REAL (CX) | I11: TOTAL LATAS
J12: =IF(D12="","",ROUNDUP(D12/IF(AND(C12="600 ml",ISNUMBER(SEARCH("NORCAU",B12))),95,IF(AND(C12="600 ml",ISNUMBER(SEARCH("APURATOS",B12))),190,IF(C12="600 ml",95,IF(C12="400 ml",125,IF(C12="200 ml",330,IF(C12="180 ml",240,1)))))),0)) | L12: =IF(H12="","",H12) | N12: =IF(I12="","",I12) | P12: PARAMOS ÀS 11:20, GÁS ACABOU. VOLTAMOS 15:00.
A13: 600 | B13: UNTA FACIL | C13: 600 | D13: =D6-L6 | E13: CX | F13: =IF($B13="","",IF(SUMIFS(CONFIG_PALLETS!$C:$C,CONFIG_PALLETS!$A:$A,TRIM($B13),CONFIG_PALLETS!$B:$B,$C13&" ml")>0,SUMIFS(CONFIG_PALLETS!$C:$C,CONFIG_PALLETS!$A:$A,TRIM($B13),CONFIG_PALLETS!$B:$B,$C13&" ml"),IF(SUMIFS(CONFIG_PALLETS!$C:$C,CONFIG_PALLETS!$A:$A,"GERAL",CONFIG_PALLETS!$B:$B,$C13&" ml")>0,SUMIFS(CONFIG_PALLETS!$C:$C,CONFIG_PALLETS!$A:$A,"GERAL",CONFIG_PALLETS!$B:$B,$C13&" ml"),""))) | G13: =IFERROR(ROUNDUP(D13/F13,0),"") | H13: 702 | I13: =IF(H13="","",H13*IF(SUMIFS(CONFIG_PALLETS!$D:$D,CONFIG_PALLETS!$A:$A,IF(ISNUMBER(SEARCH("ESPUMA",$B13)),"ESPUMA",IF(OR(ISNUMBER(SEARCH("OLEO DE COCO",$B13)),ISNUMBER(SEARCH("ÓLEO DE COCO",$B13)),ISNUMBER(SEARCH("COPRA",$B13))),"ÓLEO DE COCO",IF(ISNUMBER(SEARCH("CORANTE",$B13)),"CORANTE",TRIM($B13)))),CONFIG_PALLETS!$B:$B,$C13&" ml")>0,SUMIFS(CONFIG_PALLETS!$D:$D,CONFIG_PALLETS!$A:$A,IF(ISNUMBER(SEARCH("ESPUMA",$B13)),"ESPUMA",IF(OR(ISNUMBER(SEARCH("OLEO DE COCO",$B13)),ISNUMBER(SEARCH("ÓLEO DE COCO",$B13)),ISNUMBER(SEARCH("COPRA",$B13))),"ÓLEO DE COCO",IF(ISNUMBER(SEARCH("CORANTE",$B13)),"CORANTE",TRIM($B13)))),CONFIG_PALLETS!$B:$B,$C13&" ml"),IF(SUMIFS(CONFIG_PALLETS!$D:$D,CONFIG_PALLETS!$A:$A,"GERAL",CONFIG_PALLETS!$B:$B,$C13&" ml")>0,SUMIFS(CONFIG_PALLETS!$D:$D,CONFIG_PALLETS!$A:$A,"GERAL",CONFIG_PALLETS!$B:$B,$C13&" ml"),12))) | J13: =IF(D13="","",ROUNDUP(D13/IF(AND(C13="600 ml",ISNUMBER(SEARCH("NORCAU",B13))),95,IF(AND(C13="600 ml",ISNUMBER(SEARCH("APURATOS",B13))),190,IF(C13="600 ml",95,IF(C13="400 ml",125,IF(C13="200 ml",330,IF(C13="180 ml",240,1)))))),0)) | L13: =IF(H13="","",H13) | N13: =IF(I13="","",I13)
E14: CX | F14: =IF($B14="","",IF(SUMIFS(CONFIG_PALLETS!$C:$C,CONFIG_PALLETS!$A:$A,TRIM($B14),CONFIG_PALLETS!$B:$B,$C14&" ml")>0,SUMIFS(CONFIG_PALLETS!$C:$C,CONFIG_PALLETS!$A:$A,TRIM($B14),CONFIG_PALLETS!$B:$B,$C14&" ml"),IF(SUMIFS(CONFIG_PALLETS!$C:$C,CONFIG_PALLETS!$A:$A,"GERAL",CONFIG_PALLETS!$B:$B,$C14&" ml")>0,SUMIFS(CONFIG_PALLETS!$C:$C,CONFIG_PALLETS!$A:$A,"GERAL",CONFIG_PALLETS!$B:$B,$C14&" ml"),""))) | G14: =IFERROR(ROUNDUP(D14/F14,0),"") | I14: =IF(H14="","",H14*IF(SUMIFS(CONFIG_PALLETS!$D:$D,CONFIG_PALLETS!$A:$A,IF(ISNUMBER(SEARCH("ESPUMA",$B14)),"ESPUMA",IF(OR(ISNUMBER(SEARCH("OLEO DE COCO",$B14)),ISNUMBER(SEARCH("ÓLEO DE COCO",$B14)),ISNUMBER(SEARCH("COPRA",$B14))),"ÓLEO DE COCO",IF(ISNUMBER(SEARCH("CORANTE",$B14)),"CORANTE",TRIM($B14)))),CONFIG_PALLETS!$B:$B,$C14&" ml")>0,SUMIFS(CONFIG_PALLETS!$D:$D,CONFIG_PALLETS!$A:$A,IF(ISNUMBER(SEARCH("ESPUMA",$B14)),"ESPUMA",IF(OR(ISNUMBER(SEARCH("OLEO DE COCO",$B14)),ISNUMBER(SEARCH("ÓLEO DE COCO",$B14)),ISNUMBER(SEARCH("COPRA",$B14))),"ÓLEO DE COCO",IF(ISNUMBER(SEARCH("CORANTE",$B14)),"CORANTE",TRIM($B14)))),CONFIG_PALLETS!$B:$B,$C14&" ml"),IF(SUMIFS(CONFIG_PALLETS!$D:$D,CONFIG_PALLETS!$A:$A,"GERAL",CONFIG_PALLETS!$B:$B,$C14&" ml")>0,SUMIFS(CONFIG_PALLETS!$D:$D,CONFIG_PALLETS!$A:$A,"GERAL",CONFIG_PALLETS!$B:$B,$C14&" ml"),12))) | J14: =IF(D14="","",ROUNDUP(D14/IF(AND(C14="600 ml",ISNUMBER(SEARCH("NORCAU",B14))),95,IF(AND(C14="600 ml",ISNUMBER(SEARCH("APURATOS",B14))),190,IF(C14="600 ml",95,IF(C14="400 ml",125,IF(C14="200 ml",330,IF(C14="180 ml",240,1)))))),0)) | L14: =IF(H14="","",H14) | N14: =IF(I14="","",I14)
E15: CX | F15: =IF($B15="","",IF(SUMIFS(CONFIG_PALLETS!$C:$C,CONFIG_PALLETS!$A:$A,TRIM($B15),CONFIG_PALLETS!$B:$B,$C15&" ml")>0,SUMIFS(CONFIG_PALLETS!$C:$C,CONFIG_PALLETS!$A:$A,TRIM($B15),CONFIG_PALLETS!$B:$B,$C15&" ml"),IF(SUMIFS(CONFIG_PALLETS!$C:$C,CONFIG_PALLETS!$A:$A,"GERAL",CONFIG_PALLETS!$B:$B,$C15&" ml")>0,SUMIFS(CONFIG_PALLETS!$C:$C,CONFIG_PALLETS!$A:$A,"GERAL",CONFIG_PALLETS!$B:$B,$C15&" ml"),""))) | G15: =IFERROR(ROUNDUP(D15/F15,0),"") | I15: =IF(H15="","",H15*IF(SUMIFS(CONFIG_PALLETS!$D:$D,CONFIG_PALLETS!$A:$A,IF(ISNUMBER(SEARCH("ESPUMA",$B15)),"ESPUMA",IF(OR(ISNUMBER(SEARCH("OLEO DE COCO",$B15)),ISNUMBER(SEARCH("ÓLEO DE COCO",$B15)),ISNUMBER(SEARCH("COPRA",$B15))),"ÓLEO DE COCO",IF(ISNUMBER(SEARCH("CORANTE",$B15)),"CORANTE",TRIM($B15)))),CONFIG_PALLETS!$B:$B,$C15&" ml")>0,SUMIFS(CONFIG_PALLETS!$D:$D,CONFIG_PALLETS!$A:$A,IF(ISNUMBER(SEARCH("ESPUMA",$B15)),"ESPUMA",IF(OR(ISNUMBER(SEARCH("OLEO DE COCO",$B15)),ISNUMBER(SEARCH("ÓLEO DE COCO",$B15)),ISNUMBER(SEARCH("COPRA",$B15))),"ÓLEO DE COCO",IF(ISNUMBER(SEARCH("CORANTE",$B15)),"CORANTE",TRIM($B15)))),CONFIG_PALLETS!$B:$B,$C15&" ml"),IF(SUMIFS(CONFIG_PALLETS!$D:$D,CONFIG_PALLETS!$A:$A,"GERAL",CONFIG_PALLETS!$B:$B,$C15&" ml")>0,SUMIFS(CONFIG_PALLETS!$D:$D,CONFIG_PALLETS!$A:$A,"GERAL",CONFIG_PALLETS!$B:$B,$C15&" ml"),12))) | J15: =IF(D15="","",ROUNDUP(D15/IF(AND(C15="600 ml",ISNUMBER(SEARCH("NORCAU",B15))),95,IF(AND(C15="600 ml",ISNUMBER(SEARCH("APURATOS",B15))),190,IF(C15="600 ml",95,IF(C15="400 ml",125,IF(C15="200 ml",330,IF(C15="180 ml",240,1)))))),0)) | L15: =IF(H15="","",H15) | N15: =IF(I15="","",I15)
